Workbook
Name p_ModoCot: '10 Configurações'!$C$6
Name p_FonteCripto: '10 Configurações'!$C$7
Name p_IOF: '10 Configurações'!$C$8
Name p_Spread: '10 Configurações'!$C$9
Name p_CorrPct: '10 Configurações'!$C$10
Name p_CorrFixa: '10 Configurações'!$C$11
Name p_CompraMin: '10 Configurações'!$C$12
Name p_DifMin: '10 Configurações'!$C$13
Name p_MaxClasses: '10 Configurações'!$C$14
Name p_MaxAtivos: '10 Configurações'!$C$15
Name p_LimAtivo: '10 Configurações'!$C$16
Name p_LimSetor: '10 Configurações'!$C$17
Name moeda_cod: '10 Configurações'!$B$21:$B$30
Name moeda_fx: '10 Configurações'!$G$21:$G$30
Name p_Aporte: '01 Dashboard'!$V$2

Sheet 01 Dashboard
B2: HOLDER PREMIUM | N2: VALOR DO APORTE (R$) ► | V2: 500
B3: Realocação inteligente por aportes · Carteira consolidada em R$ | N3: ="Digite o aporte na célula azul · Cotações: "&p_ModoCot&" · o plano de compras atualiza sozinho" -> Digite o aporte na célula azul · Cotações: Automático · o plano de compras atualiza sozinho
B4: Macro | D4: Ações BR | F4: FIIs | H4: Stocks | J4: REITs | L4: Renda Fixa | N4: Cripto | P4: Ilíquidos | R4: Config. | T4: Auxiliar | V4: Base
B6: PATRIMÔNIO TOTAL | F6: PATRIMÔNIO BRASIL | J6: PATRIMÔNIO EXTERIOR | N6: ALTERNATIVOS | R6: COMPRA EFETIVA DO MÊS | V6: SOBRA DO APORTE
B7: ='02 Macro Alocação'!$D$16 -> 0 | F7: ='02 Macro Alocação'!$D$20 -> 0 | J7: ='02 Macro Alocação'!$D$21 -> 0 | N7: ='02 Macro Alocação'!$D$22 -> 0 | R7: ='02 Macro Alocação'!$Q$16 -> 0 | V7: ='02 Macro Alocação'!$R$16 -> 500
B8: =SUMPRODUCT(--('12 Base de Dados'!$C$6:$C$925<>""))&" ativos em 7 classes" -> 0 ativos em 7 classes | F8: =ROUND('02 Macro Alocação'!$E$20*100,1)&"% do patrimônio" -> 0% do patrimônio | J8: =ROUND('02 Macro Alocação'!$E$21*100,1)&"% do patrimônio" -> 0% do patrimônio | N8: =ROUND('02 Macro Alocação'!$E$22*100,1)&"% · cripto + ilíquidos" -> 0% · cripto + ilíquidos | R8: ="de R$ "&FIXED(p_Aporte,2)&" planejados" -> de R$ 500.00 planejados | V8: ="Fica para o próximo aporte" -> Fica para o próximo aporte
B10: CLASSES A APORTAR | F10: ORDENS DE COMPRA | J10: MAIOR POSIÇÃO | N10: ATIVOS EFETIVOS (1/HHI) | R10: SETOR MAIS CONCENTRADO | V10: COTAÇÕES SEM PREÇO
B11: =COUNTIF('02 Macro Alocação'!$L$9:$L$15,"BUY") -> 6 | F11: =COUNTIF('12 Base de Dados'!$M$6:$M$925,">0") -> 0 | J11: ='11 Auxiliar'!$C$69 -> — | N11: =IFERROR(1/SUMSQ('12 Base de Dados'!$N$6:$N$925),0) -> 0 | R11: ='11 Auxiliar'!$C$129 -> — | V11: =COUNTIF('12 Base de Dados'!$O$6:$O$925,"Sem cotação")+COUNTIF('12 Base de Dados'!$O$6:$O$925,"Sem câmbio") -> 0
B12: ="de "&ROWS('02 Macro Alocação'!$L$9:$L$15)&" classes" -> de 7 classes | F12: ="ativos com ordem sugerida" -> ativos com ordem sugerida | J12: =IF('11 Auxiliar'!$C$69="—","sem posições",ROUND('11 Auxiliar'!$E$69*100,1)&"% do patrimônio") -> sem posições | N12: ="Quanto maior, mais diversificada" -> Quanto maior, mais diversificada | R12: =ROUND('11 Auxiliar'!$E$129*100,1)&"% do patrimônio" -> 0% do patrimônio | V12: ="Auto: "&COUNTIF('12 Base de Dados'!$O$6:$O$925,"Auto")&" · Manual: "&COUNTIF('12 Base de Dados'!$O$6:$O$925,"Manual") -> Auto: 0 · Manual: 0
B14: APORTE INTELIGENTE | R14: ="Aporte: R$ "&FIXED(p_Aporte,2)&" · compra efetiva: R$ "&FIXED('02 Macro Alocação'!$Q$16,2) -> Aporte: R$ 500.00 · compra efetiva: R$ 0.00
B15: Classe | D15: % Atual | F15: % Obj. | G15: Ação | H15: Aporte (R$) | J15: Ativo | L15: Classe | O15: Qtd. a Comprar | R15: Cotação | T15: Moeda | V15: Valor Efetivo (R$)
B16: ='02 Macro Alocação'!$B$9 -> Ações | D16: ='02 Macro Alocação'!$E$9 -> 0 | F16: ='02 Macro Alocação'!$F$9 -> 0.4 | G16: ='02 Macro Alocação'!$L$9 -> BUY | H16: ='02 Macro Alocação'!$M$9 -> 200 | J16: =IFERROR(INDEX('12 Base de Dados'!$C$6:$C$925,MATCH(LARGE('12 Base de Dados'!$Q$6:$Q$925,1),'12 Base de Dados'!$Q$6:$Q$925,0)),"") | L16: =IFERROR(INDEX('12 Base de Dados'!$A$6:$A$925,MATCH(LARGE('12 Base de Dados'!$Q$6:$Q$925,1),'12 Base de Dados'!$Q$6:$Q$925,0)),"") | O16: =IFERROR(INDEX('12 Base de Dados'!$L$6:$L$925,MATCH(LARGE('12 Base de Dados'!$Q$6:$Q$925,1),'12 Base de Dados'!$Q$6:$Q$925,0)),"") | R16: =IFERROR(INDEX('12 Base de Dados'!$H$6:$H$925,MATCH(LARGE('12 Base de Dados'!$Q$6:$Q$925,1),'12 Base de Dados'!$Q$6:$Q$925,0)),"") | T16: =IFERROR(INDEX('12 Base de Dados'!$F$6:$F$925,MATCH(LARGE('12 Base de Dados'!$Q$6:$Q$925,1),'12 Base de Dados'!$Q$6:$Q$925,0)),"") | V16: =IFERROR(INDEX('12 Base de Dados'!$M$6:$M$925,MATCH(LARGE('12 Base de Dados'!$Q$6:$Q$925,1),'12 Base de Dados'!$Q$6:$Q$925,0)),"")
B17: ='02 Macro Alocação'!$B$10 -> FIIs | D17: ='02 Macro Alocação'!$E$10 -> 0 | F17: ='02 Macro Alocação'!$F$10 -> 0.2 | G17: ='02 Macro Alocação'!$L$10 -> BUY | H17: ='02 Macro Alocação'!$M$10 -> 100 | J17: =IFERROR(INDEX('12 Base de Dados'!$C$6:$C$925,MATCH(LARGE('12 Base de Dados'!$Q$6:$Q$925,2),'12 Base de Dados'!$Q$6:$Q$925,0)),"") | L17: =IFERROR(INDEX('12 Base de Dados'!$A$6:$A$925,MATCH(LARGE('12 Base de Dados'!$Q$6:$Q$925,2),'12 Base de Dados'!$Q$6:$Q$925,0)),"") | O17: =IFERROR(INDEX('12 Base de Dados'!$L$6:$L$925,MATCH(LARGE('12 Base de Dados'!$Q$6:$Q$925,2),'12 Base de Dados'!$Q$6:$Q$925,0)),"") | R17: =IFERROR(INDEX('12 Base de Dados'!$H$6:$H$925,MATCH(LARGE('12 Base de Dados'!$Q$6:$Q$925,2),'12 Base de Dados'!$Q$6:$Q$925,0)),"") | T17: =IFERROR(INDEX('12 Base de Dados'!$F$6:$F$925,MATCH(LARGE('12 Base de Dados'!$Q$6:$Q$925,2),'12 Base de Dados'!$Q$6:$Q$925,0)),"") | V17: =IFERROR(INDEX('12 Base de Dados'!$M$6:$M$925,MATCH(LARGE('12 Base de Dados'!$Q$6:$Q$925,2),'12 Base de Dados'!$Q$6:$Q$925,0)),"")
B18: ='02 Macro Alocação'!$B$11 -> Renda Fixa | D18: ='02 Macro Alocação'!$E$11 -> 0 | F18: ='02 Macro Alocação'!$F$11 -> 0.05 | G18: ='02 Macro Alocação'!$L$11 -> BUY | H18: ='02 Macro Alocação'!$M$11 -> 25 | J18: =IFERROR(INDEX('12 Base de Dados'!$C$6:$C$925,MATCH(LARGE('12 Base de Dados'!$Q$6:$Q$925,3),'12 Base de Dados'!$Q$6:$Q$925,0)),"") | L18: =IFERROR(INDEX('12 Base de Dados'!$A$6:$A$925,MATCH(LARGE('12 Base de Dados'!$Q$6:$Q$925,3),'12 Base de Dados'!$Q$6:$Q$925,0)),"") | O18: =IFERROR(INDEX('12 Base de Dados'!$L$6:$L$925,MATCH(LARGE('12 Base de Dados'!$Q$6:$Q$925,3),'12 Base de Dados'!$Q$6:$Q$925,0)),"") | R18: =IFERROR(INDEX('12 Base de Dados'!$H$6:$H$925,MATCH(LARGE('12 Base de Dados'!$Q$6:$Q$925,3),'12 Base de Dados'!$Q$6:$Q$925,0)),"") | T18: =IFERROR(INDEX('12 Base de Dados'!$F$6:$F$925,MATCH(LARGE('12 Base de Dados'!$Q$6:$Q$925,3),'12 Base de Dados'!$Q$6:$Q$925,0)),"") | V18: =IFERROR(INDEX('12 Base de Dados'!$M$6:$M$925,MATCH(LARGE('12 Base de Dados'!$Q$6:$Q$925,3),'12 Base de Dados'!$Q$6:$Q$925,0)),"")
B19: ='02 Macro Alocação'!$B$12 -> Stocks | D19: ='02 Macro Alocação'!$E$12 -> 0 | F19: ='02 Macro Alocação'!$F$12 -> 0.2 | G19: ='02 Macro Alocação'!$L$12 -> BUY | H19: ='02 Macro Alocação'!$M$12 -> 100 | J19: =IFERROR(INDEX('12 Base de Dados'!$C$6:$C$925,MATCH(LARGE('12 Base de Dados'!$Q$6:$Q$925,4),'12 Base de Dados'!$Q$6:$Q$925,0)),"") | L19: =IFERROR(INDEX('12 Base de Dados'!$A$6:$A$925,MATCH(LARGE('12 Base de Dados'!$Q$6:$Q$925,4),'12 Base de Dados'!$Q$6:$Q$925,0)),"") | O19: =IFERROR(INDEX('12 Base de Dados'!$L$6:$L$925,MATCH(LARGE('12 Base de Dados'!$Q$6:$Q$925,4),'12 Base de Dados'!$Q$6:$Q$925,0)),"") | R19: =IFERROR(INDEX('12 Base de Dados'!$H$6:$H$925,MATCH(LARGE('12 Base de Dados'!$Q$6:$Q$925,4),'12 Base de Dados'!$Q$6:$Q$925,0)),"") | T19: =IFERROR(INDEX('12 Base de Dados'!$F$6:$F$925,MATCH(LARGE('12 Base de Dados'!$Q$6:$Q$925,4),'12 Base de Dados'!$Q$6:$Q$925,0)),"") | V19: =IFERROR(INDEX('12 Base de Dados'!$M$6:$M$925,MATCH(LARGE('12 Base de Dados'!$Q$6:$Q$925,4),'12 Base de Dados'!$Q$6:$Q$925,0)),"")
B20: ='02 Macro Alocação'!$B$13 -> REITs | D20: ='02 Macro Alocação'!$E$13 -> 0 | F20: ='02 Macro Alocação'!$F$13 -> 0.1 | G20: ='02 Macro Alocação'!$L$13 -> BUY | H20: ='02 Macro Alocação'!$M$13 -> 50 | J20: =IFERROR(INDEX('12 Base de Dados'!$C$6:$C$925,MATCH(LARGE('12 Base de Dados'!$Q$6:$Q$925,5),'12 Base de Dados'!$Q$6:$Q$925,0)),"") | L20: =IFERROR(INDEX('12 Base de Dados'!$A$6:$A$925,MATCH(LARGE('12 Base de Dados'!$Q$6:$Q$925,5),'12 Base de Dados'!$Q$6:$Q$925,0)),"") | O20: =IFERROR(INDEX('12 Base de Dados'!$L$6:$L$925,MATCH(LARGE('12 Base de Dados'!$Q$6:$Q$925,5),'12 Base de Dados'!$Q$6:$Q$925,0)),"") | R20: =IFERROR(INDEX('12 Base de Dados'!$H$6:$H$925,MATCH(LARGE('12 Base de Dados'!$Q$6:$Q$925,5),'12 Base de Dados'!$Q$6:$Q$925,0)),"") | T20: =IFERROR(INDEX('12 Base de Dados'!$F$6:$F$925,MATCH(LARGE('12 Base de Dados'!$Q$6:$Q$925,5),'12 Base de Dados'!$Q$6:$Q$925,0)),"") | V20: =IFERROR(INDEX('12 Base de Dados'!$M$6:$M$925,MATCH(LARGE('12 Base de Dados'!$Q$6:$Q$925,5),'12 Base de Dados'!$Q$6:$Q$925,0)),"")
B21: ='02 Macro Alocação'!$B$14 -> Criptomoedas | D21: ='02 Macro Alocação'!$E$14 -> 0 | F21: ='02 Macro Alocação'!$F$14 -> 0.05 | G21: ='02 Macro Alocação'!$L$14 -> BUY | H21: ='02 Macro Alocação'!$M$14 -> 25 | J21: =IFERROR(INDEX('12 Base de Dados'!$C$6:$C$925,MATCH(LARGE('12 Base de Dados'!$Q$6:$Q$925,6),'12 Base de Dados'!$Q$6:$Q$925,0)),"") | L21: =IFERROR(INDEX('12 Base de Dados'!$A$6:$A$925,MATCH(LARGE('12 Base de Dados'!$Q$6:$Q$925,6),'12 Base de Dados'!$Q$6:$Q$925,0)),"") | O21: =IFERROR(INDEX('12 Base de Dados'!$L$6:$L$925,MATCH(LARGE('12 Base de Dados'!$Q$6:$Q$925,6),'12 Base de Dados'!$Q$6:$Q$925,0)),"") | R21: =IFERROR(INDEX('12 Base de Dados'!$H$6:$H$925,MATCH(LARGE('12 Base de Dados'!$Q$6:$Q$925,6),'12 Base de Dados'!$Q$6:$Q$925,0)),"") | T21: =IFERROR(INDEX('12 Base de Dados'!$F$6:$F$925,MATCH(LARGE('12 Base de Dados'!$Q$6:$Q$925,6),'12 Base de Dados'!$Q$6:$Q$925,0)),"") | V21: =IFERROR(INDEX('12 Base de Dados'!$M$6:$M$925,MATCH(LARGE('12 Base de Dados'!$Q$6:$Q$925,6),'12 Base de Dados'!$Q$6:$Q$925,0)),"")
B22: ='02 Macro Alocação'!$B$15 -> Ativos Ilíquidos | D22: ='02 Macro Alocação'!$E$15 -> 0 | F22: ='02 Macro Alocação'!$F$15 -> 0 | G22: ='02 Macro Alocação'!$L$15 -> HOLD | H22: ='02 Macro Alocação'!$M$15 -> 0 | J22: =IFERROR(INDEX('12 Base de Dados'!$C$6:$C$925,MATCH(LARGE('12 Base de Dados'!$Q$6:$Q$925,7),'12 Base de Dados'!$Q$6:$Q$925,0)),"") | L22: =IFERROR(INDEX('12 Base de Dados'!$A$6:$A$925,MATCH(LARGE('12 Base de Dados'!$Q$6:$Q$925,7),'12 Base de Dados'!$Q$6:$Q$925,0)),"") | O22: =IFERROR(INDEX('12 Base de Dados'!$L$6:$L$925,MATCH(LARGE('12 Base de Dados'!$Q$6:$Q$925,7),'12 Base de Dados'!$Q$6:$Q$925,0)),"") | R22: =IFERROR(INDEX('12 Base de Dados'!$H$6:$H$925,MATCH(LARGE('12 Base de Dados'!$Q$6:$Q$925,7),'12 Base de Dados'!$Q$6:$Q$925,0)),"") | T22: =IFERROR(INDEX('12 Base de Dados'!$F$6:$F$925,MATCH(LARGE('12 Base de Dados'!$Q$6:$Q$925,7),'12 Base de Dados'!$Q$6:$Q$925,0)),"") | V22: =IFERROR(INDEX('12 Base de Dados'!$M$6:$M$925,MATCH(LARGE('12 Base de Dados'!$Q$6:$Q$925,7),'12 Base de Dados'!$Q$6:$Q$925,0)),"")
B23: TOTAL | D23: ='02 Macro Alocação'!$E$16 -> 0 | F23: ='02 Macro Alocação'!$F$16 -> 1 | H23: ='02 Macro Alocação'!$M$16 -> 500 | J23: =IFERROR(INDEX('12 Base de Dados'!$C$6:$C$925,MATCH(LARGE('12 Base de Dados'!$Q$6:$Q$925,8),'12 Base de Dados'!$Q$6:$Q$925,0)),"") | L23: =IFERROR(INDEX('12 Base de Dados'!$A$6:$A$925,MATCH(LARGE('12 Base de Dados'!$Q$6:$Q$925,8),'12 Base de Dados'!$Q$6:$Q$925,0)),"") | O23: =IFERROR(INDEX('12 Base de Dados'!$L$6:$L$925,MATCH(LARGE('12 Base de Dados'!$Q$6:$Q$925,8),'12 Base de Dados'!$Q$6:$Q$925,0)),"") | R23: =IFERROR(INDEX('12 Base de Dados'!$H$6:$H$925,MATCH(LARGE('12 Base de Dados'!$Q$6:$Q$925,8),'12 Base de Dados'!$Q$6:$Q$925,0)),"") | T23: =IFERROR(INDEX('12 Base de Dados'!$F$6:$F$925,MATCH(LARGE('12 Base de Dados'!$Q$6:$Q$925,8),'12 Base de Dados'!$Q$6:$Q$925,0)),"") | V23: =IFERROR(INDEX('12 Base de Dados'!$M$6:$M$925,MATCH(LARGE('12 Base de Dados'!$Q$6:$Q$925,8),'12 Base de Dados'!$Q$6:$Q$925,0)),"")
B24: Sobra após lotes/frações/custos | H24: ='02 Macro Alocação'!$R$16 -> 500 | J24: =IFERROR(INDEX('12 Base de Dados'!$C$6:$C$925,MATCH(LARGE('12 Base de Dados'!$Q$6:$Q$925,9),'12 Base de Dados'!$Q$6:$Q$925,0)),"") | L24: =IFERROR(INDEX('12 Base de Dados'!$A$6:$A$925,MATCH(LARGE('12 Base de Dados'!$Q$6:$Q$925,9),'12 Base de Dados'!$Q$6:$Q$925,0)),"") | O24: =IFERROR(INDEX('12 Base de Dados'!$L$6:$L$925,MATCH(LARGE('12 Base de Dados'!$Q$6:$Q$925,9),'12 Base de Dados'!$Q$6:$Q$925,0)),"") | R24: =IFERROR(INDEX('12 Base de Dados'!$H$6:$H$925,MATCH(LARGE('12 Base de Dados'!$Q$6:$Q$925,9),'12 Base de Dados'!$Q$6:$Q$925,0)),"") | T24: =IFERROR(INDEX('12 Base de Dados'!$F$6:$F$925,MATCH(LARGE('12 Base de Dados'!$Q$6:$Q$925,9),'12 Base de Dados'!$Q$6:$Q$925,0)),"") | V24: =IFERROR(INDEX('12 Base de Dados'!$M$6:$M$925,MATCH(LARGE('12 Base de Dados'!$Q$6:$Q$925,9),'12 Base de Dados'!$Q$6:$Q$925,0)),"")
J25: =IFERROR(INDEX('12 Base de Dados'!$C$6:$C$925,MATCH(LARGE('12 Base de Dados'!$Q$6:$Q$925,10),'12 Base de Dados'!$Q$6:$Q$925,0)),"") | L25: =IFERROR(INDEX('12 Base de Dados'!$A$6:$A$925,MATCH(LARGE('12 Base de Dados'!$Q$6:$Q$925,10),'12 Base de Dados'!$Q$6:$Q$925,0)),"") | O25: =IFERROR(INDEX('12 Base de Dados'!$L$6:$L$925,MATCH(LARGE('12 Base de Dados'!$Q$6:$Q$925,10),'12 Base de Dados'!$Q$6:$Q$925,0)),"") | R25: =IFERROR(INDEX('12 Base de Dados'!$H$6:$H$925,MATCH(LARGE('12 Base de Dados'!$Q$6:$Q$925,10),'12 Base de Dados'!$Q$6:$Q$925,0)),"") | T25: =IFERROR(INDEX('12 Base de Dados'!$F$6:$F$925,MATCH(LARGE('12 Base de Dados'!$Q$6:$Q$925,10),'12 Base de Dados'!$Q$6:$Q$925,0)),"") | V25: =IFERROR(INDEX('12 Base de Dados'!$M$6:$M$925,MATCH(LARGE('12 Base de Dados'!$Q$6:$Q$925,10),'12 Base de Dados'!$Q$6:$Q$925,0)),"")
J26: PLANO DE COMPRAS: as 10 maiores ordens (quantidade, lote e custos já aplicados). Detalhes nas abas de cada classe.
B28: ALOCAÇÃO E EXPOSIÇÃO
B61: CONTROLE DE RISCO
B62: CONCENTRAÇÃO POR ATIVO | J62: CONCENTRAÇÃO POR SETOR (TOP 6) | R62: EXPOSIÇÃO GEOGRÁFICA E CAMBIAL
B63: Maior posição | F63: =IF('11 Auxiliar'!$C$69="—","—",'11 Auxiliar'!$C$69&" · "&ROUND('11 Auxiliar'!$E$69*100,1)&"%") -> — | J63: ='11 Auxiliar'!$C$129 -> — | N63: ='11 Auxiliar'!$E$129 -> 0 | P63: =IF(N63>p_LimSetor,"ALERTA","OK") -> OK | R63: Grupo | V63: Atual | X63: Objetivo
B64: Menor posição | F64: =IFERROR(INDEX('12 Base de Dados'!$C$6:$C$925,MATCH(SMALL('12 Base de Dados'!$P$6:$P$925,1),'12 Base de Dados'!$P$6:$P$925,0))&" · "&ROUND(INDEX('12 Base de Dados'!$N$6:$N$925,MATCH(SMALL('12 Base de Dados'!$P$6:$P$925,1),'12 Base de Dados'!$P$6:$P$925,0))*100,2)&"%","—") -> — | J64: ='11 Auxiliar'!$C$130 -> — | N64: ='11 Auxiliar'!$E$130 -> 0 | P64: =IF(N64>p_LimSetor,"ALERTA","OK") -> OK | R64: Brasil | V64: ='02 Macro Alocação'!$E$20 -> 0 | X64: ='02 Macro Alocação'!$F$20 -> 0.65
B65: Top 5 posições | F65: =SUM('11 Auxiliar'!$E$69:$E$73) -> 0 | J65: ='11 Auxiliar'!$C$131 -> — | N65: ='11 Auxiliar'!$E$131 -> 0 | P65: =IF(N65>p_LimSetor,"ALERTA","OK") -> OK | R65: Exterior | V65: ='02 Macro Alocação'!$E$21 -> 0 | X65: ='02 Macro Alocação'!$F$21 -> 0.3
B66: Top 10 posições | F66: =SUM('11 Auxiliar'!$E$69:$E$78) -> 0 | J66: ='11 Auxiliar'!$C$132 -> — | N66: ='11 Auxiliar'!$E$132 -> 0 | P66: =IF(N66>p_LimSetor,"ALERTA","OK") -> OK | R66: Alternativos | V66: ='02 Macro Alocação'!$E$22 -> 0 | X66: ='02 Macro Alocação'!$F$22 -> 0.05
B67: Ativos efetivos (1/HHI) | F67: =IFERROR(1/SUMSQ('12 Base de Dados'!$N$6:$N$925),0) -> 0 | J67: ='11 Auxiliar'!$C$133 -> — | N67: ='11 Auxiliar'!$E$133 -> 0 | P67: =IF(N67>p_LimSetor,"ALERTA","OK") -> OK | R67: Moeda | V67: Atual
B68: Nº de ativos | F68: =SUMPRODUCT(--('12 Base de Dados'!$C$6:$C$925<>"")) -> 0 | J68: ='11 Auxiliar'!$C$134 -> — | N68: ='11 Auxiliar'!$E$134 -> 0 | P68: =IF(N68>p_LimSetor,"ALERTA","OK") -> OK | R68: ='11 Auxiliar'!$B$139 -> BRL | V68: ='11 Auxiliar'!$D$139 -> 0
B69: Limite por ativo | F69: =p_LimAtivo -> 0.1 | J69: Limite por setor | N69: =p_LimSetor -> 0.3 | R69: ='11 Auxiliar'!$B$140 -> USD | V69: ='11 Auxiliar'!$D$140 -> 0
B70: Posições acima do limite | F70: =COUNTIF('12 Base de Dados'!$N$6:$N$925,">"&p_LimAtivo) -> 0 | J70: Setores acima do limite | N70: =COUNTIF('11 Auxiliar'!$E$129:$E$134,">"&p_LimSetor) -> 0 | R70: ='11 Auxiliar'!$B$141 -> EUR | V70: ='11 Auxiliar'!$D$141 -> 0
R71: ='11 Auxiliar'!$B$142 -> Outras | V71: ='11 Auxiliar'!$D$142 -> 0
B73: HOLDER PREMIUM · Informativo, não constitui recomendação de investimento. Cotações dependem da fonte configurada.

Sheet 02 Macro Alocação
A1: MACRO ALOCAÇÃO | R1: ◄ Dashboard
A2: Defina o % objetivo de cada classe. A planilha calcula o percentual atual, a diferença, BUY/HOLD e distribui o aporte pelas classes mais distantes do objetivo.
B4: APORTE DO MÊS (digite no Dashboard) | D4: PATRIMÔNIO ATUAL | F4: PATRIMÔNIO PÓS-APORTE | I4: CLASSES A APORTAR | K4: SOMA DOS OBJETIVOS | N4: COMPRA EFETIVA (R$) | Q4: SOBRA (R$)
B5: =p_Aporte -> 500 | D5: =D16 -> 0 | F5: =D16+p_Aporte -> 500 | I5: =COUNTIF($L$9:$L$15,"BUY") -> 6 | K5: =F16 -> 1 | N5: =Q16 -> 0 | Q5: =R16 -> 500
B7: ALOCAÇÃO-ALVO POR CLASSE E APORTE INTELIGENTE
B8: Classe | C8: Grupo | D8: Valor Atual (R$) | E8: % Atual | F8: % Objetivo | G8: Diferença (p.p.) | H8: Situação | I8: Déficit p/ Objetivo (R$) | J8: Rebalance Score | K8: Prior. | L8: BUY / HOLD | M8: Aporte Sugerido (R$) | N8: % do Aporte | O8: Valor Pós-Aporte (R$) | P8: % Pós-Aporte | Q8: Compra Efetiva (R$) | R8: Sobra (R$) | T8: Déficit elegível | U8: Déficit final
B9: Ações | C9: Brasil | D9: ='03 Ações BR'!$K$6 -> 0 | E9: =IF($D$16>0,D9/$D$16,0) -> 0 | F9: 0.4 | G9: =F9-E9 -> 0.4 | H9: =IF(ABS(G9)<p_DifMin,"Alinhado",IF(G9>0,"Subpeso","Sobrepeso")) -> Subpeso | I9: =ROUND(MAX(0,F9*($D$16+p_Aporte)-D9),2) -> 200 | J9: =IF($T$16>0,T9/$T$16,0) -> 0.4 | K9: =IF(T9<=0,"",COUNTIF($T$9:$T$15,">"&T9)+COUNTIF($T$9:T9,T9)) -> 1 | L9: =IF(M9>0,"BUY","HOLD") -> BUY | M9: =IF(p_Aporte<=0,0,IF($U$16>0,p_Aporte*U9/$U$16,IF($F$16>0,p_Aporte*F9/$F$16,0))) -> 200 | N9: =IF(p_Aporte>0,M9/p_Aporte,0) -> 0.4 | O9: =D9+M9 -> 200 | P9: =IF($D$16+p_Aporte>0,O9/($D$16+p_Aporte),0) -> 0.4 | Q9: ='03 Ações BR'!$T$6 -> 0 | R9: =M9-Q9 -> 200 | T9: =IF(AND(G9>0,G9>=p_DifMin),I9,0) -> 200 | U9: =IF(AND(T9>0,N(K9)<=p_MaxClasses),T9,0) -> 200
B10: FIIs | C10: Brasil | D10: ='04 FIIs'!$K$6 -> 0 | E10: =IF($D$16>0,D10/$D$16,0) -> 0 | F10: 0.2 | G10: =F10-E10 -> 0.2 | H10: =IF(ABS(G10)<p_DifMin,"Alinhado",IF(G10>0,"Subpeso","Sobrepeso")) -> Subpeso | I10: =ROUND(MAX(0,F10*($D$16+p_Aporte)-D10),2) -> 100 | J10: =IF($T$16>0,T10/$T$16,0) -> 0.2 | K10: =IF(T10<=0,"",COUNTIF($T$9:$T$15,">"&T10)+COUNTIF($T$9:T10,T10)) -> 2 | L10: =IF(M10>0,"BUY","HOLD") -> BUY | M10: =IF(p_Aporte<=0,0,IF($U$16>0,p_Aporte*U10/$U$16,IF($F$16>0,p_Aporte*F10/$F$16,0))) -> 100 | N10: =IF(p_Aporte>0,M10/p_Aporte,0) -> 0.2 | O10: =D10+M10 -> 100 | P10: =IF($D$16+p_Aporte>0,O10/($D$16+p_Aporte),0) -> 0.2 | Q10: ='04 FIIs'!$T$6 -> 0 | R10: =M10-Q10 -> 100 | T10: =IF(AND(G10>0,G10>=p_DifMin),I10,0) -> 100 | U10: =IF(AND(T10>0,N(K10)<=p_MaxClasses),T10,0) -> 100
B11: Renda Fixa | C11: Brasil | D11: ='07 Renda Fixa'!$J$6 -> 0 | E11: =IF($D$16>0,D11/$D$16,0) -> 0 | F11: 0.05 | G11: =F11-E11 -> 0.05 | H11: =IF(ABS(G11)<p_DifMin,"Alinhado",IF(G11>0,"Subpeso","Sobrepeso")) -> Subpeso | I11: =ROUND(MAX(0,F11*($D$16+p_Aporte)-D11),2) -> 25 | J11: =IF($T$16>0,T11/$T$16,0) -> 0.05 | K11: =IF(T11<=0,"",COUNTIF($T$9:$T$15,">"&T11)+COUNTIF($T$9:T11,T11)) -> 5 | L11: =IF(M11>0,"BUY","HOLD") -> BUY | M11: =IF(p_Aporte<=0,0,IF($U$16>0,p_Aporte*U11/$U$16,IF($F$16>0,p_Aporte*F11/$F$16,0))) -> 25 | N11: =IF(p_Aporte>0,M11/p_Aporte,0) -> 0.05 | O11: =D11+M11 -> 25 | P11: =IF($D$16+p_Aporte>0,O11/($D$16+p_Aporte),0) -> 0.05 | Q11: ='07 Renda Fixa'!$Q$6 -> 0 | R11: =M11-Q11 -> 25 | T11: =IF(AND(G11>0,G11>=p_DifMin),I11,0) -> 25 | U11: =IF(AND(T11>0,N(K11)<=p_MaxClasses),T11,0) -> 25
B12: Stocks | C12: Exterior | D12: ='05 Stocks'!$K$6 -> 0 | E12: =IF($D$16>0,D12/$D$16,0) -> 0 | F12: 0.2 | G12: =F12-E12 -> 0.2 | H12: =IF(ABS(G12)<p_DifMin,"Alinhado",IF(G12>0,"Subpeso","Sobrepeso")) -> Subpeso | I12: =ROUND(MAX(0,F12*($D$16+p_Aporte)-D12),2) -> 100 | J12: =IF($T$16>0,T12/$T$16,0) -> 0.2 | K12: =IF(T12<=0,"",COUNTIF($T$9:$T$15,">"&T12)+COUNTIF($T$9:T12,T12)) -> 3 | L12: =IF(M12>0,"BUY","HOLD") -> BUY | M12: =IF(p_Aporte<=0,0,IF($U$16>0,p_Aporte*U12/$U$16,IF($F$16>0,p_Aporte*F12/$F$16,0))) -> 100 | N12: =IF(p_Aporte>0,M12/p_Aporte,0) -> 0.2 | O12: =D12+M12 -> 100 | P12: =IF($D$16+p_Aporte>0,O12/($D$16+p_Aporte),0) -> 0.2 | Q12: ='05 Stocks'!$T$6 -> 0 | R12: =M12-Q12 -> 100 | T12: =IF(AND(G12>0,G12>=p_DifMin),I12,0) -> 100 | U12: =IF(AND(T12>0,N(K12)<=p_MaxClasses),T12,0) -> 100
B13: REITs | C13: Exterior | D13: ='06 REITs'!$K$6 -> 0 | E13: =IF($D$16>0,D13/$D$16,0) -> 0 | F13: 0.1 | G13: =F13-E13 -> 0.1 | H13: =IF(ABS(G13)<p_DifMin,"Alinhado",IF(G13>0,"Subpeso","Sobrepeso")) -> Subpeso | I13: =ROUND(MAX(0,F13*($D$16+p_Aporte)-D13),2) -> 50 | J13: =IF($T$16>0,T13/$T$16,0) -> 0.1 | K13: =IF(T13<=0,"",COUNTIF($T$9:$T$15,">"&T13)+COUNTIF($T$9:T13,T13)) -> 4 | L13: =IF(M13>0,"BUY","HOLD") -> BUY | M13: =IF(p_Aporte<=0,0,IF($U$16>0,p_Aporte*U13/$U$16,IF($F$16>0,p_Aporte*F13/$F$16,0))) -> 50 | N13: =IF(p_Aporte>0,M13/p_Aporte,0) -> 0.1 | O13: =D13+M13 -> 50 | P13: =IF($D$16+p_Aporte>0,O13/($D$16+p_Aporte),0) -> 0.1 | Q13: ='06 REITs'!$T$6 -> 0 | R13: =M13-Q13 -> 50 | T13: =IF(AND(G13>0,G13>=p_DifMin),I13,0) -> 50 | U13: =IF(AND(T13>0,N(K13)<=p_MaxClasses),T13,0) -> 50
B14: Criptomoedas | C14: Alternativos | D14: ='08 Criptomoedas'!$L$6 -> 0 | E14: =IF($D$16>0,D14/$D$16,0) -> 0 | F14: 0.05 | G14: =F14-E14 -> 0.05 | H14: =IF(ABS(G14)<p_DifMin,"Alinhado",IF(G14>0,"Subpeso","Sobrepeso")) -> Subpeso | I14: =ROUND(MAX(0,F14*($D$16+p_Aporte)-D14),2) -> 25 | J14: =IF($T$16>0,T14/$T$16,0) -> 0.05 | K14: =IF(T14<=0,"",COUNTIF($T$9:$T$15,">"&T14)+COUNTIF($T$9:T14,T14)) -> 6 | L14: =IF(M14>0,"BUY","HOLD") -> BUY | M14: =IF(p_Aporte<=0,0,IF($U$16>0,p_Aporte*U14/$U$16,IF($F$16>0,p_Aporte*F14/$F$16,0))) -> 25 | N14: =IF(p_Aporte>0,M14/p_Aporte,0) -> 0.05 | O14: =D14+M14 -> 25 | P14: =IF($D$16+p_Aporte>0,O14/($D$16+p_Aporte),0) -> 0.05 | Q14: ='08 Criptomoedas'!$U$6 -> 0 | R14: =M14-Q14 -> 25 | T14: =IF(AND(G14>0,G14>=p_DifMin),I14,0) -> 25 | U14: =IF(AND(T14>0,N(K14)<=p_MaxClasses),T14,0) -> 25
B15: Ativos Ilíquidos | C15: Alternativos | D15: ='09 Ativos Ilíquidos'!$H$6 -> 0 | E15: =IF($D$16>0,D15/$D$16,0) -> 0 | F15: 0 | G15: =F15-E15 -> 0 | H15: =IF(ABS(G15)<p_DifMin,"Alinhado",IF(G15>0,"Subpeso","Sobrepeso")) -> Alinhado | I15: =ROUND(MAX(0,F15*($D$16+p_Aporte)-D15),2) -> 0 | J15: =IF($T$16>0,T15/$T$16,0) -> 0 | K15: =IF(T15<=0,"",COUNTIF($T$9:$T$15,">"&T15)+COUNTIF($T$9:T15,T15)) | L15: =IF(M15>0,"BUY","HOLD") -> HOLD | M15: =IF(p_Aporte<=0,0,IF($U$16>0,p_Aporte*U15/$U$16,IF($F$16>0,p_Aporte*F15/$F$16,0))) -> 0 | N15: =IF(p_Aporte>0,M15/p_Aporte,0) -> 0 | O15: =D15+M15 -> 0 | P15: =IF($D$16+p_Aporte>0,O15/($D$16+p_Aporte),0) -> 0 | Q15: ='09 Ativos Ilíquidos'!$O$6 -> 0 | R15: =M15-Q15 -> 0 | T15: =IF(AND(G15>0,G15>=p_DifMin),I15,0) -> 0 | U15: =IF(AND(T15>0,N(K15)<=p_MaxClasses),T15,0) -> 0
B16: TOTAL | D16: =SUM(D9:D15) -> 0 | E16: =SUM(E9:E15) -> 0 | F16: =SUM(F9:F15) -> 1 | I16: =SUM(I9:I15) -> 500 | J16: =SUM(J9:J15) -> 1 | M16: =SUM(M9:M15) -> 500 | N16: =SUM(N9:N15) -> 1 | O16: =SUM(O9:O15) -> 500 | P16: =SUM(P9:P15) -> 1 | Q16: =SUM(Q9:Q15) -> 0 | R16: =SUM(R9:R15) -> 500 | T16: =SUM(T9:T15) -> 500 | U16: =SUM(U9:U15) -> 500
B17: Como funciona: Déficit = máx(0; % Objetivo × (Patrimônio + Aporte) − Valor Atual). O Rebalance Score é o déficit da classe ÷ soma dos déficits das classes elegíveis (diferença ≥ valor mínimo em Configurações). O aporte é dividido proporcionalmente ao Score entre as N classes de maior prioridade. Classes em sobrepeso recebem HOLD. A Compra Efetiva usa as ordens reais das abas de cada classe (lote, fração, custos e reaproveitamento da sobra).
B18: EXPOSIÇÃO GEOGRÁFICA: BRASIL × EXTERIOR × ALTERNATIVOS
B19: Grupo | D19: Valor Atual (R$) | E19: % Atual | F19: % Objetivo | G19: Diferença (p.p.) | H19: Situação | M19: Aporte Sugerido (R$) | O19: Valor Pós-Aporte (R$) | P19: % Pós-Aporte
B20: Brasil | D20: =SUMIF($C$9:$C$15,"Brasil",$D$9:$D$15) -> 0 | E20: =SUMIF($C$9:$C$15,"Brasil",$E$9:$E$15) -> 0 | F20: =SUMIF($C$9:$C$15,"Brasil",$F$9:$F$15) -> 0.65 | G20: =F20-E20 -> 0.65 | H20: =IF(ABS(G20)<p_DifMin,"Alinhado",IF(G20>0,"Subpeso","Sobrepeso")) -> Subpeso | M20: =SUMIF($C$9:$C$15,"Brasil",$M$9:$M$15) -> 325 | O20: =SUMIF($C$9:$C$15,"Brasil",$O$9:$O$15) -> 325 | P20: =SUMIF($C$9:$C$15,"Brasil",$P$9:$P$15) -> 0.65
B21: Exterior | D21: =SUMIF($C$9:$C$15,"Exterior",$D$9:$D$15) -> 0 | E21: =SUMIF($C$9:$C$15,"Exterior",$E$9:$E$15) -> 0 | F21: =SUMIF($C$9:$C$15,"Exterior",$F$9:$F$15) -> 0.3 | G21: =F21-E21 -> 0.3 | H21: =IF(ABS(G21)<p_DifMin,"Alinhado",IF(G21>0,"Subpeso","Sobrepeso")) -> Subpeso | M21: =SUMIF($C$9:$C$15,"Exterior",$M$9:$M$15) -> 150 | O21: =SUMIF($C$9:$C$15,"Exterior",$O$9:$O$15) -> 150 | P21: =SUMIF($C$9:$C$15,"Exterior",$P$9:$P$15) -> 0.3
B22: Alternativos | D22: =SUMIF($C$9:$C$15,"Alternativos",$D$9:$D$15) -> 0 | E22: =SUMIF($C$9:$C$15,"Alternativos",$E$9:$E$15) -> 0 | F22: =SUMIF($C$9:$C$15,"Alternativos",$F$9:$F$15) -> 0.05 | G22: =F22-E22 -> 0.05 | H22: =IF(ABS(G22)<p_DifMin,"Alinhado",IF(G22>0,"Subpeso","Sobrepeso")) -> Subpeso | M22: =SUMIF($C$9:$C$15,"Alternativos",$M$9:$M$15) -> 25 | O22: =SUMIF($C$9:$C$15,"Alternativos",$O$9:$O$15) -> 25 | P22: =SUMIF($C$9:$C$15,"Alternativos",$P$9:$P$15) -> 0.05
B23: TOTAL | D23: =SUM(D20:D22) -> 0 | E23: =SUM(E20:E22) -> 0 | F23: =SUM(F20:F22) -> 1 | M23: =SUM(M20:M22) -> 500 | O23: =SUM(O20:O22) -> 500 | P23: =SUM(P20:P22) -> 1

Sheet 03 Ações BR
A1: AÇÕES BR | T1: ◄ Dashboard | V1: Moeda padrão da classe | W1: =INDEX('10 Configurações'!$D$35:$D$41,MATCH("Ações",'10 Configurações'!$B$35:$B$41,0))&"" -> BRL | X1: Sobra da 1ª passada (R$) | Y1: =MAX(0,$W$7-SUM($AE$9:$AE$208)) -> 200
A2: ="Moeda padrão: "&$W$1&" · Fração: "&$W$3&" ("&$W$4&" casas) · Lote: "&$W$5&" · Custo efetivo de compra: "&ROUND(($W$6-1)*100,2)&"% · Cotações: "&p_ModoCot -> Moeda padrão: BRL · Fração: Não (0 casas) · Lote: 1 · Custo efetivo de compra: 0% · Cotações: Automático | V2: Sufixo Yahoo | W2: =INDEX('10 Configurações'!$E$35:$E$41,MATCH("Ações",'10 Configurações'!$B$35:$B$41,0))&"" -> .SA
A3: VALOR DA CLASSE (R$) | C3: Nº DE ATIVOS | G3: APORTE DESTINADO (R$) | K3: COMPRA EFETIVA (R$) | O3: SOBRA DA CLASSE (R$) | T3: SOMA DOS OBJETIVOS | V3: Permite fração? | W3: =INDEX('10 Configurações'!$G$35:$G$41,MATCH("Ações",'10 Configurações'!$B$35:$B$41,0))&"" -> Não
A4: =$K$6 -> 0 | C4: =SUMPRODUCT(--($A$9:$A$208<>"")) -> 0 | G4: =$W$7 -> 200 | K4: =$T$6 -> 0 | O4: =$W$7-$T$6 -> 200 | T4: =$F$6 -> 0 | V4: Casas decimais | W4: =N(INDEX('10 Configurações'!$H$35:$H$41,MATCH("Ações",'10 Configurações'!$B$35:$B$41,0))) -> 0
A5: ■ Azul = entrada de dados (você só altera Quantidade, Objetivo e, se quiser, Cotação Manual) ■ Demais células = fórmulas ■ Depois de comprar: copie 'Qtd. Após Compra' e cole como valores em 'Quantidade' | V5: Lote efetivo | W5: =IF(INDEX('10 Configurações'!$I$35:$I$41,MATCH("Ações",'10 Configurações'!$B$35:$B$41,0))="Sim",MAX(1,N(INDEX('10 Configurações'!$J$35:$J$41,MATCH("Ações",'10 Configurações'!$B$35:$B$41,0)))),1) -> 1
A6: TOTAL | F6: =SUM($F$9:$F$208) -> 0 | K6: =SUM($K$9:$K$208) -> 0 | L6: =SUM($L$9:$L$208) -> 0 | N6: =SUM($N$9:$N$208) -> 0 | Q6: =SUM($Q$9:$Q$208) -> 0 | T6: =SUM($T$9:$T$208) -> 0 | V6: Fator de custo (1 + custos) | W6: =1+N(INDEX('10 Configurações'!$K$35:$K$41,MATCH("Ações",'10 Configurações'!$B$35:$B$41,0))) -> 1 | AB6: =SUM($AB$9:$AB$208) -> 0 | AC6: =SUM($AC$9:$AC$208) -> 0 | AH6: =MAX($AH$9:$AH$208) -> 0
A7: CADASTRO | E7: POSIÇÃO E OBJETIVO | G7: COTAÇÃO | J7: VALOR | M7: REBALANCEAMENTO | V7: Aporte destinado à classe (R$) | W7: ='02 Macro Alocação'!$M$9 -> 200
A8: Ticker | B8: Nome / Descrição | C8: Setor / Segmento | D8: Moeda | E8: Quantidade | F8: Objetivo (% da classe) | G8: Cotação Manual (opcional) | H8: Cotação | I8: Fonte | J8: Valor Atual (Moeda) | K8: Valor Atual (R$) | L8: Part. na Classe | M8: Diferença | N8: Rebalance Score | O8: Prior. | P8: Ação | Q8: Valor Sugerido (R$) | R8: Qtd. Sugerida | S8: Qtd. Após Compra | T8: Valor Efetivo (R$) | V8: Moeda efetiva | W8: Câmbio (R$) | X8: Ticker Yahoo | Y8: Resposta da API | Z8: Cotação auto | AA8: Déficit (R$) | AB8: Déficit elegível | AC8: Déficit final | AD8: Qtd 1ª passada | AE8: Valor 1ª passada (R$) | AF8: Qtd extra (bruta) | AG8: Qtd extra | AH8: Prioridade extra | AI8: Recebe a sobra
H9: =IF(A9="","",IF(AND(p_ModoCot="Automático",ISNUMBER(Z9)),Z9,IF(N(G9)>0,G9,0))) | I9: =IF(A9="","",IF(W9=0,"Sem câmbio",IF(AND(p_ModoCot="Automático",ISNUMBER(Z9)),"Auto",IF(N(G9)>0,"Manual","Sem cotação")))) | J9: =IF(A9="","",N(E9)*H9) | K9: =IF(A9="","",J9*W9) | L9: =IF(A9="","",IF($K$6>0,K9/$K$6,0)) | M9: =IF(A9="","",N(F9)-L9) | N9: =IF(A9="","",IF($AB$6>0,AB9/$AB$6,0)) | O9: =IF(A9="","",IF(AB9<=0,"",COUNTIF($AB$9:$AB$208,">"&AB9)+COUNTIF($AB$9:AB9,AB9))) | P9: =IF(A9="","",IF(Q9>0,"BUY","HOLD")) | Q9: =IF(A9="","",IF($W$7<=0,0,IF($AC$6>0,$W$7*AC9/$AC$6,IF($F$6>0,$W$7*N(F9)/$F$6,0)))) | R9: =IF(A9="","",N(AD9)+IF(AI9=1,N(AG9),0)) | S9: =IF(A9="","",N(E9)+N(R9)) | T9: =IF(A9="","",IF(N(R9)>0,R9*H9*W9*$W$6+p_CorrFixa,0)) | V9: =IF(A9="","",IF(D9="",$W$1,D9)) | W9: =IF(A9="","",IFERROR(INDEX(moeda_fx,MATCH(V9,moeda_cod,0)),0)) | X9: =IF(A9="","",IF($W$2="",UPPER(TRIM(A9)),IF(RIGHT(UPPER(TRIM(A9)),LEN($W$2))=$W$2,UPPER(TRIM(A9)),UPPER(TRIM(A9))&$W$2))) | Y9: =IF(OR(A9="",p_ModoCot<>"Automático"),"",IFERROR(_xlfn.WEBSERVICE("https://query1.finance.yahoo.com/v8/finance/chart/"&X9&"?range=1d&interval=1d"),"")) | Z9: =IF(Y9="","",IFERROR(_xlfn.NUMBERVALUE(MID(Y9,SEARCH("""regularMarketPrice"":",Y9)+21,SEARCH(",",Y9&",",SEARCH("""regularMarketPrice"":",Y9)+21)-SEARCH("""regularMarketPrice"":",Y9)-21),".",","),"")) | AA9: =IF(A9="","",ROUND(MAX(0,N(F9)*($K$6+$W$7)-K9),2)) | AB9: =IF(A9="","",IF(AND(M9>0,M9>=p_DifMin),AA9,0)) | AC9: =IF(A9="","",IF(AND(AB9>0,N(O9)<=p_MaxAtivos),AB9,0)) | AD9: =IF(A9="","",IF(OR(Q9<=0,Q9<p_CompraMin,N(H9)<=0,N(W9)<=0),0,IF($W$3="Sim",TRUNC(ROUND(MAX(0,(Q9-p_CorrFixa)/(H9*W9*$W$6)),9),$W$4),TRUNC(ROUND(MAX(0,(Q9-p_CorrFixa)/(H9*W9*$W$6)),9)/$W$5)*$W$5))) | AE9: =IF(A9="","",IF(N(AD9)>0,AD9*H9*W9*$W$6+p_CorrFixa,0)) | AF9: =IF(A9="","",IF(OR($Y$1<=0,N(H9)<=0,N(W9)<=0,N(AB9)<=0),0,IF($W$3="Sim",TRUNC(ROUND(MAX(0,($Y$1-IF(N(AD9)>0,0,p_CorrFixa))/(H9*W9*$W$6)),9),$W$4),TRUNC(ROUND(MAX(0,($Y$1-IF(N(AD9)>0,0,p_CorrFixa))/(H9*W9*$W$6)),9)/$W$5)*$W$5))) | AG9: =IF(A9="","",IF(AND(N(AD9)=0,N(AF9)*(H9*W9*$W$6)+p_CorrFixa<p_CompraMin),0,AF9)) | AH9: =IF(A9="","",IF(N(AG9)>0,AB9,0)) | AI9: =IF(A9="","",IF(AND(AH9>0,AH9=$AH$6,COUNTIF($AH$9:AH9,AH9)=1),1,0))
H10: =IF(A10="","",IF(AND(p_ModoCot="Automático",ISNUMBER(Z10)),Z10,IF(N(G10)>0,G10,0))) | I10: =IF(A10="","",IF(W10=0,"Sem câmbio",IF(AND(p_ModoCot="Automático",ISNUMBER(Z10)),"Auto",IF(N(G10)>0,"Manual","Sem cotação")))) | J10: =IF(A10="","",N(E10)*H10) | K10: =IF(A10="","",J10*W10) | L10: =IF(A10="","",IF($K$6>0,K10/$K$6,0)) | M10: =IF(A10="","",N(F10)-L10) | N10: =IF(A10="","",IF($AB$6>0,AB10/$AB$6,0)) | O10: =IF(A10="","",IF(AB10<=0,"",COUNTIF($AB$9:$AB$208,">"&AB10)+COUNTIF($AB$9:AB10,AB10))) | P10: =IF(A10="","",IF(Q10>0,"BUY","HOLD")) | Q10: =IF(A10="","",IF($W$7<=0,0,IF($AC$6>0,$W$7*AC10/$AC$6,IF($F$6>0,$W$7*N(F10)/$F$6,0)))) | R10: =IF(A10="","",N(AD10)+IF(AI10=1,N(AG10),0)) | S10: =IF(A10="","",N(E10)+N(R10)) | T10: =IF(A10="","",IF(N(R10)>0,R10*H10*W10*$W$6+p_CorrFixa,0)) | V10: =IF(A10="","",IF(D10="",$W$1,D10)) | W10: =IF(A10="","",IFERROR(INDEX(moeda_fx,MATCH(V10,moeda_cod,0)),0)) | X10: =IF(A10="","",IF($W$2="",UPPER(TRIM(A10)),IF(RIGHT(UPPER(TRIM(A10)),LEN($W$2))=$W$2,UPPER(TRIM(A10)),UPPER(TRIM(A10))&$W$2))) | Y10: =IF(OR(A10="",p_ModoCot<>"Automático"),"",IFERROR(_xlfn.WEBSERVICE("https://query1.finance.yahoo.com/v8/finance/chart/"&X10&"?range=1d&interval=1d"),"")) | Z10: =IF(Y10="","",IFERROR(_xlfn.NUMBERVALUE(MID(Y10,SEARCH("""regularMarketPrice"":",Y10)+21,SEARCH(",",Y10&",",SEARCH("""regularMarketPrice"":",Y10)+21)-SEARCH("""regularMarketPrice"":",Y10)-21),".",","),"")) | AA10: =IF(A10="","",ROUND(MAX(0,N(F10)*($K$6+$W$7)-K10),2)) | AB10: =IF(A10="","",IF(AND(M10>0,M10>=p_DifMin),AA10,0)) | AC10: =IF(A10="","",IF(AND(AB10>0,N(O10)<=p_MaxAtivos),AB10,0)) | AD10: =IF(A10="","",IF(OR(Q10<=0,Q10<p_CompraMin,N(H10)<=0,N(W10)<=0),0,IF($W$3="Sim",TRUNC(ROUND(MAX(0,(Q10-p_CorrFixa)/(H10*W10*$W$6)),9),$W$4),TRUNC(ROUND(MAX(0,(Q10-p_CorrFixa)/(H10*W10*$W$6)),9)/$W$5)*$W$5))) | AE10: =IF(A10="","",IF(N(AD10)>0,AD10*H10*W10*$W$6+p_CorrFixa,0)) | AF10: =IF(A10="","",IF(OR($Y$1<=0,N(H10)<=0,N(W10)<=0,N(AB10)<=0),0,IF($W$3="Sim",TRUNC(ROUND(MAX(0,($Y$1-IF(N(AD10)>0,0,p_CorrFixa))/(H10*W10*$W$6)),9),$W$4),TRUNC(ROUND(MAX(0,($Y$1-IF(N(AD10)>0,0,p_CorrFixa))/(H10*W10*$W$6)),9)/$W$5)*$W$5))) | AG10: =IF(A10="","",IF(AND(N(AD10)=0,N(AF10)*(H10*W10*$W$6)+p_CorrFixa<p_CompraMin),0,AF10)) | AH10: =IF(A10="","",IF(N(AG10)>0,AB10,0)) | AI10: =IF(A10="","",IF(AND(AH10>0,AH10=$AH$6,COUNTIF($AH$9:AH10,AH10)=1),1,0))
H11: =IF(A11="","",IF(AND(p_ModoCot="Automático",ISNUMBER(Z11)),Z11,IF(N(G11)>0,G11,0))) | I11: =IF(A11="","",IF(W11=0,"Sem câmbio",IF(AND(p_ModoCot="Automático",ISNUMBER(Z11)),"Auto",IF(N(G11)>0,"Manual","Sem cotação")))) | J11: =IF(A11="","",N(E11)*H11) | K11: =IF(A11="","",J11*W11) | L11: =IF(A11="","",IF($K$6>0,K11/$K$6,0)) | M11: =IF(A11="","",N(F11)-L11) | N11: =IF(A11="","",IF($AB$6>0,AB11/$AB$6,0)) | O11: =IF(A11="","",IF(AB11<=0,"",COUNTIF($AB$9:$AB$208,">"&AB11)+COUNTIF($AB$9:AB11,AB11))) | P11: =IF(A11="","",IF(Q11>0,"BUY","HOLD")) | Q11: =IF(A11="","",IF($W$7<=0,0,IF($AC$6>0,$W$7*AC11/$AC$6,IF($F$6>0,$W$7*N(F11)/$F$6,0)))) | R11: =IF(A11="","",N(AD11)+IF(AI11=1,N(AG11),0)) | S11: =IF(A11="","",N(E11)+N(R11)) | T11: =IF(A11="","",IF(N(R11)>0,R11*H11*W11*$W$6+p_CorrFixa,0)) | V11: =IF(A11="","",IF(D11="",$W$1,D11)) | W11: =IF(A11="","",IFERROR(INDEX(moeda_fx,MATCH(V11,moeda_cod,0)),0)) | X11: =IF(A11="","",IF($W$2="",UPPER(TRIM(A11)),IF(RIGHT(UPPER(TRIM(A11)),LEN($W$2))=$W$2,UPPER(TRIM(A11)),UPPER(TRIM(A11))&$W$2))) | Y11: =IF(OR(A11="",p_ModoCot<>"Automático"),"",IFERROR(_xlfn.WEBSERVICE("https://query1.finance.yahoo.com/v8/finance/chart/"&X11&"?range=1d&interval=1d"),"")) | Z11: =IF(Y11="","",IFERROR(_xlfn.NUMBERVALUE(MID(Y11,SEARCH("""regularMarketPrice"":",Y11)+21,SEARCH(",",Y11&",",SEARCH("""regularMarketPrice"":",Y11)+21)-SEARCH("""regularMarketPrice"":",Y11)-21),".",","),"")) | AA11: =IF(A11="","",ROUND(MAX(0,N(F11)*($K$6+$W$7)-K11),2)) | AB11: =IF(A11="","",IF(AND(M11>0,M11>=p_DifMin),AA11,0)) | AC11: =IF(A11="","",IF(AND(AB11>0,N(O11)<=p_MaxAtivos),AB11,0)) | AD11: =IF(A11="","",IF(OR(Q11<=0,Q11<p_CompraMin,N(H11)<=0,N(W11)<=0),0,IF($W$3="Sim",TRUNC(ROUND(MAX(0,(Q11-p_CorrFixa)/(H11*W11*$W$6)),9),$W$4),TRUNC(ROUND(MAX(0,(Q11-p_CorrFixa)/(H11*W11*$W$6)),9)/$W$5)*$W$5))) | AE11: =IF(A11="","",IF(N(AD11)>0,AD11*H11*W11*$W$6+p_CorrFixa,0)) | AF11: =IF(A11="","",IF(OR($Y$1<=0,N(H11)<=0,N(W11)<=0,N(AB11)<=0),0,IF($W$3="Sim",TRUNC(ROUND(MAX(0,($Y$1-IF(N(AD11)>0,0,p_CorrFixa))/(H11*W11*$W$6)),9),$W$4),TRUNC(ROUND(MAX(0,($Y$1-IF(N(AD11)>0,0,p_CorrFixa))/(H11*W11*$W$6)),9)/$W$5)*$W$5))) | AG11: =IF(A11="","",IF(AND(N(AD11)=0,N(AF11)*(H11*W11*$W$6)+p_CorrFixa<p_CompraMin),0,AF11)) | AH11: =IF(A11="","",IF(N(AG11)>0,AB11,0)) | AI11: =IF(A11="","",IF(AND(AH11>0,AH11=$AH$6,COUNTIF($AH$9:AH11,AH11)=1),1,0))
H12: =IF(A12="","",IF(AND(p_ModoCot="Automático",ISNUMBER(Z12)),Z12,IF(N(G12)>0,G12,0))) | I12: =IF(A12="","",IF(W12=0,"Sem câmbio",IF(AND(p_ModoCot="Automático",ISNUMBER(Z12)),"Auto",IF(N(G12)>0,"Manual","Sem cotação")))) | J12: =IF(A12="","",N(E12)*H12) | K12: =IF(A12="","",J12*W12) | L12: =IF(A12="","",IF($K$6>0,K12/$K$6,0)) | M12: =IF(A12="","",N(F12)-L12) | N12: =IF(A12="","",IF($AB$6>0,AB12/$AB$6,0)) | O12: =IF(A12="","",IF(AB12<=0,"",COUNTIF($AB$9:$AB$208,">"&AB12)+COUNTIF($AB$9:AB12,AB12))) | P12: =IF(A12="","",IF(Q12>0,"BUY","HOLD")) | Q12: =IF(A12="","",IF($W$7<=0,0,IF($AC$6>0,$W$7*AC12/$AC$6,IF($F$6>0,$W$7*N(F12)/$F$6,0)))) | R12: =IF(A12="","",N(AD12)+IF(AI12=1,N(AG12),0)) | S12: =IF(A12="","",N(E12)+N(R12)) | T12: =IF(A12="","",IF(N(R12)>0,R12*H12*W12*$W$6+p_CorrFixa,0)) | V12: =IF(A12="","",IF(D12="",$W$1,D12)) | W12: =IF(A12="","",IFERROR(INDEX(moeda_fx,MATCH(V12,moeda_cod,0)),0)) | X12: =IF(A12="","",IF($W$2="",UPPER(TRIM(A12)),IF(RIGHT(UPPER(TRIM(A12)),LEN($W$2))=$W$2,UPPER(TRIM(A12)),UPPER(TRIM(A12))&$W$2))) | Y12: =IF(OR(A12="",p_ModoCot<>"Automático"),"",IFERROR(_xlfn.WEBSERVICE("https://query1.finance.yahoo.com/v8/finance/chart/"&X12&"?range=1d&interval=1d"),"")) | Z12: =IF(Y12="","",IFERROR(_xlfn.NUMBERVALUE(MID(Y12,SEARCH("""regularMarketPrice"":",Y12)+21,SEARCH(",",Y12&",",SEARCH("""regularMarketPrice"":",Y12)+21)-SEARCH("""regularMarketPrice"":",Y12)-21),".",","),"")) | AA12: =IF(A12="","",ROUND(MAX(0,N(F12)*($K$6+$W$7)-K12),2)) | AB12: =IF(A12="","",IF(AND(M12>0,M12>=p_DifMin),AA12,0)) | AC12: =IF(A12="","",IF(AND(AB12>0,N(O12)<=p_MaxAtivos),AB12,0)) | AD12: =IF(A12="","",IF(OR(Q12<=0,Q12<p_CompraMin,N(H12)<=0,N(W12)<=0),0,IF($W$3="Sim",TRUNC(ROUND(MAX(0,(Q12-p_CorrFixa)/(H12*W12*$W$6)),9),$W$4),TRUNC(ROUND(MAX(0,(Q12-p_CorrFixa)/(H12*W12*$W$6)),9)/$W$5)*$W$5))) | AE12: =IF(A12="","",IF(N(AD12)>0,AD12*H12*W12*$W$6+p_CorrFixa,0)) | AF12: =IF(A12="","",IF(OR($Y$1<=0,N(H12)<=0,N(W12)<=0,N(AB12)<=0),0,IF($W$3="Sim",TRUNC(ROUND(MAX(0,($Y$1-IF(N(AD12)>0,0,p_CorrFixa))/(H12*W12*$W$6)),9),$W$4),TRUNC(ROUND(MAX(0,($Y$1-IF(N(AD12)>0,0,p_CorrFixa))/(H12*W12*$W$6)),9)/$W$5)*$W$5))) | AG12: =IF(A12="","",IF(AND(N(AD12)=0,N(AF12)*(H12*W12*$W$6)+p_CorrFixa<p_CompraMin),0,AF12)) | AH12: =IF(A12="","",IF(N(AG12)>0,AB12,0)) | AI12: =IF(A12="","",IF(AND(AH12>0,AH12=$AH$6,COUNTIF($AH$9:AH12,AH12)=1),1,0))
H13: =IF(A13="","",IF(AND(p_ModoCot="Automático",ISNUMBER(Z13)),Z13,IF(N(G13)>0,G13,0))) | I13: =IF(A13="","",IF(W13=0,"Sem câmbio",IF(AND(p_ModoCot="Automático",ISNUMBER(Z13)),"Auto",IF(N(G13)>0,"Manual","Sem cotação")))) | J13: =IF(A13="","",N(E13)*H13) | K13: =IF(A13="","",J13*W13) | L13: =IF(A13="","",IF($K$6>0,K13/$K$6,0)) | M13: =IF(A13="","",N(F13)-L13) | N13: =IF(A13="","",IF($AB$6>0,AB13/$AB$6,0)) | O13: =IF(A13="","",IF(AB13<=0,"",COUNTIF($AB$9:$AB$208,">"&AB13)+COUNTIF($AB$9:AB13,AB13))) | P13: =IF(A13="","",IF(Q13>0,"BUY","HOLD")) | Q13: =IF(A13="","",IF($W$7<=0,0,IF($AC$6>0,$W$7*AC13/$AC$6,IF($F$6>0,$W$7*N(F13)/$F$6,0)))) | R13: =IF(A13="","",N(AD13)+IF(AI13=1,N(AG13),0)) | S13: =IF(A13="","",N(E13)+N(R13)) | T13: =IF(A13="","",IF(N(R13)>0,R13*H13*W13*$W$6+p_CorrFixa,0)) | V13: =IF(A13="","",IF(D13="",$W$1,D13)) | W13: =IF(A13="","",IFERROR(INDEX(moeda_fx,MATCH(V13,moeda_cod,0)),0)) | X13: =IF(A13="","",IF($W$2="",UPPER(TRIM(A13)),IF(RIGHT(UPPER(TRIM(A13)),LEN($W$2))=$W$2,UPPER(TRIM(A13)),UPPER(TRIM(A13))&$W$2))) | Y13: =IF(OR(A13="",p_ModoCot<>"Automático"),"",IFERROR(_xlfn.WEBSERVICE("https://query1.finance.yahoo.com/v8/finance/chart/"&X13&"?range=1d&interval=1d"),"")) | Z13: =IF(Y13="","",IFERROR(_xlfn.NUMBERVALUE(MID(Y13,SEARCH("""regularMarketPrice"":",Y13)+21,SEARCH(",",Y13&",",SEARCH("""regularMarketPrice"":",Y13)+21)-SEARCH("""regularMarketPrice"":",Y13)-21),".",","),"")) | AA13: =IF(A13="","",ROUND(MAX(0,N(F13)*($K$6+$W$7)-K13),2)) | AB13: =IF(A13="","",IF(AND(M13>0,M13>=p_DifMin),AA13,0)) | AC13: =IF(A13="","",IF(AND(AB13>0,N(O13)<=p_MaxAtivos),AB13,0)) | AD13: =IF(A13="","",IF(OR(Q13<=0,Q13<p_CompraMin,N(H13)<=0,N(W13)<=0),0,IF($W$3="Sim",TRUNC(ROUND(MAX(0,(Q13-p_CorrFixa)/(H13*W13*$W$6)),9),$W$4),TRUNC(ROUND(MAX(0,(Q13-p_CorrFixa)/(H13*W13*$W$6)),9)/$W$5)*$W$5))) | AE13: =IF(A13="","",IF(N(AD13)>0,AD13*H13*W13*$W$6+p_CorrFixa,0)) | AF13: =IF(A13="","",IF(OR($Y$1<=0,N(H13)<=0,N(W13)<=0,N(AB13)<=0),0,IF($W$3="Sim",TRUNC(ROUND(MAX(0,($Y$1-IF(N(AD13)>0,0,p_CorrFixa))/(H13*W13*$W$6)),9),$W$4),TRUNC(ROUND(MAX(0,($Y$1-IF(N(AD13)>0,0,p_CorrFixa))/(H13*W13*$W$6)),9)/$W$5)*$W$5))) | AG13: =IF(A13="","",IF(AND(N(AD13)=0,N(AF13)*(H13*W13*$W$6)+p_CorrFixa<p_CompraMin),0,AF13)) | AH13: =IF(A13="","",IF(N(AG13)>0,AB13,0)) | AI13: =IF(A13="","",IF(AND(AH13>0,AH13=$AH$6,COUNTIF($AH$9:AH13,AH13)=1),1,0))
H14: =IF(A14="","",IF(AND(p_ModoCot="Automático",ISNUMBER(Z14)),Z14,IF(N(G14)>0,G14,0))) | I14: =IF(A14="","",IF(W14=0,"Sem câmbio",IF(AND(p_ModoCot="Automático",ISNUMBER(Z14)),"Auto",IF(N(G14)>0,"Manual","Sem cotação")))) | J14: =IF(A14="","",N(E14)*H14) | K14: =IF(A14="","",J14*W14) | L14: =IF(A14="","",IF($K$6>0,K14/$K$6,0)) | M14: =IF(A14="","",N(F14)-L14) | N14: =IF(A14="","",IF($AB$6>0,AB14/$AB$6,0)) | O14: =IF(A14="","",IF(AB14<=0,"",COUNTIF($AB$9:$AB$208,">"&AB14)+COUNTIF($AB$9:AB14,AB14))) | P14: =IF(A14="","",IF(Q14>0,"BUY","HOLD")) | Q14: =IF(A14="","",IF($W$7<=0,0,IF($AC$6>0,$W$7*AC14/$AC$6,IF($F$6>0,$W$7*N(F14)/$F$6,0)))) | R14: =IF(A14="","",N(AD14)+IF(AI14=1,N(AG14),0)) | S14: =IF(A14="","",N(E14)+N(R14)) | T14: =IF(A14="","",IF(N(R14)>0,R14*H14*W14*$W$6+p_CorrFixa,0)) | V14: =IF(A14="","",IF(D14="",$W$1,D14)) | W14: =IF(A14="","",IFERROR(INDEX(moeda_fx,MATCH(V14,moeda_cod,0)),0)) | X14: =IF(A14="","",IF($W$2="",UPPER(TRIM(A14)),IF(RIGHT(UPPER(TRIM(A14)),LEN($W$2))=$W$2,UPPER(TRIM(A14)),UPPER(TRIM(A14))&$W$2))) | Y14: =IF(OR(A14="",p_ModoCot<>"Automático"),"",IFERROR(_xlfn.WEBSERVICE("https://query1.finance.yahoo.com/v8/finance/chart/"&X14&"?range=1d&interval=1d"),"")) | Z14: =IF(Y14="","",IFERROR(_xlfn.NUMBERVALUE(MID(Y14,SEARCH("""regularMarketPrice"":",Y14)+21,SEARCH(",",Y14&",",SEARCH("""regularMarketPrice"":",Y14)+21)-SEARCH("""regularMarketPrice"":",Y14)-21),".",","),"")) | AA14: =IF(A14="","",ROUND(MAX(0,N(F14)*($K$6+$W$7)-K14),2)) | AB14: =IF(A14="","",IF(AND(M14>0,M14>=p_DifMin),AA14,0)) | AC14: =IF(A14="","",IF(AND(AB14>0,N(O14)<=p_MaxAtivos),AB14,0)) | AD14: =IF(A14="","",IF(OR(Q14<=0,Q14<p_CompraMin,N(H14)<=0,N(W14)<=0),0,IF($W$3="Sim",TRUNC(ROUND(MAX(0,(Q14-p_CorrFixa)/(H14*W14*$W$6)),9),$W$4),TRUNC(ROUND(MAX(0,(Q14-p_CorrFixa)/(H14*W14*$W$6)),9)/$W$5)*$W$5))) | AE14: =IF(A14="","",IF(N(AD14)>0,AD14*H14*W14*$W$6+p_CorrFixa,0)) | AF14: =IF(A14="","",IF(OR($Y$1<=0,N(H14)<=0,N(W14)<=0,N(AB14)<=0),0,IF($W$3="Sim",TRUNC(ROUND(MAX(0,($Y$1-IF(N(AD14)>0,0,p_CorrFixa))/(H14*W14*$W$6)),9),$W$4),TRUNC(ROUND(MAX(0,($Y$1-IF(N(AD14)>0,0,p_CorrFixa))/(H14*W14*$W$6)),9)/$W$5)*$W$5))) | AG14: =IF(A14="","",IF(AND(N(AD14)=0,N(AF14)*(H14*W14*$W$6)+p_CorrFixa<p_CompraMin),0,AF14)) | AH14: =IF(A14="","",IF(N(AG14)>0,AB14,0)) | AI14: =IF(A14="","",IF(AND(AH14>0,AH14=$AH$6,COUNTIF($AH$9:AH14,AH14)=1),1,0))
H15: =IF(A15="","",IF(AND(p_ModoCot="Automático",ISNUMBER(Z15)),Z15,IF(N(G15)>0,G15,0))) | I15: =IF(A15="","",IF(W15=0,"Sem câmbio",IF(AND(p_ModoCot="Automático",ISNUMBER(Z15)),"Auto",IF(N(G15)>0,"Manual","Sem cotação")))) | J15: =IF(A15="","",N(E15)*H15) | K15: =IF(A15="","",J15*W15) | L15: =IF(A15="","",IF($K$6>0,K15/$K$6,0)) | M15: =IF(A15="","",N(F15)-L15) | N15: =IF(A15="","",IF($AB$6>0,AB15/$AB$6,0)) | O15: =IF(A15="","",IF(AB15<=0,"",COUNTIF($AB$9:$AB$208,">"&AB15)+COUNTIF($AB$9:AB15,AB15))) | P15: =IF(A15="","",IF(Q15>0,"BUY","HOLD")) | Q15: =IF(A15="","",IF($W$7<=0,0,IF($AC$6>0,$W$7*AC15/$AC$6,IF($F$6>0,$W$7*N(F15)/$F$6,0)))) | R15: =IF(A15="","",N(AD15)+IF(AI15=1,N(AG15),0)) | S15: =IF(A15="","",N(E15)+N(R15)) | T15: =IF(A15="","",IF(N(R15)>0,R15*H15*W15*$W$6+p_CorrFixa,0)) | V15: =IF(A15="","",IF(D15="",$W$1,D15)) | W15: =IF(A15="","",IFERROR(INDEX(moeda_fx,MATCH(V15,moeda_cod,0)),0)) | X15: =IF(A15="","",IF($W$2="",UPPER(TRIM(A15)),IF(RIGHT(UPPER(TRIM(A15)),LEN($W$2))=$W$2,UPPER(TRIM(A15)),UPPER(TRIM(A15))&$W$2))) | Y15: =IF(OR(A15="",p_ModoCot<>"Automático"),"",IFERROR(_xlfn.WEBSERVICE("https://query1.finance.yahoo.com/v8/finance/chart/"&X15&"?range=1d&interval=1d"),"")) | Z15: =IF(Y15="","",IFERROR(_xlfn.NUMBERVALUE(MID(Y15,SEARCH("""regularMarketPrice"":",Y15)+21,SEARCH(",",Y15&",",SEARCH("""regularMarketPrice"":",Y15)+21)-SEARCH("""regularMarketPrice"":",Y15)-21),".",","),"")) | AA15: =IF(A15="","",ROUND(MAX(0,N(F15)*($K$6+$W$7)-K15),2)) | AB15: =IF(A15="","",IF(AND(M15>0,M15>=p_DifMin),AA15,0)) | AC15: =IF(A15="","",IF(AND(AB15>0,N(O15)<=p_MaxAtivos),AB15,0)) | AD15: =IF(A15="","",IF(OR(Q15<=0,Q15<p_CompraMin,N(H15)<=0,N(W15)<=0),0,IF($W$3="Sim",TRUNC(ROUND(MAX(0,(Q15-p_CorrFixa)/(H15*W15*$W$6)),9),$W$4),TRUNC(ROUND(MAX(0,(Q15-p_CorrFixa)/(H15*W15*$W$6)),9)/$W$5)*$W$5))) | AE15: =IF(A15="","",IF(N(AD15)>0,AD15*H15*W15*$W$6+p_CorrFixa,0)) | AF15: =IF(A15="","",IF(OR($Y$1<=0,N(H15)<=0,N(W15)<=0,N(AB15)<=0),0,IF($W$3="Sim",TRUNC(ROUND(MAX(0,($Y$1-IF(N(AD15)>0,0,p_CorrFixa))/(H15*W15*$W$6)),9),$W$4),TRUNC(ROUND(MAX(0,($Y$1-IF(N(AD15)>0,0,p_CorrFixa))/(H15*W15*$W$6)),9)/$W$5)*$W$5))) | AG15: =IF(A15="","",IF(AND(N(AD15)=0,N(AF15)*(H15*W15*$W$6)+p_CorrFixa<p_CompraMin),0,AF15)) | AH15: =IF(A15="","",IF(N(AG15)>0,AB15,0)) | AI15: =IF(A15="","",IF(AND(AH15>0,AH15=$AH$6,COUNTIF($AH$9:AH15,AH15)=1),1,0))
H16: =IF(A16="","",IF(AND(p_ModoCot="Automático",ISNUMBER(Z16)),Z16,IF(N(G16)>0,G16,0))) | I16: =IF(A16="","",IF(W16=0,"Sem câmbio",IF(AND(p_ModoCot="Automático",ISNUMBER(Z16)),"Auto",IF(N(G16)>0,"Manual","Sem cotação")))) | J16: =IF(A16="","",N(E16)*H16) | K16: =IF(A16="","",J16*W16) | L16: =IF(A16="","",IF($K$6>0,K16/$K$6,0)) | M16: =IF(A16="","",N(F16)-L16) | N16: =IF(A16="","",IF($AB$6>0,AB16/$AB$6,0)) | O16: =IF(A16="","",IF(AB16<=0,"",COUNTIF($AB$9:$AB$208,">"&AB16)+COUNTIF($AB$9:AB16,AB16))) | P16: =IF(A16="","",IF(Q16>0,"BUY","HOLD")) | Q16: =IF(A16="","",IF($W$7<=0,0,IF($AC$6>0,$W$7*AC16/$AC$6,IF($F$6>0,$W$7*N(F16)/$F$6,0)))) | R16: =IF(A16="","",N(AD16)+IF(AI16=1,N(AG16),0)) | S16: =IF(A16="","",N(E16)+N(R16)) | T16: =IF(A16="","",IF(N(R16)>0,R16*H16*W16*$W$6+p_CorrFixa,0)) | V16: =IF(A16="","",IF(D16="",$W$1,D16)) | W16: =IF(A16="","",IFERROR(INDEX(moeda_fx,MATCH(V16,moeda_cod,0)),0)) | X16: =IF(A16="","",IF($W$2="",UPPER(TRIM(A16)),IF(RIGHT(UPPER(TRIM(A16)),LEN($W$2))=$W$2,UPPER(TRIM(A16)),UPPER(TRIM(A16))&$W$2))) | Y16: =IF(OR(A16="",p_ModoCot<>"Automático"),"",IFERROR(_xlfn.WEBSERVICE("https://query1.finance.yahoo.com/v8/finance/chart/"&X16&"?range=1d&interval=1d"),"")) | Z16: =IF(Y16="","",IFERROR(_xlfn.NUMBERVALUE(MID(Y16,SEARCH("""regularMarketPrice"":",Y16)+21,SEARCH(",",Y16&",",SEARCH("""regularMarketPrice"":",Y16)+21)-SEARCH("""regularMarketPrice"":",Y16)-21),".",","),"")) | AA16: =IF(A16="","",ROUND(MAX(0,N(F16)*($K$6+$W$7)-K16),2)) | AB16: =IF(A16="","",IF(AND(M16>0,M16>=p_DifMin),AA16,0)) | AC16: =IF(A16="","",IF(AND(AB16>0,N(O16)<=p_MaxAtivos),AB16,0)) | AD16: =IF(A16="","",IF(OR(Q16<=0,Q16<p_CompraMin,N(H16)<=0,N(W16)<=0),0,IF($W$3="Sim",TRUNC(ROUND(MAX(0,(Q16-p_CorrFixa)/(H16*W16*$W$6)),9),$W$4),TRUNC(ROUND(MAX(0,(Q16-p_CorrFixa)/(H16*W16*$W$6)),9)/$W$5)*$W$5))) | AE16: =IF(A16="","",IF(N(AD16)>0,AD16*H16*W16*$W$6+p_CorrFixa,0)) | AF16: =IF(A16="","",IF(OR($Y$1<=0,N(H16)<=0,N(W16)<=0,N(AB16)<=0),0,IF($W$3="Sim",TRUNC(ROUND(MAX(0,($Y$1-IF(N(AD16)>0,0,p_CorrFixa))/(H16*W16*$W$6)),9),$W$4),TRUNC(ROUND(MAX(0,($Y$1-IF(N(AD16)>0,0,p_CorrFixa))/(H16*W16*$W$6)),9)/$W$5)*$W$5))) | AG16: =IF(A16="","",IF(AND(N(AD16)=0,N(AF16)*(H16*W16*$W$6)+p_CorrFixa<p_CompraMin),0,AF16)) | AH16: =IF(A16="","",IF(N(AG16)>0,AB16,0)) | AI16: =IF(A16="","",IF(AND(AH16>0,AH16=$AH$6,COUNTIF($AH$9:AH16,AH16)=1),1,0))
H17: =IF(A17="","",IF(AND(p_ModoCot="Automático",ISNUMBER(Z17)),Z17,IF(N(G17)>0,G17,0))) | I17: =IF(A17="","",IF(W17=0,"Sem câmbio",IF(AND(p_ModoCot="Automático",ISNUMBER(Z17)),"Auto",IF(N(G17)>0,"Manual","Sem cotação")))) | J17: =IF(A17="","",N(E17)*H17) | K17: =IF(A17="","",J17*W17) | L17: =IF(A17="","",IF($K$6>0,K17/$K$6,0)) | M17: =IF(A17="","",N(F17)-L17) | N17: =IF(A17="","",IF($AB$6>0,AB17/$AB$6,0)) | O17: =IF(A17="","",IF(AB17<=0,"",COUNTIF($AB$9:$AB$208,">"&AB17)+COUNTIF($AB$9:AB17,AB17))) | P17: =IF(A17="","",IF(Q17>0,"BUY","HOLD")) | Q17: =IF(A17="","",IF($W$7<=0,0,IF($AC$6>0,$W$7*AC17/$AC$6,IF($F$6>0,$W$7*N(F17)/$F$6,0)))) | R17: =IF(A17="","",N(AD17)+IF(AI17=1,N(AG17),0)) | S17: =IF(A17="","",N(E17)+N(R17)) | T17: =IF(A17="","",IF(N(R17)>0,R17*H17*W17*$W$6+p_CorrFixa,0)) | V17: =IF(A17="","",IF(D17="",$W$1,D17)) | W17: =IF(A17="","",IFERROR(INDEX(moeda_fx,MATCH(V17,moeda_cod,0)),0)) | X17: =IF(A17="","",IF($W$2="",UPPER(TRIM(A17)),IF(RIGHT(UPPER(TRIM(A17)),LEN($W$2))=$W$2,UPPER(TRIM(A17)),UPPER(TRIM(A17))&$W$2))) | Y17: =IF(OR(A17="",p_ModoCot<>"Automático"),"",IFERROR(_xlfn.WEBSERVICE("https://query1.finance.yahoo.com/v8/finance/chart/"&X17&"?range=1d&interval=1d"),"")) | Z17: =IF(Y17="","",IFERROR(_xlfn.NUMBERVALUE(MID(Y17,SEARCH("""regularMarketPrice"":",Y17)+21,SEARCH(",",Y17&",",SEARCH("""regularMarketPrice"":",Y17)+21)-SEARCH("""regularMarketPrice"":",Y17)-21),".",","),"")) | AA17: =IF(A17="","",ROUND(MAX(0,N(F17)*($K$6+$W$7)-K17),2)) | AB17: =IF(A17="","",IF(AND(M17>0,M17>=p_DifMin),AA17,0)) | AC17: =IF(A17="","",IF(AND(AB17>0,N(O17)<=p_MaxAtivos),AB17,0)) | AD17: =IF(A17="","",IF(OR(Q17<=0,Q17<p_CompraMin,N(H17)<=0,N(W17)<=0),0,IF($W$3="Sim",TRUNC(ROUND(MAX(0,(Q17-p_CorrFixa)/(H17*W17*$W$6)),9),$W$4),TRUNC(ROUND(MAX(0,(Q17-p_CorrFixa)/(H17*W17*$W$6)),9)/$W$5)*$W$5))) | AE17: =IF(A17="","",IF(N(AD17)>0,AD17*H17*W17*$W$6+p_CorrFixa,0)) | AF17: =IF(A17="","",IF(OR($Y$1<=0,N(H17)<=0,N(W17)<=0,N(AB17)<=0),0,IF($W$3="Sim",TRUNC(ROUND(MAX(0,($Y$1-IF(N(AD17)>0,0,p_CorrFixa))/(H17*W17*$W$6)),9),$W$4),TRUNC(ROUND(MAX(0,($Y$1-IF(N(AD17)>0,0,p_CorrFixa))/(H17*W17*$W$6)),9)/$W$5)*$W$5))) | AG17: =IF(A17="","",IF(AND(N(AD17)=0,N(AF17)*(H17*W17*$W$6)+p_CorrFixa<p_CompraMin),0,AF17)) | AH17: =IF(A17="","",IF(N(AG17)>0,AB17,0)) | AI17: =IF(A17="","",IF(AND(AH17>0,AH17=$AH$6,COUNTIF($AH$9:AH17,AH17)=1),1,0))
H18: =IF(A18="","",IF(AND(p_ModoCot="Automático",ISNUMBER(Z18)),Z18,IF(N(G18)>0,G18,0))) | I18: =IF(A18="","",IF(W18=0,"Sem câmbio",IF(AND(p_ModoCot="Automático",ISNUMBER(Z18)),"Auto",IF(N(G18)>0,"Manual","Sem cotação")))) | J18: =IF(A18="","",N(E18)*H18) | K18: =IF(A18="","",J18*W18) | L18: =IF(A18="","",IF($K$6>0,K18/$K$6,0)) | M18: =IF(A18="","",N(F18)-L18) | N18: =IF(A18="","",IF($AB$6>0,AB18/$AB$6,0)) | O18: =IF(A18="","",IF(AB18<=0,"",COUNTIF($AB$9:$AB$208,">"&AB18)+COUNTIF($AB$9:AB18,AB18))) | P18: =IF(A18="","",IF(Q18>0,"BUY","HOLD")) | Q18: =IF(A18="","",IF($W$7<=0,0,IF($AC$6>0,$W$7*AC18/$AC$6,IF($F$6>0,$W$7*N(F18)/$F$6,0)))) | R18: =IF(A18="","",N(AD18)+IF(AI18=1,N(AG18),0)) | S18: =IF(A18="","",N(E18)+N(R18)) | T18: =IF(A18="","",IF(N(R18)>0,R18*H18*W18*$W$6+p_CorrFixa,0)) | V18: =IF(A18="","",IF(D18="",$W$1,D18)) | W18: =IF(A18="","",IFERROR(INDEX(moeda_fx,MATCH(V18,moeda_cod,0)),0)) | X18: =IF(A18="","",IF($W$2="",UPPER(TRIM(A18)),IF(RIGHT(UPPER(TRIM(A18)),LEN($W$2))=$W$2,UPPER(TRIM(A18)),UPPER(TRIM(A18))&$W$2))) | Y18: =IF(OR(A18="",p_ModoCot<>"Automático"),"",IFERROR(_xlfn.WEBSERVICE("https://query1.finance.yahoo.com/v8/finance/chart/"&X18&"?range=1d&interval=1d"),"")) | Z18: =IF(Y18="","",IFERROR(_xlfn.NUMBERVALUE(MID(Y18,SEARCH("""regularMarketPrice"":",Y18)+21,SEARCH(",",Y18&",",SEARCH("""regularMarketPrice"":",Y18)+21)-SEARCH("""regularMarketPrice"":",Y18)-21),".",","),"")) | AA18: =IF(A18="","",ROUND(MAX(0,N(F18)*($K$6+$W$7)-K18),2)) | AB18: =IF(A18="","",IF(AND(M18>0,M18>=p_DifMin),AA18,0)) | AC18: =IF(A18="","",IF(AND(AB18>0,N(O18)<=p_MaxAtivos),AB18,0)) | AD18: =IF(A18="","",IF(OR(Q18<=0,Q18<p_CompraMin,N(H18)<=0,N(W18)<=0),0,IF($W$3="Sim",TRUNC(ROUND(MAX(0,(Q18-p_CorrFixa)/(H18*W18*$W$6)),9),$W$4),TRUNC(ROUND(MAX(0,(Q18-p_CorrFixa)/(H18*W18*$W$6)),9)/$W$5)*$W$5))) | AE18: =IF(A18="","",IF(N(AD18)>0,AD18*H18*W18*$W$6+p_CorrFixa,0)) | AF18: =IF(A18="","",IF(OR($Y$1<=0,N(H18)<=0,N(W18)<=0,N(AB18)<=0),0,IF($W$3="Sim",TRUNC(ROUND(MAX(0,($Y$1-IF(N(AD18)>0,0,p_CorrFixa))/(H18*W18*$W$6)),9),$W$4),TRUNC(ROUND(MAX(0,($Y$1-IF(N(AD18)>0,0,p_CorrFixa))/(H18*W18*$W$6)),9)/$W$5)*$W$5))) | AG18: =IF(A18="","",IF(AND(N(AD18)=0,N(AF18)*(H18*W18*$W$6)+p_CorrFixa<p_CompraMin),0,AF18)) | AH18: =IF(A18="","",IF(N(AG18)>0,AB18,0)) | AI18: =IF(A18="","",IF(AND(AH18>0,AH18=$AH$6,COUNTIF($AH$9:AH18,AH18)=1),1,0))
H19: =IF(A19="","",IF(AND(p_ModoCot="Automático",ISNUMBER(Z19)),Z19,IF(N(G19)>0,G19,0))) | I19: =IF(A19="","",IF(W19=0,"Sem câmbio",IF(AND(p_ModoCot="Automático",ISNUMBER(Z19)),"Auto",IF(N(G19)>0,"Manual","Sem cotação")))) | J19: =IF(A19="","",N(E19)*H19) | K19: =IF(A19="","",J19*W19) | L19: =IF(A19="","",IF($K$6>0,K19/$K$6,0)) | M19: =IF(A19="","",N(F19)-L19) | N19: =IF(A19="","",IF($AB$6>0,AB19/$AB$6,0)) | O19: =IF(A19="","",IF(AB19<=0,"",COUNTIF($AB$9:$AB$208,">"&AB19)+COUNTIF($AB$9:AB19,AB19))) | P19: =IF(A19="","",IF(Q19>0,"BUY","HOLD")) | Q19: =IF(A19="","",IF($W$7<=0,0,IF($AC$6>0,$W$7*AC19/$AC$6,IF($F$6>0,$W$7*N(F19)/$F$6,0)))) | R19: =IF(A19="","",N(AD19)+IF(AI19=1,N(AG19),0)) | S19: =IF(A19="","",N(E19)+N(R19)) | T19: =IF(A19="","",IF(N(R19)>0,R19*H19*W19*$W$6+p_CorrFixa,0)) | V19: =IF(A19="","",IF(D19="",$W$1,D19)) | W19: =IF(A19="","",IFERROR(INDEX(moeda_fx,MATCH(V19,moeda_cod,0)),0)) | X19: =IF(A19="","",IF($W$2="",UPPER(TRIM(A19)),IF(RIGHT(UPPER(TRIM(A19)),LEN($W$2))=$W$2,UPPER(TRIM(A19)),UPPER(TRIM(A19))&$W$2))) | Y19: =IF(OR(A19="",p_ModoCot<>"Automático"),"",IFERROR(_xlfn.WEBSERVICE("https://query1.finance.yahoo.com/v8/finance/chart/"&X19&"?range=1d&interval=1d"),"")) | Z19: =IF(Y19="","",IFERROR(_xlfn.NUMBERVALUE(MID(Y19,SEARCH("""regularMarketPrice"":",Y19)+21,SEARCH(",",Y19&",",SEARCH("""regularMarketPrice"":",Y19)+21)-SEARCH("""regularMarketPrice"":",Y19)-21),".",","),"")) | AA19: =IF(A19="","",ROUND(MAX(0,N(F19)*($K$6+$W$7)-K19),2)) | AB19: =IF(A19="","",IF(AND(M19>0,M19>=p_DifMin),AA19,0)) | AC19: =IF(A19="","",IF(AND(AB19>0,N(O19)<=p_MaxAtivos),AB19,0)) | AD19: =IF(A19="","",IF(OR(Q19<=0,Q19<p_CompraMin,N(H19)<=0,N(W19)<=0),0,IF($W$3="Sim",TRUNC(ROUND(MAX(0,(Q19-p_CorrFixa)/(H19*W19*$W$6)),9),$W$4),TRUNC(ROUND(MAX(0,(Q19-p_CorrFixa)/(H19*W19*$W$6)),9)/$W$5)*$W$5))) | AE19: =IF(A19="","",IF(N(AD19)>0,AD19*H19*W19*$W$6+p_CorrFixa,0)) | AF19: =IF(A19="","",IF(OR($Y$1<=0,N(H19)<=0,N(W19)<=0,N(AB19)<=0),0,IF($W$3="Sim",TRUNC(ROUND(MAX(0,($Y$1-IF(N(AD19)>0,0,p_CorrFixa))/(H19*W19*$W$6)),9),$W$4),TRUNC(ROUND(MAX(0,($Y$1-IF(N(AD19)>0,0,p_CorrFixa))/(H19*W19*$W$6)),9)/$W$5)*$W$5))) | AG19: =IF(A19="","",IF(AND(N(AD19)=0,N(AF19)*(H19*W19*$W$6)+p_CorrFixa<p_CompraMin),0,AF19)) | AH19: =IF(A19="","",IF(N(AG19)>0,AB19,0)) | AI19: =IF(A19="","",IF(AND(AH19>0,AH19=$AH$6,COUNTIF($AH$9:AH19,AH19)=1),1,0))
H20: =IF(A20="","",IF(AND(p_ModoCot="Automático",ISNUMBER(Z20)),Z20,IF(N(G20)>0,G20,0))) | I20: =IF(A20="","",IF(W20=0,"Sem câmbio",IF(AND(p_ModoCot="Automático",ISNUMBER(Z20)),"Auto",IF(N(G20)>0,"Manual","Sem cotação")))) | J20: =IF(A20="","",N(E20)*H20) | K20: =IF(A20="","",J20*W20) | L20: =IF(A20="","",IF($K$6>0,K20/$K$6,0)) | M20: =IF(A20="","",N(F20)-L20) | N20: =IF(A20="","",IF($AB$6>0,AB20/$AB$6,0)) | O20: =IF(A20="","",IF(AB20<=0,"",COUNTIF($AB$9:$AB$208,">"&AB20)+COUNTIF($AB$9:AB20,AB20))) | P20: =IF(A20="","",IF(Q20>0,"BUY","HOLD")) | Q20: =IF(A20="","",IF($W$7<=0,0,IF($AC$6>0,$W$7*AC20/$AC$6,IF($F$6>0,$W$7*N(F20)/$F$6,0)))) | R20: =IF(A20="","",N(AD20)+IF(AI20=1,N(AG20),0)) | S20: =IF(A20="","",N(E20)+N(R20)) | T20: =IF(A20="","",IF(N(R20)>0,R20*H20*W20*$W$6+p_CorrFixa,0)) | V20: =IF(A20="","",IF(D20="",$W$1,D20)) | W20: =IF(A20="","",IFERROR(INDEX(moeda_fx,MATCH(V20,moeda_cod,0)),0)) | X20: =IF(A20="","",IF($W$2="",UPPER(TRIM(A20)),IF(RIGHT(UPPER(TRIM(A20)),LEN($W$2))=$W$2,UPPER(TRIM(A20)),UPPER(TRIM(A20))&$W$2))) | Y20: =IF(OR(A20="",p_ModoCot<>"Automático"),"",IFERROR(_xlfn.WEBSERVICE("https://query1.finance.yahoo.com/v8/finance/chart/"&X20&"?range=1d&interval=1d"),"")) | Z20: =IF(Y20="","",IFERROR(_xlfn.NUMBERVALUE(MID(Y20,SEARCH("""regularMarketPrice"":",Y20)+21,SEARCH(",",Y20&",",SEARCH("""regularMarketPrice"":",Y20)+21)-SEARCH("""regularMarketPrice"":",Y20)-21),".",","),"")) | AA20: =IF(A20="","",ROUND(MAX(0,N(F20)*($K$6+$W$7)-K20),2)) | AB20: =IF(A20="","",IF(AND(M20>0,M20>=p_DifMin),AA20,0)) | AC20: =IF(A20="","",IF(AND(AB20>0,N(O20)<=p_MaxAtivos),AB20,0)) | AD20: =IF(A20="","",IF(OR(Q20<=0,Q20<p_CompraMin,N(H20)<=0,N(W20)<=0),0,IF($W$3="Sim",TRUNC(ROUND(MAX(0,(Q20-p_CorrFixa)/(H20*W20*$W$6)),9),$W$4),TRUNC(ROUND(MAX(0,(Q20-p_CorrFixa)/(H20*W20*$W$6)),9)/$W$5)*$W$5))) | AE20: =IF(A20="","",IF(N(AD20)>0,AD20*H20*W20*$W$6+p_CorrFixa,0)) | AF20: =IF(A20="","",IF(OR($Y$1<=0,N(H20)<=0,N(W20)<=0,N(AB20)<=0),0,IF($W$3="Sim",TRUNC(ROUND(MAX(0,($Y$1-IF(N(AD20)>0,0,p_CorrFixa))/(H20*W20*$W$6)),9),$W$4),TRUNC(ROUND(MAX(0,($Y$1-IF(N(AD20)>0,0,p_CorrFixa))/(H20*W20*$W$6)),9)/$W$5)*$W$5))) | AG20: =IF(A20="","",IF(AND(N(AD20)=0,N(AF20)*(H20*W20*$W$6)+p_CorrFixa<p_CompraMin),0,AF20)) | AH20: =IF(A20="","",IF(N(AG20)>0,AB20,0)) | AI20: =IF(A20="","",IF(AND(AH20>0,AH20=$AH$6,COUNTIF($AH$9:AH20,AH20)=1),1,0))
... H208: =IF(A208="","",IF(AND(p_ModoCot="Automático",ISNUMBER(Z208)),Z208,IF(N(G208)>0,G208,0))) | I208: =IF(A208="","",IF(W208=0,"Sem câmbio",IF(AND(p_ModoCot="Automático",ISNUMBER(Z208)),"Auto",IF(N(G208)>0,"Manual","Sem cotação")))) | J208: =IF(A208="","",N(E208)*H208) | K208: =IF(A208="","",J208*W208) | L208: =IF(A208="","",IF($K$6>0,K208/$K$6,0)) | M208: =IF(A208="","",N(F208)-L208) | N208: =IF(A208="","",IF($AB$6>0,AB208/$AB$6,0)) | O208: =IF(A208="","",IF(AB208<=0,"",COUNTIF($AB$9:$AB$208,">"&AB208)+COUNTIF($AB$9:AB208,AB208))) | P208: =IF(A208="","",IF(Q208>0,"BUY","HOLD")) | Q208: =IF(A208="","",IF($W$7<=0,0,IF($AC$6>0,$W$7*AC208/$AC$6,IF($F$6>0,$W$7*N(F208)/$F$6,0)))) | R208: =IF(A208="","",N(AD208)+IF(AI208=1,N(AG208),0)) | S208: =IF(A208="","",N(E208)+N(R208)) | T208: =IF(A208="","",IF(N(R208)>0,R208*H208*W208*$W$6+p_CorrFixa,0)) | V208: =IF(A208="","",IF(D208="",$W$1,D208)) | W208: =IF(A208="","",IFERROR(INDEX(moeda_fx,MATCH(V208,moeda_cod,0)),0)) | X208: =IF(A208="","",IF($W$2="",UPPER(TRIM(A208)),IF(RIGHT(UPPER(TRIM(A208)),LEN($W$2))=$W$2,UPPER(TRIM(A208)),UPPER(TRIM(A208))&$W$2))) | Y208: =IF(OR(A208="",p_ModoCot<>"Automático"),"",IFERROR(_xlfn.WEBSERVICE("https://query1.finance.yahoo.com/v8/finance/chart/"&X208&"?range=1d&interval=1d"),"")) | Z208: =IF(Y208="","",IFERROR(_xlfn.NUMBERVALUE(MID(Y208,SEARCH("""regularMarketPrice"":",Y208)+21,SEARCH(",",Y208&",",SEARCH("""regularMarketPrice"":",Y208)+21)-SEARCH("""regularMarketPrice"":",Y208)-21),".",","),"")) | AA208: =IF(A208="","",ROUND(MAX(0,N(F208)*($K$6+$W$7)-K208),2)) | AB208: =IF(A208="","",IF(AND(M208>0,M208>=p_DifMin),AA208,0)) | AC208: =IF(A208="","",IF(AND(AB208>0,N(O208)<=p_MaxAtivos),AB208,0)) | AD208: =IF(A208="","",IF(OR(Q208<=0,Q208<p_CompraMin,N(H208)<=0,N(W208)<=0),0,IF($W$3="Sim",TRUNC(ROUND(MAX(0,(Q208-p_CorrFixa)/(H208*W208*$W$6)),9),$W$4),TRUNC(ROUND(MAX(0,(Q208-p_CorrFixa)/(H208*W208*$W$6)),9)/$W$5)*$W$5))) | AE208: =IF(A208="","",IF(N(AD208)>0,AD208*H208*W208*$W$6+p_CorrFixa,0)) | AF208: =IF(A208="","",IF(OR($Y$1<=0,N(H208)<=0,N(W208)<=0,N(AB208)<=0),0,IF($W$3="Sim",TRUNC(ROUND(MAX(0,($Y$1-IF(N(AD208)>0,0,p_CorrFixa))/(H208*W208*$W$6)),9),$W$4),TRUNC(ROUND(MAX(0,($Y$1-IF(N(AD208)>0,0,p_CorrFixa))/(H208*W208*$W$6)),9)/$W$5)*$W$5))) | AG208: =IF(A208="","",IF(AND(N(AD208)=0,N(AF208)*(H208*W208*$W$6)+p_CorrFixa<p_CompraMin),0,AF208)) | AH208: =IF(A208="","",IF(N(AG208)>0,AB208,0)) | AI208: =IF(A208="","",IF(AND(AH208>0,AH208=$AH$6,COUNTIF($AH$9:AH208,AH208)=1),1,0))

Sheet 04 FIIs
A1: FIIS | T1: ◄ Dashboard | V1: Moeda padrão da classe | W1: =INDEX('10 Configurações'!$D$35:$D$41,MATCH("FIIs",'10 Configurações'!$B$35:$B$41,0))&"" -> BRL | X1: Sobra da 1ª passada (R$) | Y1: =MAX(0,$W$7-SUM($AE$9:$AE$208)) -> 100
A2: ="Moeda padrão: "&$W$1&" · Fração: "&$W$3&" ("&$W$4&" casas) · Lote: "&$W$5&" · Custo efetivo de compra: "&ROUND(($W$6-1)*100,2)&"% · Cotações: "&p_ModoCot -> Moeda padrão: BRL · Fração: Não (0 casas) · Lote: 1 · Custo efetivo de compra: 0% · Cotações: Automático | V2: Sufixo Yahoo | W2: =INDEX('10 Configurações'!$E$35:$E$41,MATCH("FIIs",'10 Configurações'!$B$35:$B$41,0))&"" -> .SA
A3: VALOR DA CLASSE (R$) | C3: Nº DE ATIVOS | G3: APORTE DESTINADO (R$) | K3: COMPRA EFETIVA (R$) | O3: SOBRA DA CLASSE (R$) | T3: SOMA DOS OBJETIVOS | V3: Permite fração? | W3: =INDEX('10 Configurações'!$G$35:$G$41,MATCH("FIIs",'10 Configurações'!$B$35:$B$41,0))&"" -> Não
A4: =$K$6 -> 0 | C4: =SUMPRODUCT(--($A$9:$A$208<>"")) -> 0 | G4: =$W$7 -> 100 | K4: =$T$6 -> 0 | O4: =$W$7-$T$6 -> 100 | T4: =$F$6 -> 0 | V4: Casas decimais | W4: =N(INDEX('10 Configurações'!$H$35:$H$41,MATCH("FIIs",'10 Configurações'!$B$35:$B$41,0))) -> 0
