Workbook
Name p_Aporte: '13 Configurações'!$C$5
Name ref_data: '13 Configurações'!$C$6
Name p_ModoCot: '13 Configurações'!$C$7
Name p_FonteCripto: '13 Configurações'!$C$8
Name p_IOF: '13 Configurações'!$C$9
Name p_Spread: '13 Configurações'!$C$10
Name p_CorrPct: '13 Configurações'!$C$11
Name p_CorrFixa: '13 Configurações'!$C$12
Name p_CompraMin: '13 Configurações'!$C$13
Name p_DifMin: '13 Configurações'!$C$14
Name p_MaxClasses: '13 Configurações'!$C$15
Name p_MaxAtivos: '13 Configurações'!$C$16
Name p_LimAtivo: '13 Configurações'!$C$17
Name p_LimSetor: '13 Configurações'!$C$18
Name moeda_cod: '13 Configurações'!$B$22:$B$31
Name moeda_fx: '13 Configurações'!$G$22:$G$31

Sheet 01 Dashboard
B2: HOLDER PREMIUM | R2: =ref_data -> 46314
B3: Wealth Management System · Carteira consolidada em R$ · Rebalanceamento inteligente | N3: ="Data de referência · Cotações: "&p_ModoCot&" · Moeda base: BRL" -> Data de referência · Cotações: Automático · Moeda base: BRL
B4: Macro | D4: Ações BR | F4: FIIs | H4: Stocks | J4: REITs | L4: Renda Fixa | N4: Cripto | P4: Ilíquidos | R4: Aportes | T4: Dividendos | V4: Patrimônio | X4: Config.
B6: PATRIMÔNIO TOTAL | F6: PATRIMÔNIO BRASIL | J6: PATRIMÔNIO EXTERIOR | N6: DIVIDENDOS RECEBIDOS | R6: DIVIDEND YIELD (12M) | V6: VARIAÇÃO DIÁRIA
B7: ='02 Macro Alocação'!$D$16 -> 0 | F7: ='02 Macro Alocação'!$D$20 -> 0 | J7: ='02 Macro Alocação'!$D$21 -> 0 | N7: =SUMIFS('11 Histórico de Dividendos'!$K$8:$K$3007,'11 Histórico de Dividendos'!$A$8:$A$3007,"<="&ref_data) -> 0 | R7: =IF('02 Macro Alocação'!$D$16>0,SUMIFS('11 Histórico de Dividendos'!$K$8:$K$3007,'11 Histórico de Dividendos'!$A$8:$A$3007,">"&EDATE(ref_data,-12),'11 Histórico de Dividendos'!$A$8:$A$3007,"<="&ref_data)/'02 Macro Alocação'!$D$16,0) -> 0 | V7: =IF('15 Base de Dados'!$M$3>0,('15 Base de Dados'!$J$3-'15 Base de Dados'!$M$3)/'15 Base de Dados'!$M$3,0) -> 0
B8: ="Alternativos: R$ "&FIXED('02 Macro Alocação'!$D$22,2) -> Alternativos: R$ 0.00 | F8: =ROUND('02 Macro Alocação'!$E$20*100,1)&"% do patrimônio" -> 0% do patrimônio | J8: =ROUND('02 Macro Alocação'!$E$21*100,1)&"% do patrimônio" -> 0% do patrimônio | N8: ="12M: R$ "&FIXED(SUMIFS('11 Histórico de Dividendos'!$K$8:$K$3007,'11 Histórico de Dividendos'!$A$8:$A$3007,">"&EDATE(ref_data,-12),'11 Histórico de Dividendos'!$A$8:$A$3007,"<="&ref_data),2)&" · R$ "&FIXED(SUMIFS('11 Histórico de Dividendos'!$K$8:$K$3007,'11 Histórico de Dividendos'!$A$8:$A$3007,">"&EDATE(ref_data,-12),'11 Histórico de Dividendos'!$A$8:$A$3007,"<="&ref_data)/12,2)&"/mês" -> 12M: R$ 0.00 · R$ 0.00/mês | R8: ="Yield on Cost: "&ROUND(IF('15 Base de Dados'!$K$3>0,SUMIFS('11 Histórico de Dividendos'!$K$8:$K$3007,'11 Histórico de Dividendos'!$A$8:$A$3007,">"&EDATE(ref_data,-12),'11 Histórico de Dividendos'!$A$8:$A$3007,"<="&ref_data)/'15 Base de Dados'!$K$3,0)*100,2)&"%" -> Yield on Cost: 0% | V8: ="R$ "&FIXED('15 Base de Dados'!$J$3-'15 Base de Dados'!$M$3,2)&" no dia" -> R$ 0.00 no dia
B10: RENTABILIDADE ACUMULADA | F10: RENTABILIDADE 12M | J10: RESULTADO DA CARTEIRA | N10: APORTES TOTAIS | R10: APORTES DO MÊS | V10: YIELD ON COST (12M)
B11: =IF(COUNT('12 Histórico Patrimonial'!$A$8:$A$307)>=2,INDEX('12 Histórico Patrimonial'!$G$8:$G$307,COUNT('12 Histórico Patrimonial'!$A$8:$A$307)),IF('15 Base de Dados'!$K$3>0,'15 Base de Dados'!$L$3/'15 Base de Dados'!$K$3,0)) -> 0 | F11: =IF(COUNT('12 Histórico Patrimonial'!$A$8:$A$307)>12,(1+INDEX('12 Histórico Patrimonial'!$G$8:$G$307,COUNT('12 Histórico Patrimonial'!$A$8:$A$307)))/(1+INDEX('12 Histórico Patrimonial'!$G$8:$G$307,COUNT('12 Histórico Patrimonial'!$A$8:$A$307)-12))-1,"n/d") -> n/d | J11: ='15 Base de Dados'!$L$3 -> 0 | N11: =SUM('10 Histórico de Aportes'!$D$8:$D$2007) -> 0 | R11: =SUMIFS('10 Histórico de Aportes'!$D$8:$D$2007,'10 Histórico de Aportes'!$F$8:$F$2007,EOMONTH(ref_data,0)) -> 0 | V11: =IF('15 Base de Dados'!$K$3>0,SUMIFS('11 Histórico de Dividendos'!$K$8:$K$3007,'11 Histórico de Dividendos'!$A$8:$A$3007,">"&EDATE(ref_data,-12),'11 Histórico de Dividendos'!$A$8:$A$3007,"<="&ref_data)/'15 Base de Dados'!$K$3,0) -> 0
B12: =IF(COUNT('12 Histórico Patrimonial'!$A$8:$A$307)>=2,"Base: histórico ("&COUNT('12 Histórico Patrimonial'!$A$8:$A$307)&" registros)","Base: custo das posições") -> Base: custo das posições | F12: =IF(COUNT('12 Histórico Patrimonial'!$A$8:$A$307)>12,"Últimos 12 registros","Requer 13 registros mensais") -> Requer 13 registros mensais | J12: ="Sobre o custo: "&ROUND(IF('15 Base de Dados'!$K$3>0,'15 Base de Dados'!$L$3/'15 Base de Dados'!$K$3,0)*100,2)&"%" -> Sobre o custo: 0% | N12: ="Média 12M: R$ "&FIXED(SUMIFS('10 Histórico de Aportes'!$D$8:$D$2007,'10 Histórico de Aportes'!$A$8:$A$2007,">"&EDATE(ref_data,-12),'10 Histórico de Aportes'!$A$8:$A$2007,"<="&ref_data)/12,2)&"/mês" -> Média 12M: R$ 0.00/mês | R12: ="Planejado: R$ "&FIXED(p_Aporte,2) -> Planejado: R$ 500.00 | V12: ="Proventos 12M sobre o custo" -> Proventos 12M sobre o custo
B14: APORTE INTELIGENTE | R14: ="Aporte do mês: R$ "&FIXED(p_Aporte,2)&" · alocado: R$ "&FIXED('02 Macro Alocação'!$M$16,2) -> Aporte do mês: R$ 500.00 · alocado: R$ 500.00
B15: Classe | D15: % Atual | F15: % Obj. | G15: Ação | H15: Aporte (R$) | J15: Ativo | L15: Classe | O15: Qtd. | R15: Cotação | T15: Moeda | V15: Valor Efetivo (R$)
B16: ='02 Macro Alocação'!$B$9 -> Ações | D16: ='02 Macro Alocação'!$E$9 -> 0 | F16: ='02 Macro Alocação'!$F$9 -> 0.4 | G16: ='02 Macro Alocação'!$L$9 -> BUY | H16: ='02 Macro Alocação'!$M$9 -> 200 | J16: =IFERROR(INDEX('15 Base de Dados'!$C$6:$C$925,MATCH(LARGE('15 Base de Dados'!$T$6:$T$925,1),'15 Base de Dados'!$T$6:$T$925,0)),"") | L16: =IFERROR(INDEX('15 Base de Dados'!$A$6:$A$925,MATCH(LARGE('15 Base de Dados'!$T$6:$T$925,1),'15 Base de Dados'!$T$6:$T$925,0)),"") | O16: =IFERROR(INDEX('15 Base de Dados'!$O$6:$O$925,MATCH(LARGE('15 Base de Dados'!$T$6:$T$925,1),'15 Base de Dados'!$T$6:$T$925,0)),"") | R16: =IFERROR(INDEX('15 Base de Dados'!$H$6:$H$925,MATCH(LARGE('15 Base de Dados'!$T$6:$T$925,1),'15 Base de Dados'!$T$6:$T$925,0)),"") | T16: =IFERROR(INDEX('15 Base de Dados'!$F$6:$F$925,MATCH(LARGE('15 Base de Dados'!$T$6:$T$925,1),'15 Base de Dados'!$T$6:$T$925,0)),"") | V16: =IFERROR(INDEX('15 Base de Dados'!$P$6:$P$925,MATCH(LARGE('15 Base de Dados'!$T$6:$T$925,1),'15 Base de Dados'!$T$6:$T$925,0)),"")
B17: ='02 Macro Alocação'!$B$10 -> FIIs | D17: ='02 Macro Alocação'!$E$10 -> 0 | F17: ='02 Macro Alocação'!$F$10 -> 0.2 | G17: ='02 Macro Alocação'!$L$10 -> BUY | H17: ='02 Macro Alocação'!$M$10 -> 100 | J17: =IFERROR(INDEX('15 Base de Dados'!$C$6:$C$925,MATCH(LARGE('15 Base de Dados'!$T$6:$T$925,2),'15 Base de Dados'!$T$6:$T$925,0)),"") | L17: =IFERROR(INDEX('15 Base de Dados'!$A$6:$A$925,MATCH(LARGE('15 Base de Dados'!$T$6:$T$925,2),'15 Base de Dados'!$T$6:$T$925,0)),"") | O17: =IFERROR(INDEX('15 Base de Dados'!$O$6:$O$925,MATCH(LARGE('15 Base de Dados'!$T$6:$T$925,2),'15 Base de Dados'!$T$6:$T$925,0)),"") | R17: =IFERROR(INDEX('15 Base de Dados'!$H$6:$H$925,MATCH(LARGE('15 Base de Dados'!$T$6:$T$925,2),'15 Base de Dados'!$T$6:$T$925,0)),"") | T17: =IFERROR(INDEX('15 Base de Dados'!$F$6:$F$925,MATCH(LARGE('15 Base de Dados'!$T$6:$T$925,2),'15 Base de Dados'!$T$6:$T$925,0)),"") | V17: =IFERROR(INDEX('15 Base de Dados'!$P$6:$P$925,MATCH(LARGE('15 Base de Dados'!$T$6:$T$925,2),'15 Base de Dados'!$T$6:$T$925,0)),"")
B18: ='02 Macro Alocação'!$B$11 -> Renda Fixa | D18: ='02 Macro Alocação'!$E$11 -> 0 | F18: ='02 Macro Alocação'!$F$11 -> 0.05 | G18: ='02 Macro Alocação'!$L$11 -> BUY | H18: ='02 Macro Alocação'!$M$11 -> 25 | J18: =IFERROR(INDEX('15 Base de Dados'!$C$6:$C$925,MATCH(LARGE('15 Base de Dados'!$T$6:$T$925,3),'15 Base de Dados'!$T$6:$T$925,0)),"") | L18: =IFERROR(INDEX('15 Base de Dados'!$A$6:$A$925,MATCH(LARGE('15 Base de Dados'!$T$6:$T$925,3),'15 Base de Dados'!$T$6:$T$925,0)),"") | O18: =IFERROR(INDEX('15 Base de Dados'!$O$6:$O$925,MATCH(LARGE('15 Base de Dados'!$T$6:$T$925,3),'15 Base de Dados'!$T$6:$T$925,0)),"") | R18: =IFERROR(INDEX('15 Base de Dados'!$H$6:$H$925,MATCH(LARGE('15 Base de Dados'!$T$6:$T$925,3),'15 Base de Dados'!$T$6:$T$925,0)),"") | T18: =IFERROR(INDEX('15 Base de Dados'!$F$6:$F$925,MATCH(LARGE('15 Base de Dados'!$T$6:$T$925,3),'15 Base de Dados'!$T$6:$T$925,0)),"") | V18: =IFERROR(INDEX('15 Base de Dados'!$P$6:$P$925,MATCH(LARGE('15 Base de Dados'!$T$6:$T$925,3),'15 Base de Dados'!$T$6:$T$925,0)),"")
B19: ='02 Macro Alocação'!$B$12 -> Stocks | D19: ='02 Macro Alocação'!$E$12 -> 0 | F19: ='02 Macro Alocação'!$F$12 -> 0.2 | G19: ='02 Macro Alocação'!$L$12 -> BUY | H19: ='02 Macro Alocação'!$M$12 -> 100 | J19: =IFERROR(INDEX('15 Base de Dados'!$C$6:$C$925,MATCH(LARGE('15 Base de Dados'!$T$6:$T$925,4),'15 Base de Dados'!$T$6:$T$925,0)),"") | L19: =IFERROR(INDEX('15 Base de Dados'!$A$6:$A$925,MATCH(LARGE('15 Base de Dados'!$T$6:$T$925,4),'15 Base de Dados'!$T$6:$T$925,0)),"") | O19: =IFERROR(INDEX('15 Base de Dados'!$O$6:$O$925,MATCH(LARGE('15 Base de Dados'!$T$6:$T$925,4),'15 Base de Dados'!$T$6:$T$925,0)),"") | R19: =IFERROR(INDEX('15 Base de Dados'!$H$6:$H$925,MATCH(LARGE('15 Base de Dados'!$T$6:$T$925,4),'15 Base de Dados'!$T$6:$T$925,0)),"") | T19: =IFERROR(INDEX('15 Base de Dados'!$F$6:$F$925,MATCH(LARGE('15 Base de Dados'!$T$6:$T$925,4),'15 Base de Dados'!$T$6:$T$925,0)),"") | V19: =IFERROR(INDEX('15 Base de Dados'!$P$6:$P$925,MATCH(LARGE('15 Base de Dados'!$T$6:$T$925,4),'15 Base de Dados'!$T$6:$T$925,0)),"")
B20: ='02 Macro Alocação'!$B$13 -> REITs | D20: ='02 Macro Alocação'!$E$13 -> 0 | F20: ='02 Macro Alocação'!$F$13 -> 0.1 | G20: ='02 Macro Alocação'!$L$13 -> BUY | H20: ='02 Macro Alocação'!$M$13 -> 50 | J20: =IFERROR(INDEX('15 Base de Dados'!$C$6:$C$925,MATCH(LARGE('15 Base de Dados'!$T$6:$T$925,5),'15 Base de Dados'!$T$6:$T$925,0)),"") | L20: =IFERROR(INDEX('15 Base de Dados'!$A$6:$A$925,MATCH(LARGE('15 Base de Dados'!$T$6:$T$925,5),'15 Base de Dados'!$T$6:$T$925,0)),"") | O20: =IFERROR(INDEX('15 Base de Dados'!$O$6:$O$925,MATCH(LARGE('15 Base de Dados'!$T$6:$T$925,5),'15 Base de Dados'!$T$6:$T$925,0)),"") | R20: =IFERROR(INDEX('15 Base de Dados'!$H$6:$H$925,MATCH(LARGE('15 Base de Dados'!$T$6:$T$925,5),'15 Base de Dados'!$T$6:$T$925,0)),"") | T20: =IFERROR(INDEX('15 Base de Dados'!$F$6:$F$925,MATCH(LARGE('15 Base de Dados'!$T$6:$T$925,5),'15 Base de Dados'!$T$6:$T$925,0)),"") | V20: =IFERROR(INDEX('15 Base de Dados'!$P$6:$P$925,MATCH(LARGE('15 Base de Dados'!$T$6:$T$925,5),'15 Base de Dados'!$T$6:$T$925,0)),"")
B21: ='02 Macro Alocação'!$B$14 -> Criptomoedas | D21: ='02 Macro Alocação'!$E$14 -> 0 | F21: ='02 Macro Alocação'!$F$14 -> 0.05 | G21: ='02 Macro Alocação'!$L$14 -> BUY | H21: ='02 Macro Alocação'!$M$14 -> 25 | J21: =IFERROR(INDEX('15 Base de Dados'!$C$6:$C$925,MATCH(LARGE('15 Base de Dados'!$T$6:$T$925,6),'15 Base de Dados'!$T$6:$T$925,0)),"") | L21: =IFERROR(INDEX('15 Base de Dados'!$A$6:$A$925,MATCH(LARGE('15 Base de Dados'!$T$6:$T$925,6),'15 Base de Dados'!$T$6:$T$925,0)),"") | O21: =IFERROR(INDEX('15 Base de Dados'!$O$6:$O$925,MATCH(LARGE('15 Base de Dados'!$T$6:$T$925,6),'15 Base de Dados'!$T$6:$T$925,0)),"") | R21: =IFERROR(INDEX('15 Base de Dados'!$H$6:$H$925,MATCH(LARGE('15 Base de Dados'!$T$6:$T$925,6),'15 Base de Dados'!$T$6:$T$925,0)),"") | T21: =IFERROR(INDEX('15 Base de Dados'!$F$6:$F$925,MATCH(LARGE('15 Base de Dados'!$T$6:$T$925,6),'15 Base de Dados'!$T$6:$T$925,0)),"") | V21: =IFERROR(INDEX('15 Base de Dados'!$P$6:$P$925,MATCH(LARGE('15 Base de Dados'!$T$6:$T$925,6),'15 Base de Dados'!$T$6:$T$925,0)),"")
B22: ='02 Macro Alocação'!$B$15 -> Ativos Ilíquidos | D22: ='02 Macro Alocação'!$E$15 -> 0 | F22: ='02 Macro Alocação'!$F$15 -> 0 | G22: ='02 Macro Alocação'!$L$15 -> HOLD | H22: ='02 Macro Alocação'!$M$15 -> 0 | J22: =IFERROR(INDEX('15 Base de Dados'!$C$6:$C$925,MATCH(LARGE('15 Base de Dados'!$T$6:$T$925,7),'15 Base de Dados'!$T$6:$T$925,0)),"") | L22: =IFERROR(INDEX('15 Base de Dados'!$A$6:$A$925,MATCH(LARGE('15 Base de Dados'!$T$6:$T$925,7),'15 Base de Dados'!$T$6:$T$925,0)),"") | O22: =IFERROR(INDEX('15 Base de Dados'!$O$6:$O$925,MATCH(LARGE('15 Base de Dados'!$T$6:$T$925,7),'15 Base de Dados'!$T$6:$T$925,0)),"") | R22: =IFERROR(INDEX('15 Base de Dados'!$H$6:$H$925,MATCH(LARGE('15 Base de Dados'!$T$6:$T$925,7),'15 Base de Dados'!$T$6:$T$925,0)),"") | T22: =IFERROR(INDEX('15 Base de Dados'!$F$6:$F$925,MATCH(LARGE('15 Base de Dados'!$T$6:$T$925,7),'15 Base de Dados'!$T$6:$T$925,0)),"") | V22: =IFERROR(INDEX('15 Base de Dados'!$P$6:$P$925,MATCH(LARGE('15 Base de Dados'!$T$6:$T$925,7),'15 Base de Dados'!$T$6:$T$925,0)),"")
B23: TOTAL | D23: ='02 Macro Alocação'!$E$16 -> 0 | F23: ='02 Macro Alocação'!$F$16 -> 1 | H23: ='02 Macro Alocação'!$M$16 -> 500 | J23: =IFERROR(INDEX('15 Base de Dados'!$C$6:$C$925,MATCH(LARGE('15 Base de Dados'!$T$6:$T$925,8),'15 Base de Dados'!$T$6:$T$925,0)),"") | L23: =IFERROR(INDEX('15 Base de Dados'!$A$6:$A$925,MATCH(LARGE('15 Base de Dados'!$T$6:$T$925,8),'15 Base de Dados'!$T$6:$T$925,0)),"") | O23: =IFERROR(INDEX('15 Base de Dados'!$O$6:$O$925,MATCH(LARGE('15 Base de Dados'!$T$6:$T$925,8),'15 Base de Dados'!$T$6:$T$925,0)),"") | R23: =IFERROR(INDEX('15 Base de Dados'!$H$6:$H$925,MATCH(LARGE('15 Base de Dados'!$T$6:$T$925,8),'15 Base de Dados'!$T$6:$T$925,0)),"") | T23: =IFERROR(INDEX('15 Base de Dados'!$F$6:$F$925,MATCH(LARGE('15 Base de Dados'!$T$6:$T$925,8),'15 Base de Dados'!$T$6:$T$925,0)),"") | V23: =IFERROR(INDEX('15 Base de Dados'!$P$6:$P$925,MATCH(LARGE('15 Base de Dados'!$T$6:$T$925,8),'15 Base de Dados'!$T$6:$T$925,0)),"")
B24: Sobra após lotes/frações/custos | H24: ='02 Macro Alocação'!$R$16 -> 500 | J24: =IFERROR(INDEX('15 Base de Dados'!$C$6:$C$925,MATCH(LARGE('15 Base de Dados'!$T$6:$T$925,9),'15 Base de Dados'!$T$6:$T$925,0)),"") | L24: =IFERROR(INDEX('15 Base de Dados'!$A$6:$A$925,MATCH(LARGE('15 Base de Dados'!$T$6:$T$925,9),'15 Base de Dados'!$T$6:$T$925,0)),"") | O24: =IFERROR(INDEX('15 Base de Dados'!$O$6:$O$925,MATCH(LARGE('15 Base de Dados'!$T$6:$T$925,9),'15 Base de Dados'!$T$6:$T$925,0)),"") | R24: =IFERROR(INDEX('15 Base de Dados'!$H$6:$H$925,MATCH(LARGE('15 Base de Dados'!$T$6:$T$925,9),'15 Base de Dados'!$T$6:$T$925,0)),"") | T24: =IFERROR(INDEX('15 Base de Dados'!$F$6:$F$925,MATCH(LARGE('15 Base de Dados'!$T$6:$T$925,9),'15 Base de Dados'!$T$6:$T$925,0)),"") | V24: =IFERROR(INDEX('15 Base de Dados'!$P$6:$P$925,MATCH(LARGE('15 Base de Dados'!$T$6:$T$925,9),'15 Base de Dados'!$T$6:$T$925,0)),"")
J25: =IFERROR(INDEX('15 Base de Dados'!$C$6:$C$925,MATCH(LARGE('15 Base de Dados'!$T$6:$T$925,10),'15 Base de Dados'!$T$6:$T$925,0)),"") | L25: =IFERROR(INDEX('15 Base de Dados'!$A$6:$A$925,MATCH(LARGE('15 Base de Dados'!$T$6:$T$925,10),'15 Base de Dados'!$T$6:$T$925,0)),"") | O25: =IFERROR(INDEX('15 Base de Dados'!$O$6:$O$925,MATCH(LARGE('15 Base de Dados'!$T$6:$T$925,10),'15 Base de Dados'!$T$6:$T$925,0)),"") | R25: =IFERROR(INDEX('15 Base de Dados'!$H$6:$H$925,MATCH(LARGE('15 Base de Dados'!$T$6:$T$925,10),'15 Base de Dados'!$T$6:$T$925,0)),"") | T25: =IFERROR(INDEX('15 Base de Dados'!$F$6:$F$925,MATCH(LARGE('15 Base de Dados'!$T$6:$T$925,10),'15 Base de Dados'!$T$6:$T$925,0)),"") | V25: =IFERROR(INDEX('15 Base de Dados'!$P$6:$P$925,MATCH(LARGE('15 Base de Dados'!$T$6:$T$925,10),'15 Base de Dados'!$T$6:$T$925,0)),"")
J26: PLANO DE COMPRAS: as 10 maiores ordens do mês (quantidade, lote e custos já aplicados). Detalhes completos nas abas de cada classe.
B28: ALOCAÇÃO E EXPOSIÇÃO
B45: EVOLUÇÃO
B62: CONTROLE DE RISCO
B63: CONCENTRAÇÃO POR ATIVO | J63: CONCENTRAÇÃO POR SETOR (TOP 6) | R63: EXPOSIÇÃO GEOGRÁFICA E CAMBIAL
B64: Maior posição | F64: =IF('14 Auxiliar'!$C$69="—","—",'14 Auxiliar'!$C$69&" · "&ROUND('14 Auxiliar'!$E$69*100,1)&"%") -> — | J64: ='14 Auxiliar'!$C$129 -> — | N64: ='14 Auxiliar'!$E$129 -> 0 | P64: =IF(N64>p_LimSetor,"ALERTA","OK") -> OK | R64: Grupo | V64: Atual | X64: Objetivo
B65: Menor posição | F65: =IFERROR(INDEX('15 Base de Dados'!$C$6:$C$925,MATCH(SMALL('15 Base de Dados'!$S$6:$S$925,1),'15 Base de Dados'!$S$6:$S$925,0))&" · "&ROUND(INDEX('15 Base de Dados'!$R$6:$R$925,MATCH(SMALL('15 Base de Dados'!$S$6:$S$925,1),'15 Base de Dados'!$S$6:$S$925,0))*100,2)&"%","—") -> — | J65: ='14 Auxiliar'!$C$130 -> — | N65: ='14 Auxiliar'!$E$130 -> 0 | P65: =IF(N65>p_LimSetor,"ALERTA","OK") -> OK | R65: Brasil | V65: ='02 Macro Alocação'!$E$20 -> 0 | X65: ='02 Macro Alocação'!$F$20 -> 0.65
B66: Top 5 posições | F66: =SUM('14 Auxiliar'!$E$69:$E$73) -> 0 | J66: ='14 Auxiliar'!$C$131 -> — | N66: ='14 Auxiliar'!$E$131 -> 0 | P66: =IF(N66>p_LimSetor,"ALERTA","OK") -> OK | R66: Exterior | V66: ='02 Macro Alocação'!$E$21 -> 0 | X66: ='02 Macro Alocação'!$F$21 -> 0.3
B67: Top 10 posições | F67: =SUM('14 Auxiliar'!$E$69:$E$78) -> 0 | J67: ='14 Auxiliar'!$C$132 -> — | N67: ='14 Auxiliar'!$E$132 -> 0 | P67: =IF(N67>p_LimSetor,"ALERTA","OK") -> OK | R67: Alternativos | V67: ='02 Macro Alocação'!$E$22 -> 0 | X67: ='02 Macro Alocação'!$F$22 -> 0.05
B68: Ativos efetivos (1/HHI) | F68: =IFERROR(1/SUMSQ('15 Base de Dados'!$R$6:$R$925),0) -> 0 | J68: ='14 Auxiliar'!$C$133 -> — | N68: ='14 Auxiliar'!$E$133 -> 0 | P68: =IF(N68>p_LimSetor,"ALERTA","OK") -> OK | R68: Moeda | V68: Atual
B69: Nº de ativos | F69: =SUMPRODUCT(--('15 Base de Dados'!$C$6:$C$925<>"")) -> 0 | J69: ='14 Auxiliar'!$C$134 -> — | N69: ='14 Auxiliar'!$E$134 -> 0 | P69: =IF(N69>p_LimSetor,"ALERTA","OK") -> OK | R69: ='14 Auxiliar'!$B$139 -> BRL | V69: ='14 Auxiliar'!$D$139 -> 0
B70: Limite por ativo | F70: =p_LimAtivo -> 0.1 | J70: Limite por setor | N70: =p_LimSetor -> 0.3 | R70: ='14 Auxiliar'!$B$140 -> USD | V70: ='14 Auxiliar'!$D$140 -> 0
B71: Posições acima do limite | F71: =COUNTIF('15 Base de Dados'!$R$6:$R$925,">"&p_LimAtivo) -> 0 | J71: Setores acima do limite | N71: =COUNTIF('14 Auxiliar'!$E$129:$E$134,">"&p_LimSetor) -> 0 | R71: ='14 Auxiliar'!$B$141 -> EUR | V71: ='14 Auxiliar'!$D$141 -> 0
R72: ='14 Auxiliar'!$B$142 -> Outras | V72: ='14 Auxiliar'!$D$142 -> 0
B74: HOLDER PREMIUM · Informativo, não constitui recomendação de investimento. Cotações dependem da fonte configurada.

Sheet 02 Macro Alocação
A1: MACRO ALOCAÇÃO | U1: ◄ Dashboard
A2: Defina o % objetivo de cada classe. A planilha calcula o percentual atual, a diferença, BUY/HOLD e distribui o aporte pelas classes mais distantes do objetivo.
B4: APORTE DO MÊS (Configurações) | D4: PATRIMÔNIO ATUAL | F4: PATRIMÔNIO PÓS-APORTE | I4: CLASSES A APORTAR | K4: SOMA DOS OBJETIVOS | N4: APORTE ALOCADO (R$) | Q4: SOBRA APÓS AS COMPRAS (R$)
B5: =p_Aporte -> 500 | D5: =D16 -> 0 | F5: =D16+p_Aporte -> 500 | I5: =COUNTIF($L$9:$L$15,"BUY") -> 6 | K5: =F16 -> 1 | N5: =M16 -> 500 | Q5: =R16 -> 500
B7: ALOCAÇÃO-ALVO POR CLASSE E APORTE INTELIGENTE
B8: Classe | C8: Grupo | D8: Valor Atual (R$) | E8: % Atual | F8: % Objetivo | G8: Diferença (p.p.) | H8: Situação | I8: Déficit p/ Objetivo (R$) | J8: Rebalance Score | K8: Prior. | L8: BUY / HOLD | M8: Aporte Sugerido (R$) | N8: % do Aporte | O8: Valor Pós-Aporte (R$) | P8: % Pós-Aporte | Q8: Compra Efetiva (R$) | R8: Sobra (R$) | S8: Custo (R$) | T8: Resultado (R$) | U8: Rentab. | W8: Déficit elegível | X8: Déficit final
B9: Ações | C9: Brasil | D9: ='03 Ações BR'!$M$6 -> 0 | E9: =IF($D$16>0,D9/$D$16,0) -> 0 | F9: 0.4 | G9: =F9-E9 -> 0.4 | H9: =IF(ABS(G9)<p_DifMin,"Alinhado",IF(G9>0,"Subpeso","Sobrepeso")) -> Subpeso | I9: =ROUND(MAX(0,F9*($D$16+p_Aporte)-D9),2) -> 200 | J9: =IF($W$16>0,W9/$W$16,0) -> 0.4 | K9: =IF(W9<=0,"",COUNTIF($W$9:$W$15,">"&W9)+COUNTIF($W$9:W9,W9)) -> 1 | L9: =IF(M9>0,"BUY","HOLD") -> BUY | M9: =IF(p_Aporte<=0,0,IF($X$16>0,p_Aporte*X9/$X$16,IF($F$16>0,p_Aporte*F9/$F$16,0))) -> 200 | N9: =IF(p_Aporte>0,M9/p_Aporte,0) -> 0.4 | O9: =D9+M9 -> 200 | P9: =IF($D$16+p_Aporte>0,O9/($D$16+p_Aporte),0) -> 0.4 | Q9: ='03 Ações BR'!$Y$6 -> 0 | R9: =M9-Q9 -> 200 | S9: ='03 Ações BR'!$N$6 -> 0 | T9: ='03 Ações BR'!$O$6 -> 0 | U9: =IF(S9>0,T9/S9,0) -> 0 | W9: =IF(AND(G9>0,G9>=p_DifMin),I9,0) -> 200 | X9: =IF(AND(W9>0,N(K9)<=p_MaxClasses),W9,0) -> 200
B10: FIIs | C10: Brasil | D10: ='04 FIIs'!$M$6 -> 0 | E10: =IF($D$16>0,D10/$D$16,0) -> 0 | F10: 0.2 | G10: =F10-E10 -> 0.2 | H10: =IF(ABS(G10)<p_DifMin,"Alinhado",IF(G10>0,"Subpeso","Sobrepeso")) -> Subpeso | I10: =ROUND(MAX(0,F10*($D$16+p_Aporte)-D10),2) -> 100 | J10: =IF($W$16>0,W10/$W$16,0) -> 0.2 | K10: =IF(W10<=0,"",COUNTIF($W$9:$W$15,">"&W10)+COUNTIF($W$9:W10,W10)) -> 2 | L10: =IF(M10>0,"BUY","HOLD") -> BUY | M10: =IF(p_Aporte<=0,0,IF($X$16>0,p_Aporte*X10/$X$16,IF($F$16>0,p_Aporte*F10/$F$16,0))) -> 100 | N10: =IF(p_Aporte>0,M10/p_Aporte,0) -> 0.2 | O10: =D10+M10 -> 100 | P10: =IF($D$16+p_Aporte>0,O10/($D$16+p_Aporte),0) -> 0.2 | Q10: ='04 FIIs'!$Y$6 -> 0 | R10: =M10-Q10 -> 100 | S10: ='04 FIIs'!$N$6 -> 0 | T10: ='04 FIIs'!$O$6 -> 0 | U10: =IF(S10>0,T10/S10,0) -> 0 | W10: =IF(AND(G10>0,G10>=p_DifMin),I10,0) -> 100 | X10: =IF(AND(W10>0,N(K10)<=p_MaxClasses),W10,0) -> 100
B11: Renda Fixa | C11: Brasil | D11: ='07 Renda Fixa'!$J$6 -> 0 | E11: =IF($D$16>0,D11/$D$16,0) -> 0 | F11: 0.05 | G11: =F11-E11 -> 0.05 | H11: =IF(ABS(G11)<p_DifMin,"Alinhado",IF(G11>0,"Subpeso","Sobrepeso")) -> Subpeso | I11: =ROUND(MAX(0,F11*($D$16+p_Aporte)-D11),2) -> 25 | J11: =IF($W$16>0,W11/$W$16,0) -> 0.05 | K11: =IF(W11<=0,"",COUNTIF($W$9:$W$15,">"&W11)+COUNTIF($W$9:W11,W11)) -> 5 | L11: =IF(M11>0,"BUY","HOLD") -> BUY | M11: =IF(p_Aporte<=0,0,IF($X$16>0,p_Aporte*X11/$X$16,IF($F$16>0,p_Aporte*F11/$F$16,0))) -> 25 | N11: =IF(p_Aporte>0,M11/p_Aporte,0) -> 0.05 | O11: =D11+M11 -> 25 | P11: =IF($D$16+p_Aporte>0,O11/($D$16+p_Aporte),0) -> 0.05 | Q11: ='07 Renda Fixa'!$U$6 -> 0 | R11: =M11-Q11 -> 25 | S11: ='07 Renda Fixa'!$K$6 -> 0 | T11: ='07 Renda Fixa'!$L$6 -> 0 | U11: =IF(S11>0,T11/S11,0) -> 0 | W11: =IF(AND(G11>0,G11>=p_DifMin),I11,0) -> 25 | X11: =IF(AND(W11>0,N(K11)<=p_MaxClasses),W11,0) -> 25
B12: Stocks | C12: Exterior | D12: ='05 Stocks'!$M$6 -> 0 | E12: =IF($D$16>0,D12/$D$16,0) -> 0 | F12: 0.2 | G12: =F12-E12 -> 0.2 | H12: =IF(ABS(G12)<p_DifMin,"Alinhado",IF(G12>0,"Subpeso","Sobrepeso")) -> Subpeso | I12: =ROUND(MAX(0,F12*($D$16+p_Aporte)-D12),2) -> 100 | J12: =IF($W$16>0,W12/$W$16,0) -> 0.2 | K12: =IF(W12<=0,"",COUNTIF($W$9:$W$15,">"&W12)+COUNTIF($W$9:W12,W12)) -> 3 | L12: =IF(M12>0,"BUY","HOLD") -> BUY | M12: =IF(p_Aporte<=0,0,IF($X$16>0,p_Aporte*X12/$X$16,IF($F$16>0,p_Aporte*F12/$F$16,0))) -> 100 | N12: =IF(p_Aporte>0,M12/p_Aporte,0) -> 0.2 | O12: =D12+M12 -> 100 | P12: =IF($D$16+p_Aporte>0,O12/($D$16+p_Aporte),0) -> 0.2 | Q12: ='05 Stocks'!$Y$6 -> 0 | R12: =M12-Q12 -> 100 | S12: ='05 Stocks'!$N$6 -> 0 | T12: ='05 Stocks'!$O$6 -> 0 | U12: =IF(S12>0,T12/S12,0) -> 0 | W12: =IF(AND(G12>0,G12>=p_DifMin),I12,0) -> 100 | X12: =IF(AND(W12>0,N(K12)<=p_MaxClasses),W12,0) -> 100
B13: REITs | C13: Exterior | D13: ='06 REITs'!$M$6 -> 0 | E13: =IF($D$16>0,D13/$D$16,0) -> 0 | F13: 0.1 | G13: =F13-E13 -> 0.1 | H13: =IF(ABS(G13)<p_DifMin,"Alinhado",IF(G13>0,"Subpeso","Sobrepeso")) -> Subpeso | I13: =ROUND(MAX(0,F13*($D$16+p_Aporte)-D13),2) -> 50 | J13: =IF($W$16>0,W13/$W$16,0) -> 0.1 | K13: =IF(W13<=0,"",COUNTIF($W$9:$W$15,">"&W13)+COUNTIF($W$9:W13,W13)) -> 4 | L13: =IF(M13>0,"BUY","HOLD") -> BUY | M13: =IF(p_Aporte<=0,0,IF($X$16>0,p_Aporte*X13/$X$16,IF($F$16>0,p_Aporte*F13/$F$16,0))) -> 50 | N13: =IF(p_Aporte>0,M13/p_Aporte,0) -> 0.1 | O13: =D13+M13 -> 50 | P13: =IF($D$16+p_Aporte>0,O13/($D$16+p_Aporte),0) -> 0.1 | Q13: ='06 REITs'!$Y$6 -> 0 | R13: =M13-Q13 -> 50 | S13: ='06 REITs'!$N$6 -> 0 | T13: ='06 REITs'!$O$6 -> 0 | U13: =IF(S13>0,T13/S13,0) -> 0 | W13: =IF(AND(G13>0,G13>=p_DifMin),I13,0) -> 50 | X13: =IF(AND(W13>0,N(K13)<=p_MaxClasses),W13,0) -> 50
B14: Criptomoedas | C14: Alternativos | D14: ='08 Criptomoedas'!$N$6 -> 0 | E14: =IF($D$16>0,D14/$D$16,0) -> 0 | F14: 0.05 | G14: =F14-E14 -> 0.05 | H14: =IF(ABS(G14)<p_DifMin,"Alinhado",IF(G14>0,"Subpeso","Sobrepeso")) -> Subpeso | I14: =ROUND(MAX(0,F14*($D$16+p_Aporte)-D14),2) -> 25 | J14: =IF($W$16>0,W14/$W$16,0) -> 0.05 | K14: =IF(W14<=0,"",COUNTIF($W$9:$W$15,">"&W14)+COUNTIF($W$9:W14,W14)) -> 6 | L14: =IF(M14>0,"BUY","HOLD") -> BUY | M14: =IF(p_Aporte<=0,0,IF($X$16>0,p_Aporte*X14/$X$16,IF($F$16>0,p_Aporte*F14/$F$16,0))) -> 25 | N14: =IF(p_Aporte>0,M14/p_Aporte,0) -> 0.05 | O14: =D14+M14 -> 25 | P14: =IF($D$16+p_Aporte>0,O14/($D$16+p_Aporte),0) -> 0.05 | Q14: ='08 Criptomoedas'!$Z$6 -> 0 | R14: =M14-Q14 -> 25 | S14: ='08 Criptomoedas'!$O$6 -> 0 | T14: ='08 Criptomoedas'!$P$6 -> 0 | U14: =IF(S14>0,T14/S14,0) -> 0 | W14: =IF(AND(G14>0,G14>=p_DifMin),I14,0) -> 25 | X14: =IF(AND(W14>0,N(K14)<=p_MaxClasses),W14,0) -> 25
B15: Ativos Ilíquidos | C15: Alternativos | D15: ='09 Ativos Ilíquidos'!$H$6 -> 0 | E15: =IF($D$16>0,D15/$D$16,0) -> 0 | F15: 0 | G15: =F15-E15 -> 0 | H15: =IF(ABS(G15)<p_DifMin,"Alinhado",IF(G15>0,"Subpeso","Sobrepeso")) -> Alinhado | I15: =ROUND(MAX(0,F15*($D$16+p_Aporte)-D15),2) -> 0 | J15: =IF($W$16>0,W15/$W$16,0) -> 0 | K15: =IF(W15<=0,"",COUNTIF($W$9:$W$15,">"&W15)+COUNTIF($W$9:W15,W15)) | L15: =IF(M15>0,"BUY","HOLD") -> HOLD | M15: =IF(p_Aporte<=0,0,IF($X$16>0,p_Aporte*X15/$X$16,IF($F$16>0,p_Aporte*F15/$F$16,0))) -> 0 | N15: =IF(p_Aporte>0,M15/p_Aporte,0) -> 0 | O15: =D15+M15 -> 0 | P15: =IF($D$16+p_Aporte>0,O15/($D$16+p_Aporte),0) -> 0 | Q15: ='09 Ativos Ilíquidos'!$S$6 -> 0 | R15: =M15-Q15 -> 0 | S15: ='09 Ativos Ilíquidos'!$I$6 -> 0 | T15: ='09 Ativos Ilíquidos'!$J$6 -> 0 | U15: =IF(S15>0,T15/S15,0) -> 0 | W15: =IF(AND(G15>0,G15>=p_DifMin),I15,0) -> 0 | X15: =IF(AND(W15>0,N(K15)<=p_MaxClasses),W15,0) -> 0
B16: TOTAL | D16: =SUM(D9:D15) -> 0 | E16: =SUM(E9:E15) -> 0 | F16: =SUM(F9:F15) -> 1 | I16: =SUM(I9:I15) -> 500 | J16: =SUM(J9:J15) -> 1 | M16: =SUM(M9:M15) -> 500 | N16: =SUM(N9:N15) -> 1 | O16: =SUM(O9:O15) -> 500 | P16: =SUM(P9:P15) -> 1 | Q16: =SUM(Q9:Q15) -> 0 | R16: =SUM(R9:R15) -> 500 | S16: =SUM(S9:S15) -> 0 | T16: =SUM(T9:T15) -> 0 | U16: =IF(S16>0,T16/S16,0) -> 0 | W16: =SUM(W9:W15) -> 500 | X16: =SUM(X9:X15) -> 500
B17: Como funciona: Déficit = máx(0; % Objetivo × (Patrimônio + Aporte) − Valor Atual). O Rebalance Score é o déficit da classe ÷ soma dos déficits das classes elegíveis (diferença ≥ valor mínimo em Configurações). O aporte é dividido proporcionalmente ao Score entre as N classes de maior prioridade. Classes em sobrepeso recebem HOLD. A Compra Efetiva usa as ordens reais das abas de cada classe (lote, fração, custos e reaproveitamento da sobra).
B18: EXPOSIÇÃO GEOGRÁFICA: BRASIL × EXTERIOR × ALTERNATIVOS
B19: Grupo | D19: Valor Atual (R$) | E19: % Atual | F19: % Objetivo | G19: Diferença (p.p.) | H19: Situação | M19: Aporte Sugerido (R$) | O19: Valor Pós-Aporte (R$) | P19: % Pós-Aporte
B20: Brasil | D20: =SUMIF($C$9:$C$15,"Brasil",$D$9:$D$15) -> 0 | E20: =SUMIF($C$9:$C$15,"Brasil",$E$9:$E$15) -> 0 | F20: =SUMIF($C$9:$C$15,"Brasil",$F$9:$F$15) -> 0.65 | G20: =F20-E20 -> 0.65 | H20: =IF(ABS(G20)<p_DifMin,"Alinhado",IF(G20>0,"Subpeso","Sobrepeso")) -> Subpeso | M20: =SUMIF($C$9:$C$15,"Brasil",$M$9:$M$15) -> 325 | O20: =SUMIF($C$9:$C$15,"Brasil",$O$9:$O$15) -> 325 | P20: =SUMIF($C$9:$C$15,"Brasil",$P$9:$P$15) -> 0.65
B21: Exterior | D21: =SUMIF($C$9:$C$15,"Exterior",$D$9:$D$15) -> 0 | E21: =SUMIF($C$9:$C$15,"Exterior",$E$9:$E$15) -> 0 | F21: =SUMIF($C$9:$C$15,"Exterior",$F$9:$F$15) -> 0.3 | G21: =F21-E21 -> 0.3 | H21: =IF(ABS(G21)<p_DifMin,"Alinhado",IF(G21>0,"Subpeso","Sobrepeso")) -> Subpeso | M21: =SUMIF($C$9:$C$15,"Exterior",$M$9:$M$15) -> 150 | O21: =SUMIF($C$9:$C$15,"Exterior",$O$9:$O$15) -> 150 | P21: =SUMIF($C$9:$C$15,"Exterior",$P$9:$P$15) -> 0.3
B22: Alternativos | D22: =SUMIF($C$9:$C$15,"Alternativos",$D$9:$D$15) -> 0 | E22: =SUMIF($C$9:$C$15,"Alternativos",$E$9:$E$15) -> 0 | F22: =SUMIF($C$9:$C$15,"Alternativos",$F$9:$F$15) -> 0.05 | G22: =F22-E22 -> 0.05 | H22: =IF(ABS(G22)<p_DifMin,"Alinhado",IF(G22>0,"Subpeso","Sobrepeso")) -> Subpeso | M22: =SUMIF($C$9:$C$15,"Alternativos",$M$9:$M$15) -> 25 | O22: =SUMIF($C$9:$C$15,"Alternativos",$O$9:$O$15) -> 25 | P22: =SUMIF($C$9:$C$15,"Alternativos",$P$9:$P$15) -> 0.05
B23: TOTAL | D23: =SUM(D20:D22) -> 0 | E23: =SUM(E20:E22) -> 0 | F23: =SUM(F20:F22) -> 1 | M23: =SUM(M20:M22) -> 500 | O23: =SUM(O20:O22) -> 500 | P23: =SUM(P20:P22) -> 1

Sheet 03 Ações BR
A1: AÇÕES BR | AB1: ◄ Dashboard | AD1: Moeda padrão da classe | AE1: =INDEX('13 Configurações'!$D$36:$D$42,MATCH("Ações",'13 Configurações'!$B$36:$B$42,0))&"" -> BRL | AH1: Sobra da 1ª passada (R$) | AI1: =MAX(0,$AE$7-SUM($AO$9:$AO$208)) -> 200
A2: ="Moeda padrão: "&$AE$1&" · Fração: "&$AE$3&" ("&$AE$4&" casas) · Lote: "&$AE$5&" · Custo efetivo de compra: "&ROUND(($AE$6-1)*100,2)&"% · Cotações: "&p_ModoCot -> Moeda padrão: BRL · Fração: Não (0 casas) · Lote: 1 · Custo efetivo de compra: 0% · Cotações: Automático | AD2: Sufixo Yahoo | AE2: =INDEX('13 Configurações'!$E$36:$E$42,MATCH("Ações",'13 Configurações'!$B$36:$B$42,0))&"" -> .SA
A3: VALOR DA CLASSE (R$) | C3: Nº DE ATIVOS | E3: APORTE DESTINADO (R$) | H3: COMPRA EFETIVA (R$) | J3: RENTABILIDADE | L3: DIVIDEND YIELD 12M | N3: SOMA DOS OBJETIVOS | AD3: Permite fração? | AE3: =INDEX('13 Configurações'!$G$36:$G$42,MATCH("Ações",'13 Configurações'!$B$36:$B$42,0))&"" -> Não
A4: =$M$6 -> 0 | C4: =SUMPRODUCT(--($A$9:$A$208<>"")) -> 0 | E4: =$AE$7 -> 200 | H4: =$Y$6 -> 0 | J4: =$P$6 -> 0 | L4: =$AA$6 -> 0 | N4: =$R$6 -> 0 | AD4: Casas decimais | AE4: =N(INDEX('13 Configurações'!$H$36:$H$42,MATCH("Ações",'13 Configurações'!$B$36:$B$42,0))) -> 0
A5: ■ Células em azul = entrada de dados ■ Demais células = fórmulas automáticas (não edite) ■ Valor Efetivo = ordem real (lote/fração/custos); a sobra do arredondamento vai para o ativo de maior prioridade | AD5: Lote efetivo | AE5: =IF(INDEX('13 Configurações'!$I$36:$I$42,MATCH("Ações",'13 Configurações'!$B$36:$B$42,0))="Sim",MAX(1,N(INDEX('13 Configurações'!$J$36:$J$42,MATCH("Ações",'13 Configurações'!$B$36:$B$42,0)))),1) -> 1
A6: TOTAL | M6: =SUM($M$9:$M$208) -> 0 | N6: =SUM($N$9:$N$208) -> 0 | O6: =SUM($O$9:$O$208) -> 0 | P6: =IF($N$6>0,$O$6/$N$6,0) -> 0 | Q6: =SUM($Q$9:$Q$208) -> 0 | R6: =SUM($R$9:$R$208) -> 0 | T6: =SUM($T$9:$T$208) -> 0 | W6: =SUM($W$9:$W$208) -> 0 | Y6: =SUM($Y$9:$Y$208) -> 0 | Z6: =SUM($Z$9:$Z$208) -> 0 | AA6: =IF($M$6>0,$Z$6/$M$6,0) -> 0 | AB6: =IF($N$6>0,$Z$6/$N$6,0) -> 0 | AD6: Fator de custo (1 + custos) | AE6: =1+N(INDEX('13 Configurações'!$K$36:$K$42,MATCH("Ações",'13 Configurações'!$B$36:$B$42,0))) -> 1 | AL6: =SUM($AL$9:$AL$208) -> 0 | AM6: =SUM($AM$9:$AM$208) -> 0 | AR6: =MAX($AR$9:$AR$208) -> 0
A7: CADASTRO | E7: POSIÇÃO | H7: COTAÇÃO | L7: RESULTADO | Q7: REBALANCEAMENTO | Z7: PROVENTOS | AD7: Aporte destinado à classe (R$) | AE7: ='02 Macro Alocação'!$M$9 -> 200
A8: Ticker | B8: Nome / Descrição | C8: Setor / Segmento | D8: Moeda | E8: Quantidade | F8: Preço Médio | G8: Câmbio Médio (opc.) | H8: Cotação Manual | I8: Fech. Anterior Manual | J8: Cotação | K8: Fonte | L8: Valor Atual (Moeda) | M8: Valor Atual (R$) | N8: Custo (R$) | O8: Resultado (R$) | P8: Rentab. | Q8: Part. na Classe | R8: Objetivo | S8: Diferença | T8: Rebalance Score | U8: Prior. | V8: Ação | W8: Valor Sugerido (R$) | X8: Qtd. Sugerida | Y8: Valor Efetivo (R$) | Z8: Proventos 12M (R$) | AA8: DY 12M | AB8: Yield on Cost | AD8: Moeda efetiva | AE8: Câmbio (R$) | AF8: Ticker Yahoo | AG8: Resposta da API | AH8: Cotação auto | AI8: Fech. ant. auto | AJ8: Valor anterior (R$) | AK8: Déficit (R$) | AL8: Déficit elegível | AM8: Déficit final | AN8: Qtd 1ª passada | AO8: Valor 1ª passada (R$) | AP8: Qtd extra (bruta) | AQ8: Qtd extra | AR8: Prioridade extra | AS8: Recebe a sobra
J9: =IF(A9="","",IF(AND(p_ModoCot="Automático",ISNUMBER(AH9)),AH9,IF(N(H9)>0,H9,N(F9)))) | K9: =IF(A9="","",IF(AE9=0,"Sem câmbio",IF(AND(p_ModoCot="Automático",ISNUMBER(AH9)),"Auto",IF(N(H9)>0,"Manual",IF(N(F9)>0,"PM","Sem cotação"))))) | L9: =IF(A9="","",N(E9)*J9) | M9: =IF(A9="","",L9*AE9) | N9: =IF(A9="","",N(E9)*N(F9)*IF(N(G9)>0,G9,AE9)) | O9: =IF(A9="","",M9-N9) | P9: =IF(A9="","",IF(N9>0,O9/N9,0)) | Q9: =IF(A9="","",IF($M$6>0,M9/$M$6,0)) | S9: =IF(A9="","",N(R9)-Q9) | T9: =IF(A9="","",IF($AL$6>0,AL9/$AL$6,0)) | U9: =IF(A9="","",IF(AL9<=0,"",COUNTIF($AL$9:$AL$208,">"&AL9)+COUNTIF($AL$9:AL9,AL9))) | V9: =IF(A9="","",IF(W9>0,"BUY","HOLD")) | W9: =IF(A9="","",IF($AE$7<=0,0,IF($AM$6>0,$AE$7*AM9/$AM$6,IF($R$6>0,$AE$7*N(R9)/$R$6,0)))) | X9: =IF(A9="","",N(AN9)+IF(AS9=1,N(AQ9),0)) | Y9: =IF(A9="","",IF(N(X9)>0,X9*J9*AE9*$AE$6+p_CorrFixa,0)) | Z9: =IF(A9="","",SUMIFS('11 Histórico de Dividendos'!$K$8:$K$3007,'11 Histórico de Dividendos'!$B$8:$B$3007,A9,'11 Histórico de Dividendos'!$A$8:$A$3007,">"&EDATE(ref_data,-12),'11 Histórico de Dividendos'!$A$8:$A$3007,"<="&ref_data)) | AA9: =IF(A9="","",IF(M9>0,Z9/M9,0)) | AB9: =IF(A9="","",IF(N9>0,Z9/N9,0)) | AD9: =IF(A9="","",IF(D9="",$AE$1,D9)) | AE9: =IF(A9="","",IFERROR(INDEX(moeda_fx,MATCH(AD9,moeda_cod,0)),0)) | AF9: =IF(A9="","",IF($AE$2="",UPPER(TRIM(A9)),IF(RIGHT(UPPER(TRIM(A9)),LEN($AE$2))=$AE$2,UPPER(TRIM(A9)),UPPER(TRIM(A9))&$AE$2))) | AG9: =IF(OR(A9="",p_ModoCot<>"Automático"),"",IFERROR(_xlfn.WEBSERVICE("https://query1.finance.yahoo.com/v8/finance/chart/"&AF9&"?range=1d&interval=1d"),"")) | AH9: =IF(AG9="","",IFERROR(_xlfn.NUMBERVALUE(MID(AG9,SEARCH("""regularMarketPrice"":",AG9)+21,SEARCH(",",AG9&",",SEARCH("""regularMarketPrice"":",AG9)+21)-SEARCH("""regularMarketPrice"":",AG9)-21),".",","),"")) | AI9: =IF(AG9="","",IFERROR(_xlfn.NUMBERVALUE(MID(AG9,SEARCH("""chartPreviousClose"":",AG9)+21,SEARCH(",",AG9&",",SEARCH("""chartPreviousClose"":",AG9)+21)-SEARCH("""chartPreviousClose"":",AG9)-21),".",","),"")) | AJ9: =IF(A9="","",N(E9)*IF(AND(p_ModoCot="Automático",ISNUMBER(AI9)),AI9,IF(N(I9)>0,I9,J9))*AE9) | AK9: =IF(A9="","",ROUND(MAX(0,N(R9)*($M$6+$AE$7)-M9),2)) | AL9: =IF(A9="","",IF(AND(S9>0,S9>=p_DifMin),AK9,0)) | AM9: =IF(A9="","",IF(AND(AL9>0,N(U9)<=p_MaxAtivos),AL9,0)) | AN9: =IF(A9="","",IF(OR(W9<=0,W9<p_CompraMin,N(J9)<=0,N(AE9)<=0),0,IF($AE$3="Sim",TRUNC(ROUND(MAX(0,(W9-p_CorrFixa)/(J9*AE9*$AE$6)),9),$AE$4),TRUNC(ROUND(MAX(0,(W9-p_CorrFixa)/(J9*AE9*$AE$6)),9)/$AE$5)*$AE$5))) | AO9: =IF(A9="","",IF(N(AN9)>0,AN9*J9*AE9*$AE$6+p_CorrFixa,0)) | AP9: =IF(A9="","",IF(OR($AI$1<=0,N(J9)<=0,N(AE9)<=0,N(AL9)<=0),0,IF($AE$3="Sim",TRUNC(ROUND(MAX(0,($AI$1-IF(N(AN9)>0,0,p_CorrFixa))/(J9*AE9*$AE$6)),9),$AE$4),TRUNC(ROUND(MAX(0,($AI$1-IF(N(AN9)>0,0,p_CorrFixa))/(J9*AE9*$AE$6)),9)/$AE$5)*$AE$5))) | AQ9: =IF(A9="","",IF(AND(N(AN9)=0,N(AP9)*(J9*AE9*$AE$6)+p_CorrFixa<p_CompraMin),0,AP9)) | AR9: =IF(A9="","",IF(N(AQ9)>0,AL9,0)) | AS9: =IF(A9="","",IF(AND(AR9>0,AR9=$AR$6,COUNTIF($AR$9:AR9,AR9)=1),1,0))
J10: =IF(A10="","",IF(AND(p_ModoCot="Automático",ISNUMBER(AH10)),AH10,IF(N(H10)>0,H10,N(F10)))) | K10: =IF(A10="","",IF(AE10=0,"Sem câmbio",IF(AND(p_ModoCot="Automático",ISNUMBER(AH10)),"Auto",IF(N(H10)>0,"Manual",IF(N(F10)>0,"PM","Sem cotação"))))) | L10: =IF(A10="","",N(E10)*J10) | M10: =IF(A10="","",L10*AE10) | N10: =IF(A10="","",N(E10)*N(F10)*IF(N(G10)>0,G10,AE10)) | O10: =IF(A10="","",M10-N10) | P10: =IF(A10="","",IF(N10>0,O10/N10,0)) | Q10: =IF(A10="","",IF($M$6>0,M10/$M$6,0)) | S10: =IF(A10="","",N(R10)-Q10) | T10: =IF(A10="","",IF($AL$6>0,AL10/$AL$6,0)) | U10: =IF(A10="","",IF(AL10<=0,"",COUNTIF($AL$9:$AL$208,">"&AL10)+COUNTIF($AL$9:AL10,AL10))) | V10: =IF(A10="","",IF(W10>0,"BUY","HOLD")) | W10: =IF(A10="","",IF($AE$7<=0,0,IF($AM$6>0,$AE$7*AM10/$AM$6,IF($R$6>0,$AE$7*N(R10)/$R$6,0)))) | X10: =IF(A10="","",N(AN10)+IF(AS10=1,N(AQ10),0)) | Y10: =IF(A10="","",IF(N(X10)>0,X10*J10*AE10*$AE$6+p_CorrFixa,0)) | Z10: =IF(A10="","",SUMIFS('11 Histórico de Dividendos'!$K$8:$K$3007,'11 Histórico de Dividendos'!$B$8:$B$3007,A10,'11 Histórico de Dividendos'!$A$8:$A$3007,">"&EDATE(ref_data,-12),'11 Histórico de Dividendos'!$A$8:$A$3007,"<="&ref_data)) | AA10: =IF(A10="","",IF(M10>0,Z10/M10,0)) | AB10: =IF(A10="","",IF(N10>0,Z10/N10,0)) | AD10: =IF(A10="","",IF(D10="",$AE$1,D10)) | AE10: =IF(A10="","",IFERROR(INDEX(moeda_fx,MATCH(AD10,moeda_cod,0)),0)) | AF10: =IF(A10="","",IF($AE$2="",UPPER(TRIM(A10)),IF(RIGHT(UPPER(TRIM(A10)),LEN($AE$2))=$AE$2,UPPER(TRIM(A10)),UPPER(TRIM(A10))&$AE$2))) | AG10: =IF(OR(A10="",p_ModoCot<>"Automático"),"",IFERROR(_xlfn.WEBSERVICE("https://query1.finance.yahoo.com/v8/finance/chart/"&AF10&"?range=1d&interval=1d"),"")) | AH10: =IF(AG10="","",IFERROR(_xlfn.NUMBERVALUE(MID(AG10,SEARCH("""regularMarketPrice"":",AG10)+21,SEARCH(",",AG10&",",SEARCH("""regularMarketPrice"":",AG10)+21)-SEARCH("""regularMarketPrice"":",AG10)-21),".",","),"")) | AI10: =IF(AG10="","",IFERROR(_xlfn.NUMBERVALUE(MID(AG10,SEARCH("""chartPreviousClose"":",AG10)+21,SEARCH(",",AG10&",",SEARCH("""chartPreviousClose"":",AG10)+21)-SEARCH("""chartPreviousClose"":",AG10)-21),".",","),"")) | AJ10: =IF(A10="","",N(E10)*IF(AND(p_ModoCot="Automático",ISNUMBER(AI10)),AI10,IF(N(I10)>0,I10,J10))*AE10) | AK10: =IF(A10="","",ROUND(MAX(0,N(R10)*($M$6+$AE$7)-M10),2)) | AL10: =IF(A10="","",IF(AND(S10>0,S10>=p_DifMin),AK10,0)) | AM10: =IF(A10="","",IF(AND(AL10>0,N(U10)<=p_MaxAtivos),AL10,0)) | AN10: =IF(A10="","",IF(OR(W10<=0,W10<p_CompraMin,N(J10)<=0,N(AE10)<=0),0,IF($AE$3="Sim",TRUNC(ROUND(MAX(0,(W10-p_CorrFixa)/(J10*AE10*$AE$6)),9),$AE$4),TRUNC(ROUND(MAX(0,(W10-p_CorrFixa)/(J10*AE10*$AE$6)),9)/$AE$5)*$AE$5))) | AO10: =IF(A10="","",IF(N(AN10)>0,AN10*J10*AE10*$AE$6+p_CorrFixa,0)) | AP10: =IF(A10="","",IF(OR($AI$1<=0,N(J10)<=0,N(AE10)<=0,N(AL10)<=0),0,IF($AE$3="Sim",TRUNC(ROUND(MAX(0,($AI$1-IF(N(AN10)>0,0,p_CorrFixa))/(J10*AE10*$AE$6)),9),$AE$4),TRUNC(ROUND(MAX(0,($AI$1-IF(N(AN10)>0,0,p_CorrFixa))/(J10*AE10*$AE$6)),9)/$AE$5)*$AE$5))) | AQ10: =IF(A10="","",IF(AND(N(AN10)=0,N(AP10)*(J10*AE10*$AE$6)+p_CorrFixa<p_CompraMin),0,AP10)) | AR10: =IF(A10="","",IF(N(AQ10)>0,AL10,0)) | AS10: =IF(A10="","",IF(AND(AR10>0,AR10=$AR$6,COUNTIF($AR$9:AR10,AR10)=1),1,0))
J11: =IF(A11="","",IF(AND(p_ModoCot="Automático",ISNUMBER(AH11)),AH11,IF(N(H11)>0,H11,N(F11)))) | K11: =IF(A11="","",IF(AE11=0,"Sem câmbio",IF(AND(p_ModoCot="Automático",ISNUMBER(AH11)),"Auto",IF(N(H11)>0,"Manual",IF(N(F11)>0,"PM","Sem cotação"))))) | L11: =IF(A11="","",N(E11)*J11) | M11: =IF(A11="","",L11*AE11) | N11: =IF(A11="","",N(E11)*N(F11)*IF(N(G11)>0,G11,AE11)) | O11: =IF(A11="","",M11-N11) | P11: =IF(A11="","",IF(N11>0,O11/N11,0)) | Q11: =IF(A11="","",IF($M$6>0,M11/$M$6,0)) | S11: =IF(A11="","",N(R11)-Q11) | T11: =IF(A11="","",IF($AL$6>0,AL11/$AL$6,0)) | U11: =IF(A11="","",IF(AL11<=0,"",COUNTIF($AL$9:$AL$208,">"&AL11)+COUNTIF($AL$9:AL11,AL11))) | V11: =IF(A11="","",IF(W11>0,"BUY","HOLD")) | W11: =IF(A11="","",IF($AE$7<=0,0,IF($AM$6>0,$AE$7*AM11/$AM$6,IF($R$6>0,$AE$7*N(R11)/$R$6,0)))) | X11: =IF(A11="","",N(AN11)+IF(AS11=1,N(AQ11),0)) | Y11: =IF(A11="","",IF(N(X11)>0,X11*J11*AE11*$AE$6+p_CorrFixa,0)) | Z11: =IF(A11="","",SUMIFS('11 Histórico de Dividendos'!$K$8:$K$3007,'11 Histórico de Dividendos'!$B$8:$B$3007,A11,'11 Histórico de Dividendos'!$A$8:$A$3007,">"&EDATE(ref_data,-12),'11 Histórico de Dividendos'!$A$8:$A$3007,"<="&ref_data)) | AA11: =IF(A11="","",IF(M11>0,Z11/M11,0)) | AB11: =IF(A11="","",IF(N11>0,Z11/N11,0)) | AD11: =IF(A11="","",IF(D11="",$AE$1,D11)) | AE11: =IF(A11="","",IFERROR(INDEX(moeda_fx,MATCH(AD11,moeda_cod,0)),0)) | AF11: =IF(A11="","",IF($AE$2="",UPPER(TRIM(A11)),IF(RIGHT(UPPER(TRIM(A11)),LEN($AE$2))=$AE$2,UPPER(TRIM(A11)),UPPER(TRIM(A11))&$AE$2))) | AG11: =IF(OR(A11="",p_ModoCot<>"Automático"),"",IFERROR(_xlfn.WEBSERVICE("https://query1.finance.yahoo.com/v8/finance/chart/"&AF11&"?range=1d&interval=1d"),"")) | AH11: =IF(AG11="","",IFERROR(_xlfn.NUMBERVALUE(MID(AG11,SEARCH("""regularMarketPrice"":",AG11)+21,SEARCH(",",AG11&",",SEARCH("""regularMarketPrice"":",AG11)+21)-SEARCH("""regularMarketPrice"":",AG11)-21),".",","),"")) | AI11: =IF(AG11="","",IFERROR(_xlfn.NUMBERVALUE(MID(AG11,SEARCH("""chartPreviousClose"":",AG11)+21,SEARCH(",",AG11&",",SEARCH("""chartPreviousClose"":",AG11)+21)-SEARCH("""chartPreviousClose"":",AG11)-21),".",","),"")) | AJ11: =IF(A11="","",N(E11)*IF(AND(p_ModoCot="Automático",ISNUMBER(AI11)),AI11,IF(N(I11)>0,I11,J11))*AE11) | AK11: =IF(A11="","",ROUND(MAX(0,N(R11)*($M$6+$AE$7)-M11),2)) | AL11: =IF(A11="","",IF(AND(S11>0,S11>=p_DifMin),AK11,0)) | AM11: =IF(A11="","",IF(AND(AL11>0,N(U11)<=p_MaxAtivos),AL11,0)) | AN11: =IF(A11="","",IF(OR(W11<=0,W11<p_CompraMin,N(J11)<=0,N(AE11)<=0),0,IF($AE$3="Sim",TRUNC(ROUND(MAX(0,(W11-p_CorrFixa)/(J11*AE11*$AE$6)),9),$AE$4),TRUNC(ROUND(MAX(0,(W11-p_CorrFixa)/(J11*AE11*$AE$6)),9)/$AE$5)*$AE$5))) | AO11: =IF(A11="","",IF(N(AN11)>0,AN11*J11*AE11*$AE$6+p_CorrFixa,0)) | AP11: =IF(A11="","",IF(OR($AI$1<=0,N(J11)<=0,N(AE11)<=0,N(AL11)<=0),0,IF($AE$3="Sim",TRUNC(ROUND(MAX(0,($AI$1-IF(N(AN11)>0,0,p_CorrFixa))/(J11*AE11*$AE$6)),9),$AE$4),TRUNC(ROUND(MAX(0,($AI$1-IF(N(AN11)>0,0,p_CorrFixa))/(J11*AE11*$AE$6)),9)/$AE$5)*$AE$5))) | AQ11: =IF(A11="","",IF(AND(N(AN11)=0,N(AP11)*(J11*AE11*$AE$6)+p_CorrFixa<p_CompraMin),0,AP11)) | AR11: =IF(A11="","",IF(N(AQ11)>0,AL11,0)) | AS11: =IF(A11="","",IF(AND(AR11>0,AR11=$AR$6,COUNTIF($AR$9:AR11,AR11)=1),1,0))
J12: =IF(A12="","",IF(AND(p_ModoCot="Automático",ISNUMBER(AH12)),AH12,IF(N(H12)>0,H12,N(F12)))) | K12: =IF(A12="","",IF(AE12=0,"Sem câmbio",IF(AND(p_ModoCot="Automático",ISNUMBER(AH12)),"Auto",IF(N(H12)>0,"Manual",IF(N(F12)>0,"PM","Sem cotação"))))) | L12: =IF(A12="","",N(E12)*J12) | M12: =IF(A12="","",L12*AE12) | N12: =IF(A12="","",N(E12)*N(F12)*IF(N(G12)>0,G12,AE12)) | O12: =IF(A12="","",M12-N12) | P12: =IF(A12="","",IF(N12>0,O12/N12,0)) | Q12: =IF(A12="","",IF($M$6>0,M12/$M$6,0)) | S12: =IF(A12="","",N(R12)-Q12) | T12: =IF(A12="","",IF($AL$6>0,AL12/$AL$6,0)) | U12: =IF(A12="","",IF(AL12<=0,"",COUNTIF($AL$9:$AL$208,">"&AL12)+COUNTIF($AL$9:AL12,AL12))) | V12: =IF(A12="","",IF(W12>0,"BUY","HOLD")) | W12: =IF(A12="","",IF($AE$7<=0,0,IF($AM$6>0,$AE$7*AM12/$AM$6,IF($R$6>0,$AE$7*N(R12)/$R$6,0)))) | X12: =IF(A12="","",N(AN12)+IF(AS12=1,N(AQ12),0)) | Y12: =IF(A12="","",IF(N(X12)>0,X12*J12*AE12*$AE$6+p_CorrFixa,0)) | Z12: =IF(A12="","",SUMIFS('11 Histórico de Dividendos'!$K$8:$K$3007,'11 Histórico de Dividendos'!$B$8:$B$3007,A12,'11 Histórico de Dividendos'!$A$8:$A$3007,">"&EDATE(ref_data,-12),'11 Histórico de Dividendos'!$A$8:$A$3007,"<="&ref_data)) | AA12: =IF(A12="","",IF(M12>0,Z12/M12,0)) | AB12: =IF(A12="","",IF(N12>0,Z12/N12,0)) | AD12: =IF(A12="","",IF(D12="",$AE$1,D12)) | AE12: =IF(A12="","",IFERROR(INDEX(moeda_fx,MATCH(AD12,moeda_cod,0)),0)) | AF12: =IF(A12="","",IF($AE$2="",UPPER(TRIM(A12)),IF(RIGHT(UPPER(TRIM(A12)),LEN($AE$2))=$AE$2,UPPER(TRIM(A12)),UPPER(TRIM(A12))&$AE$2))) | AG12: =IF(OR(A12="",p_ModoCot<>"Automático"),"",IFERROR(_xlfn.WEBSERVICE("https://query1.finance.yahoo.com/v8/finance/chart/"&AF12&"?range=1d&interval=1d"),"")) | AH12: =IF(AG12="","",IFERROR(_xlfn.NUMBERVALUE(MID(AG12,SEARCH("""regularMarketPrice"":",AG12)+21,SEARCH(",",AG12&",",SEARCH("""regularMarketPrice"":",AG12)+21)-SEARCH("""regularMarketPrice"":",AG12)-21),".",","),"")) | AI12: =IF(AG12="","",IFERROR(_xlfn.NUMBERVALUE(MID(AG12,SEARCH("""chartPreviousClose"":",AG12)+21,SEARCH(",",AG12&",",SEARCH("""chartPreviousClose"":",AG12)+21)-SEARCH("""chartPreviousClose"":",AG12)-21),".",","),"")) | AJ12: =IF(A12="","",N(E12)*IF(AND(p_ModoCot="Automático",ISNUMBER(AI12)),AI12,IF(N(I12)>0,I12,J12))*AE12) | AK12: =IF(A12="","",ROUND(MAX(0,N(R12)*($M$6+$AE$7)-M12),2)) | AL12: =IF(A12="","",IF(AND(S12>0,S12>=p_DifMin),AK12,0)) | AM12: =IF(A12="","",IF(AND(AL12>0,N(U12)<=p_MaxAtivos),AL12,0)) | AN12: =IF(A12="","",IF(OR(W12<=0,W12<p_CompraMin,N(J12)<=0,N(AE12)<=0),0,IF($AE$3="Sim",TRUNC(ROUND(MAX(0,(W12-p_CorrFixa)/(J12*AE12*$AE$6)),9),$AE$4),TRUNC(ROUND(MAX(0,(W12-p_CorrFixa)/(J12*AE12*$AE$6)),9)/$AE$5)*$AE$5))) | AO12: =IF(A12="","",IF(N(AN12)>0,AN12*J12*AE12*$AE$6+p_CorrFixa,0)) | AP12: =IF(A12="","",IF(OR($AI$1<=0,N(J12)<=0,N(AE12)<=0,N(AL12)<=0),0,IF($AE$3="Sim",TRUNC(ROUND(MAX(0,($AI$1-IF(N(AN12)>0,0,p_CorrFixa))/(J12*AE12*$AE$6)),9),$AE$4),TRUNC(ROUND(MAX(0,($AI$1-IF(N(AN12)>0,0,p_CorrFixa))/(J12*AE12*$AE$6)),9)/$AE$5)*$AE$5))) | AQ12: =IF(A12="","",IF(AND(N(AN12)=0,N(AP12)*(J12*AE12*$AE$6)+p_CorrFixa<p_CompraMin),0,AP12)) | AR12: =IF(A12="","",IF(N(AQ12)>0,AL12,0)) | AS12: =IF(A12="","",IF(AND(AR12>0,AR12=$AR$6,COUNTIF($AR$9:AR12,AR12)=1),1,0))
J13: =IF(A13="","",IF(AND(p_ModoCot="Automático",ISNUMBER(AH13)),AH13,IF(N(H13)>0,H13,N(F13)))) | K13: =IF(A13="","",IF(AE13=0,"Sem câmbio",IF(AND(p_ModoCot="Automático",ISNUMBER(AH13)),"Auto",IF(N(H13)>0,"Manual",IF(N(F13)>0,"PM","Sem cotação"))))) | L13: =IF(A13="","",N(E13)*J13) | M13: =IF(A13="","",L13*AE13) | N13: =IF(A13="","",N(E13)*N(F13)*IF(N(G13)>0,G13,AE13)) | O13: =IF(A13="","",M13-N13) | P13: =IF(A13="","",IF(N13>0,O13/N13,0)) | Q13: =IF(A13="","",IF($M$6>0,M13/$M$6,0)) | S13: =IF(A13="","",N(R13)-Q13) | T13: =IF(A13="","",IF($AL$6>0,AL13/$AL$6,0)) | U13: =IF(A13="","",IF(AL13<=0,"",COUNTIF($AL$9:$AL$208,">"&AL13)+COUNTIF($AL$9:AL13,AL13))) | V13: =IF(A13="","",IF(W13>0,"BUY","HOLD")) | W13: =IF(A13="","",IF($AE$7<=0,0,IF($AM$6>0,$AE$7*AM13/$AM$6,IF($R$6>0,$AE$7*N(R13)/$R$6,0)))) | X13: =IF(A13="","",N(AN13)+IF(AS13=1,N(AQ13),0)) | Y13: =IF(A13="","",IF(N(X13)>0,X13*J13*AE13*$AE$6+p_CorrFixa,0)) | Z13: =IF(A13="","",SUMIFS('11 Histórico de Dividendos'!$K$8:$K$3007,'11 Histórico de Dividendos'!$B$8:$B$3007,A13,'11 Histórico de Dividendos'!$A$8:$A$3007,">"&EDATE(ref_data,-12),'11 Histórico de Dividendos'!$A$8:$A$3007,"<="&ref_data)) | AA13: =IF(A13="","",IF(M13>0,Z13/M13,0)) | AB13: =IF(A13="","",IF(N13>0,Z13/N13,0)) | AD13: =IF(A13="","",IF(D13="",$AE$1,D13)) | AE13: =IF(A13="","",IFERROR(INDEX(moeda_fx,MATCH(AD13,moeda_cod,0)),0)) | AF13: =IF(A13="","",IF($AE$2="",UPPER(TRIM(A13)),IF(RIGHT(UPPER(TRIM(A13)),LEN($AE$2))=$AE$2,UPPER(TRIM(A13)),UPPER(TRIM(A13))&$AE$2))) | AG13: =IF(OR(A13="",p_ModoCot<>"Automático"),"",IFERROR(_xlfn.WEBSERVICE("https://query1.finance.yahoo.com/v8/finance/chart/"&AF13&"?range=1d&interval=1d"),"")) | AH13: =IF(AG13="","",IFERROR(_xlfn.NUMBERVALUE(MID(AG13,SEARCH("""regularMarketPrice"":",AG13)+21,SEARCH(",",AG13&",",SEARCH("""regularMarketPrice"":",AG13)+21)-SEARCH("""regularMarketPrice"":",AG13)-21),".",","),"")) | AI13: =IF(AG13="","",IFERROR(_xlfn.NUMBERVALUE(MID(AG13,SEARCH("""chartPreviousClose"":",AG13)+21,SEARCH(",",AG13&",",SEARCH("""chartPreviousClose"":",AG13)+21)-SEARCH("""chartPreviousClose"":",AG13)-21),".",","),"")) | AJ13: =IF(A13="","",N(E13)*IF(AND(p_ModoCot="Automático",ISNUMBER(AI13)),AI13,IF(N(I13)>0,I13,J13))*AE13) | AK13: =IF(A13="","",ROUND(MAX(0,N(R13)*($M$6+$AE$7)-M13),2)) | AL13: =IF(A13="","",IF(AND(S13>0,S13>=p_DifMin),AK13,0)) | AM13: =IF(A13="","",IF(AND(AL13>0,N(U13)<=p_MaxAtivos),AL13,0)) | AN13: =IF(A13="","",IF(OR(W13<=0,W13<p_CompraMin,N(J13)<=0,N(AE13)<=0),0,IF($AE$3="Sim",TRUNC(ROUND(MAX(0,(W13-p_CorrFixa)/(J13*AE13*$AE$6)),9),$AE$4),TRUNC(ROUND(MAX(0,(W13-p_CorrFixa)/(J13*AE13*$AE$6)),9)/$AE$5)*$AE$5))) | AO13: =IF(A13="","",IF(N(AN13)>0,AN13*J13*AE13*$AE$6+p_CorrFixa,0)) | AP13: =IF(A13="","",IF(OR($AI$1<=0,N(J13)<=0,N(AE13)<=0,N(AL13)<=0),0,IF($AE$3="Sim",TRUNC(ROUND(MAX(0,($AI$1-IF(N(AN13)>0,0,p_CorrFixa))/(J13*AE13*$AE$6)),9),$AE$4),TRUNC(ROUND(MAX(0,($AI$1-IF(N(AN13)>0,0,p_CorrFixa))/(J13*AE13*$AE$6)),9)/$AE$5)*$AE$5))) | AQ13: =IF(A13="","",IF(AND(N(AN13)=0,N(AP13)*(J13*AE13*$AE$6)+p_CorrFixa<p_CompraMin),0,AP13)) | AR13: =IF(A13="","",IF(N(AQ13)>0,AL13,0)) | AS13: =IF(A13="","",IF(AND(AR13>0,AR13=$AR$6,COUNTIF($AR$9:AR13,AR13)=1),1,0))
J14: =IF(A14="","",IF(AND(p_ModoCot="Automático",ISNUMBER(AH14)),AH14,IF(N(H14)>0,H14,N(F14)))) | K14: =IF(A14="","",IF(AE14=0,"Sem câmbio",IF(AND(p_ModoCot="Automático",ISNUMBER(AH14)),"Auto",IF(N(H14)>0,"Manual",IF(N(F14)>0,"PM","Sem cotação"))))) | L14: =IF(A14="","",N(E14)*J14) | M14: =IF(A14="","",L14*AE14) | N14: =IF(A14="","",N(E14)*N(F14)*IF(N(G14)>0,G14,AE14)) | O14: =IF(A14="","",M14-N14) | P14: =IF(A14="","",IF(N14>0,O14/N14,0)) | Q14: =IF(A14="","",IF($M$6>0,M14/$M$6,0)) | S14: =IF(A14="","",N(R14)-Q14) | T14: =IF(A14="","",IF($AL$6>0,AL14/$AL$6,0)) | U14: =IF(A14="","",IF(AL14<=0,"",COUNTIF($AL$9:$AL$208,">"&AL14)+COUNTIF($AL$9:AL14,AL14))) | V14: =IF(A14="","",IF(W14>0,"BUY","HOLD")) | W14: =IF(A14="","",IF($AE$7<=0,0,IF($AM$6>0,$AE$7*AM14/$AM$6,IF($R$6>0,$AE$7*N(R14)/$R$6,0)))) | X14: =IF(A14="","",N(AN14)+IF(AS14=1,N(AQ14),0)) | Y14: =IF(A14="","",IF(N(X14)>0,X14*J14*AE14*$AE$6+p_CorrFixa,0)) | Z14: =IF(A14="","",SUMIFS('11 Histórico de Dividendos'!$K$8:$K$3007,'11 Histórico de Dividendos'!$B$8:$B$3007,A14,'11 Histórico de Dividendos'!$A$8:$A$3007,">"&EDATE(ref_data,-12),'11 Histórico de Dividendos'!$A$8:$A$3007,"<="&ref_data)) | AA14: =IF(A14="","",IF(M14>0,Z14/M14,0)) | AB14: =IF(A14="","",IF(N14>0,Z14/N14,0)) | AD14: =IF(A14="","",IF(D14="",$AE$1,D14)) | AE14: =IF(A14="","",IFERROR(INDEX(moeda_fx,MATCH(AD14,moeda_cod,0)),0)) | AF14: =IF(A14="","",IF($AE$2="",UPPER(TRIM(A14)),IF(RIGHT(UPPER(TRIM(A14)),LEN($AE$2))=$AE$2,UPPER(TRIM(A14)),UPPER(TRIM(A14))&$AE$2))) | AG14: =IF(OR(A14="",p_ModoCot<>"Automático"),"",IFERROR(_xlfn.WEBSERVICE("https://query1.finance.yahoo.com/v8/finance/chart/"&AF14&"?range=1d&interval=1d"),"")) | AH14: =IF(AG14="","",IFERROR(_xlfn.NUMBERVALUE(MID(AG14,SEARCH("""regularMarketPrice"":",AG14)+21,SEARCH(",",AG14&",",SEARCH("""regularMarketPrice"":",AG14)+21)-SEARCH("""regularMarketPrice"":",AG14)-21),".",","),"")) | AI14: =IF(AG14="","",IFERROR(_xlfn.NUMBERVALUE(MID(AG14,SEARCH("""chartPreviousClose"":",AG14)+21,SEARCH(",",AG14&",",SEARCH("""chartPreviousClose"":",AG14)+21)-SEARCH("""chartPreviousClose"":",AG14)-21),".",","),"")) | AJ14: =IF(A14="","",N(E14)*IF(AND(p_ModoCot="Automático",ISNUMBER(AI14)),AI14,IF(N(I14)>0,I14,J14))*AE14) | AK14: =IF(A14="","",ROUND(MAX(0,N(R14)*($M$6+$AE$7)-M14),2)) | AL14: =IF(A14="","",IF(AND(S14>0,S14>=p_DifMin),AK14,0)) | AM14: =IF(A14="","",IF(AND(AL14>0,N(U14)<=p_MaxAtivos),AL14,0)) | AN14: =IF(A14="","",IF(OR(W14<=0,W14<p_CompraMin,N(J14)<=0,N(AE14)<=0),0,IF($AE$3="Sim",TRUNC(ROUND(MAX(0,(W14-p_CorrFixa)/(J14*AE14*$AE$6)),9),$AE$4),TRUNC(ROUND(MAX(0,(W14-p_CorrFixa)/(J14*AE14*$AE$6)),9)/$AE$5)*$AE$5))) | AO14: =IF(A14="","",IF(N(AN14)>0,AN14*J14*AE14*$AE$6+p_CorrFixa,0)) | AP14: =IF(A14="","",IF(OR($AI$1<=0,N(J14)<=0,N(AE14)<=0,N(AL14)<=0),0,IF($AE$3="Sim",TRUNC(ROUND(MAX(0,($AI$1-IF(N(AN14)>0,0,p_CorrFixa))/(J14*AE14*$AE$6)),9),$AE$4),TRUNC(ROUND(MAX(0,($AI$1-IF(N(AN14)>0,0,p_CorrFixa))/(J14*AE14*$AE$6)),9)/$AE$5)*$AE$5))) | AQ14: =IF(A14="","",IF(AND(N(AN14)=0,N(AP14)*(J14*AE14*$AE$6)+p_CorrFixa<p_CompraMin),0,AP14)) | AR14: =IF(A14="","",IF(N(AQ14)>0,AL14,0)) | AS14: =IF(A14="","",IF(AND(AR14>0,AR14=$AR$6,COUNTIF($AR$9:AR14,AR14)=1),1,0))
J15: =IF(A15="","",IF(AND(p_ModoCot="Automático",ISNUMBER(AH15)),AH15,IF(N(H15)>0,H15,N(F15)))) | K15: =IF(A15="","",IF(AE15=0,"Sem câmbio",IF(AND(p_ModoCot="Automático",ISNUMBER(AH15)),"Auto",IF(N(H15)>0,"Manual",IF(N(F15)>0,"PM","Sem cotação"))))) | L15: =IF(A15="","",N(E15)*J15) | M15: =IF(A15="","",L15*AE15) | N15: =IF(A15="","",N(E15)*N(F15)*IF(N(G15)>0,G15,AE15)) | O15: =IF(A15="","",M15-N15) | P15: =IF(A15="","",IF(N15>0,O15/N15,0)) | Q15: =IF(A15="","",IF($M$6>0,M15/$M$6,0)) | S15: =IF(A15="","",N(R15)-Q15) | T15: =IF(A15="","",IF($AL$6>0,AL15/$AL$6,0)) | U15: =IF(A15="","",IF(AL15<=0,"",COUNTIF($AL$9:$AL$208,">"&AL15)+COUNTIF($AL$9:AL15,AL15))) | V15: =IF(A15="","",IF(W15>0,"BUY","HOLD")) | W15: =IF(A15="","",IF($AE$7<=0,0,IF($AM$6>0,$AE$7*AM15/$AM$6,IF($R$6>0,$AE$7*N(R15)/$R$6,0)))) | X15: =IF(A15="","",N(AN15)+IF(AS15=1,N(AQ15),0)) | Y15: =IF(A15="","",IF(N(X15)>0,X15*J15*AE15*$AE$6+p_CorrFixa,0)) | Z15: =IF(A15="","",SUMIFS('11 Histórico de Dividendos'!$K$8:$K$3007,'11 Histórico de Dividendos'!$B$8:$B$3007,A15,'11 Histórico de Dividendos'!$A$8:$A$3007,">"&EDATE(ref_data,-12),'11 Histórico de Dividendos'!$A$8:$A$3007,"<="&ref_data)) | AA15: =IF(A15="","",IF(M15>0,Z15/M15,0)) | AB15: =IF(A15="","",IF(N15>0,Z15/N15,0)) | AD15: =IF(A15="","",IF(D15="",$AE$1,D15)) | AE15: =IF(A15="","",IFERROR(INDEX(moeda_fx,MATCH(AD15,moeda_cod,0)),0)) | AF15: =IF(A15="","",IF($AE$2="",UPPER(TRIM(A15)),IF(RIGHT(UPPER(TRIM(A15)),LEN($AE$2))=$AE$2,UPPER(TRIM(A15)),UPPER(TRIM(A15))&$AE$2))) | AG15: =IF(OR(A15="",p_ModoCot<>"Automático"),"",IFERROR(_xlfn.WEBSERVICE("https://query1.finance.yahoo.com/v8/finance/chart/"&AF15&"?range=1d&interval=1d"),"")) | AH15: =IF(AG15="","",IFERROR(_xlfn.NUMBERVALUE(MID(AG15,SEARCH("""regularMarketPrice"":",AG15)+21,SEARCH(",",AG15&",",SEARCH("""regularMarketPrice"":",AG15)+21)-SEARCH("""regularMarketPrice"":",AG15)-21),".",","),"")) | AI15: =IF(AG15="","",IFERROR(_xlfn.NUMBERVALUE(MID(AG15,SEARCH("""chartPreviousClose"":",AG15)+21,SEARCH(",",AG15&",",SEARCH("""chartPreviousClose"":",AG15)+21)-SEARCH("""chartPreviousClose"":",AG15)-21),".",","),"")) | AJ15: =IF(A15="","",N(E15)*IF(AND(p_ModoCot="Automático",ISNUMBER(AI15)),AI15,IF(N(I15)>0,I15,J15))*AE15) | AK15: =IF(A15="","",ROUND(MAX(0,N(R15)*($M$6+$AE$7)-M15),2)) | AL15: =IF(A15="","",IF(AND(S15>0,S15>=p_DifMin),AK15,0)) | AM15: =IF(A15="","",IF(AND(AL15>0,N(U15)<=p_MaxAtivos),AL15,0)) | AN15: =IF(A15="","",IF(OR(W15<=0,W15<p_CompraMin,N(J15)<=0,N(AE15)<=0),0,IF($AE$3="Sim",TRUNC(ROUND(MAX(0,(W15-p_CorrFixa)/(J15*AE15*$AE$6)),9),$AE$4),TRUNC(ROUND(MAX(0,(W15-p_CorrFixa)/(J15*AE15*$AE$6)),9)/$AE$5)*$AE$5))) | AO15: =IF(A15="","",IF(N(AN15)>0,AN15*J15*AE15*$AE$6+p_CorrFixa,0)) | AP15: =IF(A15="","",IF(OR($AI$1<=0,N(J15)<=0,N(AE15)<=0,N(AL15)<=0),0,IF($AE$3="Sim",TRUNC(ROUND(MAX(0,($AI$1-IF(N(AN15)>0,0,p_CorrFixa))/(J15*AE15*$AE$6)),9),$AE$4),TRUNC(ROUND(MAX(0,($AI$1-IF(N(AN15)>0,0,p_CorrFixa))/(J15*AE15*$AE$6)),9)/$AE$5)*$AE$5))) | AQ15: =IF(A15="","",IF(AND(N(AN15)=0,N(AP15)*(J15*AE15*$AE$6)+p_CorrFixa<p_CompraMin),0,AP15)) | AR15: =IF(A15="","",IF(N(AQ15)>0,AL15,0)) | AS15: =IF(A15="","",IF(AND(AR15>0,AR15=$AR$6,COUNTIF($AR$9:AR15,AR15)=1),1,0))
J16: =IF(A16="","",IF(AND(p_ModoCot="Automático",ISNUMBER(AH16)),AH16,IF(N(H16)>0,H16,N(F16)))) | K16: =IF(A16="","",IF(AE16=0,"Sem câmbio",IF(AND(p_ModoCot="Automático",ISNUMBER(AH16)),"Auto",IF(N(H16)>0,"Manual",IF(N(F16)>0,"PM","Sem cotação"))))) | L16: =IF(A16="","",N(E16)*J16) | M16: =IF(A16="","",L16*AE16) | N16: =IF(A16="","",N(E16)*N(F16)*IF(N(G16)>0,G16,AE16)) | O16: =IF(A16="","",M16-N16) | P16: =IF(A16="","",IF(N16>0,O16/N16,0)) | Q16: =IF(A16="","",IF($M$6>0,M16/$M$6,0)) | S16: =IF(A16="","",N(R16)-Q16) | T16: =IF(A16="","",IF($AL$6>0,AL16/$AL$6,0)) | U16: =IF(A16="","",IF(AL16<=0,"",COUNTIF($AL$9:$AL$208,">"&AL16)+COUNTIF($AL$9:AL16,AL16))) | V16: =IF(A16="","",IF(W16>0,"BUY","HOLD")) | W16: =IF(A16="","",IF($AE$7<=0,0,IF($AM$6>0,$AE$7*AM16/$AM$6,IF($R$6>0,$AE$7*N(R16)/$R$6,0)))) | X16: =IF(A16="","",N(AN16)+IF(AS16=1,N(AQ16),0)) | Y16: =IF(A16="","",IF(N(X16)>0,X16*J16*AE16*$AE$6+p_CorrFixa,0)) | Z16: =IF(A16="","",SUMIFS('11 Histórico de Dividendos'!$K$8:$K$3007,'11 Histórico de Dividendos'!$B$8:$B$3007,A16,'11 Histórico de Dividendos'!$A$8:$A$3007,">"&EDATE(ref_data,-12),'11 Histórico de Dividendos'!$A$8:$A$3007,"<="&ref_data)) | AA16: =IF(A16="","",IF(M16>0,Z16/M16,0)) | AB16: =IF(A16="","",IF(N16>0,Z16/N16,0)) | AD16: =IF(A16="","",IF(D16="",$AE$1,D16)) | AE16: =IF(A16="","",IFERROR(INDEX(moeda_fx,MATCH(AD16,moeda_cod,0)),0)) | AF16: =IF(A16="","",IF($AE$2="",UPPER(TRIM(A16)),IF(RIGHT(UPPER(TRIM(A16)),LEN($AE$2))=$AE$2,UPPER(TRIM(A16)),UPPER(TRIM(A16))&$AE$2))) | AG16: =IF(OR(A16="",p_ModoCot<>"Automático"),"",IFERROR(_xlfn.WEBSERVICE("https://query1.finance.yahoo.com/v8/finance/chart/"&AF16&"?range=1d&interval=1d"),"")) | AH16: =IF(AG16="","",IFERROR(_xlfn.NUMBERVALUE(MID(AG16,SEARCH("""regularMarketPrice"":",AG16)+21,SEARCH(",",AG16&",",SEARCH("""regularMarketPrice"":",AG16)+21)-SEARCH("""regularMarketPrice"":",AG16)-21),".",","),"")) | AI16: =IF(AG16="","",IFERROR(_xlfn.NUMBERVALUE(MID(AG16,SEARCH("""chartPreviousClose"":",AG16)+21,SEARCH(",",AG16&",",SEARCH("""chartPreviousClose"":",AG16)+21)-SEARCH("""chartPreviousClose"":",AG16)-21),".",","),"")) | AJ16: =IF(A16="","",N(E16)*IF(AND(p_ModoCot="Automático",ISNUMBER(AI16)),AI16,IF(N(I16)>0,I16,J16))*AE16) | AK16: =IF(A16="","",ROUND(MAX(0,N(R16)*($M$6+$AE$7)-M16),2)) | AL16: =IF(A16="","",IF(AND(S16>0,S16>=p_DifMin),AK16,0)) | AM16: =IF(A16="","",IF(AND(AL16>0,N(U16)<=p_MaxAtivos),AL16,0)) | AN16: =IF(A16="","",IF(OR(W16<=0,W16<p_CompraMin,N(J16)<=0,N(AE16)<=0),0,IF($AE$3="Sim",TRUNC(ROUND(MAX(0,(W16-p_CorrFixa)/(J16*AE16*$AE$6)),9),$AE$4),TRUNC(ROUND(MAX(0,(W16-p_CorrFixa)/(J16*AE16*$AE$6)),9)/$AE$5)*$AE$5))) | AO16: =IF(A16="","",IF(N(AN16)>0,AN16*J16*AE16*$AE$6+p_CorrFixa,0)) | AP16: =IF(A16="","",IF(OR($AI$1<=0,N(J16)<=0,N(AE16)<=0,N(AL16)<=0),0,IF($AE$3="Sim",TRUNC(ROUND(MAX(0,($AI$1-IF(N(AN16)>0,0,p_CorrFixa))/(J16*AE16*$AE$6)),9),$AE$4),TRUNC(ROUND(MAX(0,($AI$1-IF(N(AN16)>0,0,p_CorrFixa))/(J16*AE16*$AE$6)),9)/$AE$5)*$AE$5))) | AQ16: =IF(A16="","",IF(AND(N(AN16)=0,N(AP16)*(J16*AE16*$AE$6)+p_CorrFixa<p_CompraMin),0,AP16)) | AR16: =IF(A16="","",IF(N(AQ16)>0,AL16,0)) | AS16: =IF(A16="","",IF(AND(AR16>0,AR16=$AR$6,COUNTIF($AR$9:AR16,AR16)=1),1,0))
J17: =IF(A17="","",IF(AND(p_ModoCot="Automático",ISNUMBER(AH17)),AH17,IF(N(H17)>0,H17,N(F17)))) | K17: =IF(A17="","",IF(AE17=0,"Sem câmbio",IF(AND(p_ModoCot="Automático",ISNUMBER(AH17)),"Auto",IF(N(H17)>0,"Manual",IF(N(F17)>0,"PM","Sem cotação"))))) | L17: =IF(A17="","",N(E17)*J17) | M17: =IF(A17="","",L17*AE17) | N17: =IF(A17="","",N(E17)*N(F17)*IF(N(G17)>0,G17,AE17)) | O17: =IF(A17="","",M17-N17) | P17: =IF(A17="","",IF(N17>0,O17/N17,0)) | Q17: =IF(A17="","",IF($M$6>0,M17/$M$6,0)) | S17: =IF(A17="","",N(R17)-Q17) | T17: =IF(A17="","",IF($AL$6>0,AL17/$AL$6,0)) | U17: =IF(A17="","",IF(AL17<=0,"",COUNTIF($AL$9:$AL$208,">"&AL17)+COUNTIF($AL$9:AL17,AL17))) | V17: =IF(A17="","",IF(W17>0,"BUY","HOLD")) | W17: =IF(A17="","",IF($AE$7<=0,0,IF($AM$6>0,$AE$7*AM17/$AM$6,IF($R$6>0,$AE$7*N(R17)/$R$6,0)))) | X17: =IF(A17="","",N(AN17)+IF(AS17=1,N(AQ17),0)) | Y17: =IF(A17="","",IF(N(X17)>0,X17*J17*AE17*$AE$6+p_CorrFixa,0)) | Z17: =IF(A17="","",SUMIFS('11 Histórico de Dividendos'!$K$8:$K$3007,'11 Histórico de Dividendos'!$B$8:$B$3007,A17,'11 Histórico de Dividendos'!$A$8:$A$3007,">"&EDATE(ref_data,-12),'11 Histórico de Dividendos'!$A$8:$A$3007,"<="&ref_data)) | AA17: =IF(A17="","",IF(M17>0,Z17/M17,0)) | AB17: =IF(A17="","",IF(N17>0,Z17/N17,0)) | AD17: =IF(A17="","",IF(D17="",$AE$1,D17)) | AE17: =IF(A17="","",IFERROR(INDEX(moeda_fx,MATCH(AD17,moeda_cod,0)),0)) | AF17: =IF(A17="","",IF($AE$2="",UPPER(TRIM(A17)),IF(RIGHT(UPPER(TRIM(A17)),LEN($AE$2))=$AE$2,UPPER(TRIM(A17)),UPPER(TRIM(A17))&$AE$2))) | AG17: =IF(OR(A17="",p_ModoCot<>"Automático"),"",IFERROR(_xlfn.WEBSERVICE("https://query1.finance.yahoo.com/v8/finance/chart/"&AF17&"?range=1d&interval=1d"),"")) | AH17: =IF(AG17="","",IFERROR(_xlfn.NUMBERVALUE(MID(AG17,SEARCH("""regularMarketPrice"":",AG17)+21,SEARCH(",",AG17&",",SEARCH("""regularMarketPrice"":",AG17)+21)-SEARCH("""regularMarketPrice"":",AG17)-21),".",","),"")) | AI17: =IF(AG17="","",IFERROR(_xlfn.NUMBERVALUE(MID(AG17,SEARCH("""chartPreviousClose"":",AG17)+21,SEARCH(",",AG17&",",SEARCH("""chartPreviousClose"":",AG17)+21)-SEARCH("""chartPreviousClose"":",AG17)-21),".",","),"")) | AJ17: =IF(A17="","",N(E17)*IF(AND(p_ModoCot="Automático",ISNUMBER(AI17)),AI17,IF(N(I17)>0,I17,J17))*AE17) | AK17: =IF(A17="","",ROUND(MAX(0,N(R17)*($M$6+$AE$7)-M17),2)) | AL17: =IF(A17="","",IF(AND(S17>0,S17>=p_DifMin),AK17,0)) | AM17: =IF(A17="","",IF(AND(AL17>0,N(U17)<=p_MaxAtivos),AL17,0)) | AN17: =IF(A17="","",IF(OR(W17<=0,W17<p_CompraMin,N(J17)<=0,N(AE17)<=0),0,IF($AE$3="Sim",TRUNC(ROUND(MAX(0,(W17-p_CorrFixa)/(J17*AE17*$AE$6)),9),$AE$4),TRUNC(ROUND(MAX(0,(W17-p_CorrFixa)/(J17*AE17*$AE$6)),9)/$AE$5)*$AE$5))) | AO17: =IF(A17="","",IF(N(AN17)>0,AN17*J17*AE17*$AE$6+p_CorrFixa,0)) | AP17: =IF(A17="","",IF(OR($AI$1<=0,N(J17)<=0,N(AE17)<=0,N(AL17)<=0),0,IF($AE$3="Sim",TRUNC(ROUND(MAX(0,($AI$1-IF(N(AN17)>0,0,p_CorrFixa))/(J17*AE17*$AE$6)),9),$AE$4),TRUNC(ROUND(MAX(0,($AI$1-IF(N(AN17)>0,0,p_CorrFixa))/(J17*AE17*$AE$6)),9)/$AE$5)*$AE$5))) | AQ17: =IF(A17="","",IF(AND(N(AN17)=0,N(AP17)*(J17*AE17*$AE$6)+p_CorrFixa<p_CompraMin),0,AP17)) | AR17: =IF(A17="","",IF(N(AQ17)>0,AL17,0)) | AS17: =IF(A17="","",IF(AND(AR17>0,AR17=$AR$6,COUNTIF($AR$9:AR17,AR17)=1),1,0))
